Workbook
Name PLANILLA: Planilla!$B$2:$F$4548
Name RESXCC_1: ResXCC!$B$2:$J$950
Name RESXCO: ResXCO!$B$2:$J$1000
Name RESXCO_SUB23_1: ResXCO!$B$40:$J$60

Sheet EM
A8: ELITE MASCULINO (19+)
A10: 1 - Finca Grupo Orosi >21 y 22 febrero 2 - Parque La Libertad Desamparados > 28 y 29 marzo 3 - Adventure Park > 16 y 17 mayo 4 - Finca La Hisopa San Pedro de Turrubares > 13 y 14 junio
A11: 5 - Campamento Oikoumene, Ochomogo > 18 y 19 julio 6 - Finca Grupo Orosi, Paraiso > 12 y 13 setiembre 7 - Parque Recreativo Sarapiqui > 31 Oct y 01 Nov
A13: POSICION | F13: 1 | J13: 2 | N13: 3 | R13: 4 | V13: 5 | Z13: 6 | AD13: 7 | AH13: TOTAL PUNTOS
A14: ACTUAL | B14: ANTERIOR | C14: NO | D14: NOMBRE | E14: EQUIPO | F14: POS XCC | G14: PTOS XCC | H14: POS XCO | I14: PTOS XCO | J14: POS XCC | K14: PTOS XCC | L14: POS XCO | M14: PTOS XCO | N14: POS XCC | O14: PTOS XCC | P14: POS XCO | Q14: PTOS XCO | R14: POS XCC | S14: PTOS XCC | T14: POS XCO | U14: PTOS XCO | V14: POS XCC | W14: PTOS XCC | X14: POS XCO | Y14: PTOS XCO | Z14: POS XCC | AA14: PTOS XCC | AB14: POS XCO | AC14: PTOS XCO | AD14: POS XCC | AE14: PTOS XCC | AF14: POS XCO | AG14: PTOS XCO
A15: 1 | B15: 1 | C15: 3 | D15: HERRERA Carlos | E15: PEDREGAL 7C | F15: 2 | G15: 20 | H15: 1 | I15: 200 | J15: 2 | K15: 20 | L15: 3 | M15: 120 | N15: 9 | O15: =IFERROR(VLOOKUP(N15,'Puntos XCC Mayor'!$A$1:$B$15,2,FALSE),0) -> 7 | P15: 5 | Q15: =IFERROR(VLOOKUP(P15,'Puntos XCO'!$A$1:$B$63,2,FALSE),0) -> 100 | R15: 2 | S15: =IFERROR(VLOOKUP(R15,'Puntos XCC Mayor'!$A$1:$B$15,2,FALSE),0) -> 20 | T15: 1 | U15: =IFERROR(VLOOKUP(T15,'Puntos XCO'!$A$1:$B$63,2,FALSE),0) -> 200 | V15: 2 | W15: =IFERROR(VLOOKUP(V15,'Puntos XCC Mayor'!$A$1:$B$15,2,FALSE),0) -> 20 | X15: 2 | Y15: =IFERROR(VLOOKUP(X15,'Puntos XCO'!$A$1:$B$63,2,FALSE),0) -> 150 | Z15: =IFERROR(VLOOKUP($C15,RESXCC_1,9,FALSE),0) -> 1 | AA15: =IFERROR(VLOOKUP(Z15,'Puntos XCC Mayor'!$A$1:$B$15,2,FALSE),0) -> 25 | AB15: =IFERROR(VLOOKUP($C15,RESXCO,9,FALSE),0) -> 1 | AC15: =IFERROR(VLOOKUP(AB15,'Puntos XCO'!$A$1:$B$63,2,FALSE),0) -> 200 | AH15: =G15+I15+K15+M15+O15+Q15+S15+U15+W15+Y15+AA15+AC15+AE15+AG15 -> 1082
A16: 2 | B16: 2 | C16: 27 | D16: RAABE Fabricio* | E16: COLONO BIKE STATION KOLBI | F16: 10 | G16: 6 | H16: 4 | I16: 110 | J16: 12 | K16: 4 | L16: 7 | M16: 90 | N16: 15 | O16: =IFERROR(VLOOKUP(N16,'Puntos XCC Mayor'!$A$1:$B$15,2,FALSE),0) -> 1 | P16: 3 | Q16: =IFERROR(VLOOKUP(P16,'Puntos XCO'!$A$1:$B$63,2,FALSE),0) -> 120 | R16: 6 | S16: =IFERROR(VLOOKUP(R16,'Puntos XCC Mayor'!$A$1:$B$15,2,FALSE),0) -> 10 | T16: 5 | U16: =IFERROR(VLOOKUP(T16,'Puntos XCO'!$A$1:$B$63,2,FALSE),0) -> 100 | V16: 10 | W16: =IFERROR(VLOOKUP(V16,'Puntos XCC Mayor'!$A$1:$B$15,2,FALSE),0) -> 6 | X16: 8 | Y16: =IFERROR(VLOOKUP(X16,'Puntos XCO'!$A$1:$B$63,2,FALSE),0) -> 85 | Z16: =IFERROR(VLOOKUP($C16,RESXCC_1,9,FALSE),0) -> 5 | AA16: =IFERROR(VLOOKUP(Z16,'Puntos XCC Mayor'!$A$1:$B$15,2,FALSE),0) -> 12 | AB16: =IFERROR(VLOOKUP($C16,RESXCO,9,FALSE),0) -> 4 | AC16: =IFERROR(VLOOKUP(AB16,'Puntos XCO'!$A$1:$B$63,2,FALSE),0) -> 110 | AH16: =G16+I16+K16+M16+O16+Q16+S16+U16+W16+Y16+AA16+AC16+AE16+AG16 -> 654
A17: 3 | B17: 5 | C17: 25 | D17: GONZÁLEZ Adriano* | E17: COLONO BIKE STATION KOLBI | F17: 4 | G17: 14 | H17: 3 | I17: 120 | J17: 5 | K17: 12 | L17: 5 | M17: 100 | N17: 14 | O17: =IFERROR(VLOOKUP(N17,'Puntos XCC Mayor'!$A$1:$B$15,2,FALSE),0) -> 2 | P17: 4 | Q17: =IFERROR(VLOOKUP(P17,'Puntos XCO'!$A$1:$B$63,2,FALSE),0) -> 110 | R17: 5 | S17: =IFERROR(VLOOKUP(R17,'Puntos XCC Mayor'!$A$1:$B$15,2,FALSE),0) -> 12 | T17: 0 | U17: =IFERROR(VLOOKUP(T17,'Puntos XCO'!$A$1:$B$63,2,FALSE),0) -> 0 | V17: 5 | W17: =IFERROR(VLOOKUP(V17,'Puntos XCC Mayor'!$A$1:$B$15,2,FALSE),0) -> 12 | X17: 5 | Y17: =IFERROR(VLOOKUP(X17,'Puntos XCO'!$A$1:$B$63,2,FALSE),0) -> 100 | Z17: =IFERROR(VLOOKUP($C17,RESXCC_1,9,FALSE),0) -> 3 | AA17: =IFERROR(VLOOKUP(Z17,'Puntos XCC Mayor'!$A$1:$B$15,2,FALSE),0) -> 16 | AB17: =IFERROR(VLOOKUP($C17,RESXCO,9,FALSE),0) -> 3 | AC17: =IFERROR(VLOOKUP(AB17,'Puntos XCO'!$A$1:$B$63,2,FALSE),0) -> 120 | AH17: =G17+I17+K17+M17+O17+Q17+S17+U17+W17+Y17+AA17+AC17+AE17+AG17 -> 618
A18: 4 | B18: 4 | C18: 12 | D18: RAMIREZ Federico | E18: MEGAMO MANZATÉ LA SELVA | F18: 6 | G18: 10 | H18: 10 | I18: 78 | J18: 1 | K18: 25 | L18: 6 | M18: 95 | O18: =IFERROR(VLOOKUP(N18,'Puntos XCC Mayor'!$A$1:$B$15,2,FALSE),0) -> 0 | P18: 11 | Q18: =IFERROR(VLOOKUP(P18,'Puntos XCO'!$A$1:$B$63,2,FALSE),0) -> 76 | R18: 0 | S18: =IFERROR(VLOOKUP(R18,'Puntos XCC Mayor'!$A$1:$B$15,2,FALSE),0) -> 0 | T18: 7 | U18: =IFERROR(VLOOKUP(T18,'Puntos XCO'!$A$1:$B$63,2,FALSE),0) -> 90 | V18: 4 | W18: =IFERROR(VLOOKUP(V18,'Puntos XCC Mayor'!$A$1:$B$15,2,FALSE),0) -> 14 | X18: 6 | Y18: =IFERROR(VLOOKUP(X18,'Puntos XCO'!$A$1:$B$63,2,FALSE),0) -> 95 | Z18: =IFERROR(VLOOKUP($C18,RESXCC_1,9,FALSE),0) -> 4 | AA18: =IFERROR(VLOOKUP(Z18,'Puntos XCC Mayor'!$A$1:$B$15,2,FALSE),0) -> 14 | AB18: =IFERROR(VLOOKUP($C18,RESXCO,9,FALSE),0) -> 5 | AC18: =IFERROR(VLOOKUP(AB18,'Puntos XCO'!$A$1:$B$63,2,FALSE),0) -> 100 | AH18: =G18+I18+K18+M18+O18+Q18+S18+U18+W18+Y18+AA18+AC18+AE18+AG18 -> 597
A19: 5 | B19: 10 | C19: 26 | D19: VARGAS José David* | E19: COLONO BIKE STATION KOLBI | J19: 11 | K19: 5 | L19: 9 | M19: 80 | N19: 21 | O19: =IFERROR(VLOOKUP(N19,'Puntos XCC Mayor'!$A$1:$B$15,2,FALSE),0) -> 0 | P19: 10 | Q19: =IFERROR(VLOOKUP(P19,'Puntos XCO'!$A$1:$B$63,2,FALSE),0) -> 78 | R19: 9 | S19: =IFERROR(VLOOKUP(R19,'Puntos XCC Mayor'!$A$1:$B$15,2,FALSE),0) -> 7 | T19: 8 | U19: =IFERROR(VLOOKUP(T19,'Puntos XCO'!$A$1:$B$63,2,FALSE),0) -> 85 | V19: 12 | W19: =IFERROR(VLOOKUP(V19,'Puntos XCC Mayor'!$A$1:$B$15,2,FALSE),0) -> 4 | X19: 7 | Y19: =IFERROR(VLOOKUP(X19,'Puntos XCO'!$A$1:$B$63,2,FALSE),0) -> 90 | Z19: =IFERROR(VLOOKUP($C19,RESXCC_1,9,FALSE),0) -> 2 | AA19: =IFERROR(VLOOKUP(Z19,'Puntos XCC Mayor'!$A$1:$B$15,2,FALSE),0) -> 20 | AB19: =IFERROR(VLOOKUP($C19,RESXCO,9,FALSE),0) -> 2 | AC19: =IFERROR(VLOOKUP(AB19,'Puntos XCO'!$A$1:$B$63,2,FALSE),0) -> 150 | AH19: =G19+I19+K19+M19+O19+Q19+S19+U19+W19+Y19+AA19+AC19+AE19+AG19 -> 519
A20: 6 | B20: 3 | C20: 28 | D20: AZOFEIFA Daniel* | E20: BOBBYS CYCLING TEAM | F20: 13 | G20: 3 | H20: 8 | I20: 85 | J20: 2 | K20: 20 | L20: 11 | M20: 76 | N20: 16 | O20: =IFERROR(VLOOKUP(N20,'Puntos XCC Mayor'!$A$1:$B$15,2,FALSE),0) -> 0 | P20: 6 | Q20: =IFERROR(VLOOKUP(P20,'Puntos XCO'!$A$1:$B$63,2,FALSE),0) -> 95 | R20: 4 | S20: =IFERROR(VLOOKUP(R20,'Puntos XCC Mayor'!$A$1:$B$15,2,FALSE),0) -> 14 | T20: 4 | U20: =IFERROR(VLOOKUP(T20,'Puntos XCO'!$A$1:$B$63,2,FALSE),0) -> 110 | V20: 6 | W20: =IFERROR(VLOOKUP(V20,'Puntos XCC Mayor'!$A$1:$B$15,2,FALSE),0) -> 10 | X20: 12 | Y20: =IFERROR(VLOOKUP(X20,'Puntos XCO'!$A$1:$B$63,2,FALSE),0) -> 74 | Z20: =IFERROR(VLOOKUP($C20,RESXCC_1,9,FALSE),0) -> 0 | AA20: =IFERROR(VLOOKUP(Z20,'Puntos XCC Mayor'!$A$1:$B$15,2,FALSE),0) -> 0 | AB20: =IFERROR(VLOOKUP($C20,RESXCO,9,FALSE),0) -> 0 | AC20: =IFERROR(VLOOKUP(AB20,'Puntos XCO'!$A$1:$B$63,2,FALSE),0) -> 0 | AH20: =G20+I20+K20+M20+O20+Q20+S20+U20+W20+Y20+AA20+AC20+AE20+AG20 -> 487
A21: 7 | B21: 6 | C21: 4 | D21: LÓPEZ Luis Enrique | E21: MEGAMO MANZATÉ LA SELVA | J21: 1 | K21: 25 | L21: 1 | M21: 200 | N21: 4 | O21: =IFERROR(VLOOKUP(N21,'Puntos XCC Mayor'!$A$1:$B$15,2,FALSE),0) -> 14 | Q21: =IFERROR(VLOOKUP(P21,'Puntos XCO'!$A$1:$B$63,2,FALSE),0) -> 0 | R21: 1 | S21: =IFERROR(VLOOKUP(R21,'Puntos XCC Mayor'!$A$1:$B$15,2,FALSE),0) -> 25 | T21: 2 | U21: =IFERROR(VLOOKUP(T21,'Puntos XCO'!$A$1:$B$63,2,FALSE),0) -> 150 | V21: 0 | W21: =IFERROR(VLOOKUP(V21,'Puntos XCC Mayor'!$A$1:$B$15,2,FALSE),0) -> 0 | X21: 0 | Y21: =IFERROR(VLOOKUP(X21,'Puntos XCO'!$A$1:$B$63,2,FALSE),0) -> 0 | Z21: =IFERROR(VLOOKUP($C21,RESXCC_1,9,FALSE),0) -> 0 | AA21: =IFERROR(VLOOKUP(Z21,'Puntos XCC Mayor'!$A$1:$B$15,2,FALSE),0) -> 0 | AB21: =IFERROR(VLOOKUP($C21,RESXCO,9,FALSE),0) -> 0 | AC21: =IFERROR(VLOOKUP(AB21,'Puntos XCO'!$A$1:$B$63,2,FALSE),0) -> 0 | AH21: =G21+I21+K21+M21+O21+Q21+S21+U21+W21+Y21+AA21+AC21+AE21+AG21 -> 414
A22: 8 | B22: 12 | C22: 37 | D22: ROJAS Alejandro* | E22: TEAM HC | F22: 15 | G22: 1 | H22: 14 | I22: 70 | J22: 13 | K22: 3 | L22: 17 | M22: 64 | O22: =IFERROR(VLOOKUP(N22,'Puntos XCC Mayor'!$A$1:$B$15,2,FALSE),0) -> 0 | Q22: =IFERROR(VLOOKUP(P22,'Puntos XCO'!$A$1:$B$63,2,FALSE),0) -> 0 | R22: 10 | S22: =IFERROR(VLOOKUP(R22,'Puntos XCC Mayor'!$A$1:$B$15,2,FALSE),0) -> 6 | T22: 9 | U22: =IFERROR(VLOOKUP(T22,'Puntos XCO'!$A$1:$B$63,2,FALSE),0) -> 80 | V22: 8 | W22: =IFERROR(VLOOKUP(V22,'Puntos XCC Mayor'!$A$1:$B$15,2,FALSE),0) -> 8 | X22: 14 | Y22: =IFERROR(VLOOKUP(X22,'Puntos XCO'!$A$1:$B$63,2,FALSE),0) -> 70 | Z22: =IFERROR(VLOOKUP($C22,RESXCC_1,9,FALSE),0) -> 7 | AA22: =IFERROR(VLOOKUP(Z22,'Puntos XCC Mayor'!$A$1:$B$15,2,FALSE),0) -> 9 | AB22: =IFERROR(VLOOKUP($C22,RESXCO,9,FALSE),0) -> 7 | AC22: =IFERROR(VLOOKUP(AB22,'Puntos XCO'!$A$1:$B$63,2,FALSE),0) -> 90 | AH22: =G22+I22+K22+M22+O22+Q22+S22+U22+W22+Y22+AA22+AC22+AE22+AG22 -> 401
A23: 9 | B23: 7 | C23: 9 | D23: GONZALEZ Raymond | E23: CICLO VÍCTOR VARGAS | F23: 5 | G23: 12 | H23: 2 | I23: 150 | J23: 4 | K23: 14 | L23: 4 | M23: 110 | N23: 6 | O23: =IFERROR(VLOOKUP(N23,'Puntos XCC Mayor'!$A$1:$B$15,2,FALSE),0) -> 10 | P23: 6 | Q23: =IFERROR(VLOOKUP(P23,'Puntos XCO'!$A$1:$B$63,2,FALSE),0) -> 95 | R23: 0 | S23: =IFERROR(VLOOKUP(R23,'Puntos XCC Mayor'!$A$1:$B$15,2,FALSE),0) -> 0 | T23: 0 | U23: =IFERROR(VLOOKUP(T23,'Puntos XCO'!$A$1:$B$63,2,FALSE),0) -> 0 | V23: 0 | W23: =IFERROR(VLOOKUP(V23,'Puntos XCC Mayor'!$A$1:$B$15,2,FALSE),0) -> 0 | X23: 0 | Y23: =IFERROR(VLOOKUP(X23,'Puntos XCO'!$A$1:$B$63,2,FALSE),0) -> 0 | Z23: =IFERROR(VLOOKUP($C23,RESXCC_1,9,FALSE),0) -> 0 | AA23: =IFERROR(VLOOKUP(Z23,'Puntos XCC Mayor'!$A$1:$B$15,2,FALSE),0) -> 0 | AB23: =IFERROR(VLOOKUP($C23,RESXCO,9,FALSE),0) -> 0 | AC23: =IFERROR(VLOOKUP(AB23,'Puntos XCO'!$A$1:$B$63,2,FALSE),0) -> 0 | AH23: =G23+I23+K23+M23+O23+Q23+S23+U23+W23+Y23+AA23+AC23+AE23+AG23 -> 391
A24: 10 | B24: 8 | C24: 13 | D24: SOLÍS Keiron | E24: PEDREGAL - 7C | N24: 5 | O24: =IFERROR(VLOOKUP(N24,'Puntos XCC Mayor'!$A$1:$B$15,2,FALSE),0) -> 12 | Q24: =IFERROR(VLOOKUP(P24,'Puntos XCO'!$A$1:$B$63,2,FALSE),0) -> 0 | R24: 3 | S24: =IFERROR(VLOOKUP(R24,'Puntos XCC Mayor'!$A$1:$B$15,2,FALSE),0) -> 16 | T24: 3 | U24: =IFERROR(VLOOKUP(T24,'Puntos XCO'!$A$1:$B$63,2,FALSE),0) -> 120 | V24: 1 | W24: =IFERROR(VLOOKUP(V24,'Puntos XCC Mayor'!$A$1:$B$15,2,FALSE),0) -> 25 | X24: 1 | Y24: =IFERROR(VLOOKUP(X24,'Puntos XCO'!$A$1:$B$63,2,FALSE),0) -> 200 | Z24: =IFERROR(VLOOKUP($C24,RESXCC_1,9,FALSE),0) -> 0 | AA24: =IFERROR(VLOOKUP(Z24,'Puntos XCC Mayor'!$A$1:$B$15,2,FALSE),0) -> 0 | AB24: =IFERROR(VLOOKUP($C24,RESXCO,9,FALSE),0) -> 0 | AC24: =IFERROR(VLOOKUP(AB24,'Puntos XCO'!$A$1:$B$63,2,FALSE),0) -> 0 | AH24: =G24+I24+K24+M24+O24+Q24+S24+U24+W24+Y24+AA24+AC24+AE24+AG24 -> 373
A25: 11 | B25: 9 | C25: 10 | D25: VARGAS Steven Andres | E25: SCOTT SHIMANO CYCLING TEAM | F25: 14 | G25: 2 | H25: 6 | I25: 95 | J25: 0 | K25: 0 | L25: 10 | M25: 78 | N25: 25 | O25: =IFERROR(VLOOKUP(N25,'Puntos XCC Mayor'!$A$1:$B$15,2,FALSE),0) -> 0 | P25: 10 | Q25: =IFERROR(VLOOKUP(P25,'Puntos XCO'!$A$1:$B$63,2,FALSE),0) -> 78 | R25: 7 | S25: =IFERROR(VLOOKUP(R25,'Puntos XCC Mayor'!$A$1:$B$15,2,FALSE),0) -> 9 | T25: 6 | U25: =IFERROR(VLOOKUP(T25,'Puntos XCO'!$A$1:$B$63,2,FALSE),0) -> 95 | V25: 0 | W25: =IFERROR(VLOOKUP(V25,'Puntos XCC Mayor'!$A$1:$B$15,2,FALSE),0) -> 0 | X25: 0 | Y25: =IFERROR(VLOOKUP(X25,'Puntos XCO'!$A$1:$B$63,2,FALSE),0) -> 0 | Z25: =IFERROR(VLOOKUP($C25,RESXCC_1,9,FALSE),0) -> 0 | AA25: =IFERROR(VLOOKUP(Z25,'Puntos XCC Mayor'!$A$1:$B$15,2,FALSE),0) -> 0 | AB25: =IFERROR(VLOOKUP($C25,RESXCO,9,FALSE),0) -> 0 | AC25: =IFERROR(VLOOKUP(AB25,'Puntos XCO'!$A$1:$B$63,2,FALSE),0) -> 0 | AH25: =G25+I25+K25+M25+O25+Q25+S25+U25+W25+Y25+AA25+AC25+AE25+AG25 -> 357
A26: 12 | B26: 14 | C26: 30 | D26: ALVARADO Armando* | E26: CCDR DESAMPARADOS | F26: 9 | G26: 7 | H26: 11 | I26: 76 | J26: 0 | K26: 0 | L26: 13 | M26: 72 | N26: 18 | O26: =IFERROR(VLOOKUP(N26,'Puntos XCC Mayor'!$A$1:$B$15,2,FALSE),0) -> 0 | Q26: =IFERROR(VLOOKUP(P26,'Puntos XCO'!$A$1:$B$63,2,FALSE),0) -> 0 | R26: 11 | S26: =IFERROR(VLOOKUP(R26,'Puntos XCC Mayor'!$A$1:$B$15,2,FALSE),0) -> 5 | T26: 0 | U26: =IFERROR(VLOOKUP(T26,'Puntos XCO'!$A$1:$B$63,2,FALSE),0) -> 0 | V26: 13 | W26: =IFERROR(VLOOKUP(V26,'Puntos XCC Mayor'!$A$1:$B$15,2,FALSE),0) -> 3 | X26: 9 | Y26: =IFERROR(VLOOKUP(X26,'Puntos XCO'!$A$1:$B$63,2,FALSE),0) -> 80 | Z26: =IFERROR(VLOOKUP($C26,RESXCC_1,9,FALSE),0) -> 6 | AA26: =IFERROR(VLOOKUP(Z26,'Puntos XCC Mayor'!$A$1:$B$15,2,FALSE),0) -> 10 | AB26: =IFERROR(VLOOKUP($C26,RESXCO,9,FALSE),0) -> 10 | AC26: =IFERROR(VLOOKUP(AB26,'Puntos XCO'!$A$1:$B$63,2,FALSE),0) -> 78 | AH26: =G26+I26+K26+M26+O26+Q26+S26+U26+W26+Y26+AA26+AC26+AE26+AG26 -> 331
A27: 13 | B27: 11 | C27: 29 | D27: HIDALGO Stefano* | E27: BOBBYS CYCLING TEAM | F27: 7 | G27: 9 | H27: 12 | I27: 74 | J27: 10 | K27: 6 | L27: 12 | M27: 74 | N27: 23 | O27: =IFERROR(VLOOKUP(N27,'Puntos XCC Mayor'!$A$1:$B$15,2,FALSE),0) -> 0 | P27: 11 | Q27: =IFERROR(VLOOKUP(P27,'Puntos XCO'!$A$1:$B$63,2,FALSE),0) -> 76 | R27: 8 | S27: =IFERROR(VLOOKUP(R27,'Puntos XCC Mayor'!$A$1:$B$15,2,FALSE),0) -> 8 | T27: 0 | U27: =IFERROR(VLOOKUP(T27,'Puntos XCO'!$A$1:$B$63,2,FALSE),0) -> 0 | V27: 7 | W27: =IFERROR(VLOOKUP(V27,'Puntos XCC Mayor'!$A$1:$B$15,2,FALSE),0) -> 9 | X27: 13 | Y27: =IFERROR(VLOOKUP(X27,'Puntos XCO'!$A$1:$B$63,2,FALSE),0) -> 72 | Z27: =IFERROR(VLOOKUP($C27,RESXCC_1,9,FALSE),0) -> 0 | AA27: =IFERROR(VLOOKUP(Z27,'Puntos XCC Mayor'!$A$1:$B$15,2,FALSE),0) -> 0 | AB27: =IFERROR(VLOOKUP($C27,RESXCO,9,FALSE),0) -> 0 | AC27: =IFERROR(VLOOKUP(AB27,'Puntos XCO'!$A$1:$B$63,2,FALSE),0) -> 0 | AH27: =G27+I27+K27+M27+O27+Q27+S27+U27+W27+Y27+AA27+AC27+AE27+AG27 -> 328
A28: 14 | B28: 13 | C28: 23 | D28: MENDEZ Jared* | E28: BOBBYS CYCLING TEAM | F28: 1 | G28: 25 | H28: 5 | I28: 100 | J28: 3 | K28: 16 | L28: 0 | M28: 0 | N28: 11 | O28: =IFERROR(VLOOKUP(N28,'Puntos XCC Mayor'!$A$1:$B$15,2,FALSE),0) -> 5 | Q28: =IFERROR(VLOOKUP(P28,'Puntos XCO'!$A$1:$B$63,2,FALSE),0) -> 0 | R28: 0 | S28: =IFERROR(VLOOKUP(R28,'Puntos XCC Mayor'!$A$1:$B$15,2,FALSE),0) -> 0 | T28: 0 | U28: =IFERROR(VLOOKUP(T28,'Puntos XCO'!$A$1:$B$63,2,FALSE),0) -> 0 | V28: 3 | W28: =IFERROR(VLOOKUP(V28,'Puntos XCC Mayor'!$A$1:$B$15,2,FALSE),0) -> 16 | X28: 4 | Y28: =IFERROR(VLOOKUP(X28,'Puntos XCO'!$A$1:$B$63,2,FALSE),0) -> 110 | Z28: =IFERROR(VLOOKUP($C28,RESXCC_1,9,FALSE),0) -> 0 | AA28: =IFERROR(VLOOKUP(Z28,'Puntos XCC Mayor'!$A$1:$B$15,2,FALSE),0) -> 0 | AB28: =IFERROR(VLOOKUP($C28,RESXCO,9,FALSE),0) -> 0 | AC28: =IFERROR(VLOOKUP(AB28,'Puntos XCO'!$A$1:$B$63,2,FALSE),0) -> 0 | AH28: =G28+I28+K28+M28+O28+Q28+S28+U28+W28+Y28+AA28+AC28+AE28+AG28 -> 272
A29: 15 | B29: 24 | C29: 32 | D29: TORRES Kevin* | E29: 1000 FPS- ZONA INFINITO SPORT | F29: 16 | G29: 0 | H29: 16 | I29: 66 | J29: 0 | K29: 0 | L29: 0 | M29: 0 | N29: 27 | O29: =IFERROR(VLOOKUP(N29,'Puntos XCC Mayor'!$A$1:$B$15,2,FALSE),0) -> 0 | P29: 12 | Q29: =IFERROR(VLOOKUP(P29,'Puntos XCO'!$A$1:$B$63,2,FALSE),0) -> 74 | R29: 0 | S29: =IFERROR(VLOOKUP(R29,'Puntos XCC Mayor'!$A$1:$B$15,2,FALSE),0) -> 0 | T29: 0 | U29: =IFERROR(VLOOKUP(T29,'Puntos XCO'!$A$1:$B$63,2,FALSE),0) -> 0 | V29: 0 | W29: =IFERROR(VLOOKUP(V29,'Puntos XCC Mayor'!$A$1:$B$15,2,FALSE),0) -> 0 | X29: 0 | Y29: =IFERROR(VLOOKUP(X29,'Puntos XCO'!$A$1:$B$63,2,FALSE),0) -> 0 | Z29: =IFERROR(VLOOKUP($C29,RESXCC_1,9,FALSE),0) -> 10 | AA29: =IFERROR(VLOOKUP(Z29,'Puntos XCC Mayor'!$A$1:$B$15,2,FALSE),0) -> 6 | AB29: =IFERROR(VLOOKUP($C29,RESXCO,9,FALSE),0) -> 9 | AC29: =IFERROR(VLOOKUP(AB29,'Puntos XCO'!$A$1:$B$63,2,FALSE),0) -> 80 | AH29: =G29+I29+K29+M29+O29+Q29+S29+U29+W29+Y29+AA29+AC29+AE29+AG29 -> 226
A30: 16 | B30: 15 | C30: 1 | D30: MARQUES José Gabriel | E30: COD RACING | N30: 1 | O30: =IFERROR(VLOOKUP(N30,'Puntos XCC Mayor'!$A$1:$B$15,2,FALSE),0) -> 25 | P30: 1 | Q30: =IFERROR(VLOOKUP(P30,'Puntos XCO'!$A$1:$B$63,2,FALSE),0) -> 200 | R30: 0 | S30: =IFERROR(VLOOKUP(R30,'Puntos XCC Mayor'!$A$1:$B$15,2,FALSE),0) -> 0 | T30: 0 | U30: =IFERROR(VLOOKUP(T30,'Puntos XCO'!$A$1:$B$63,2,FALSE),0) -> 0 | V30: 0 | W30: =IFERROR(VLOOKUP(V30,'Puntos XCC Mayor'!$A$1:$B$15,2,FALSE),0) -> 0 | X30: 0 | Y30: =IFERROR(VLOOKUP(X30,'Puntos XCO'!$A$1:$B$63,2,FALSE),0) -> 0 | Z30: =IFERROR(VLOOKUP($C30,RESXCC_1,9,FALSE),0) -> 0 | AA30: =IFERROR(VLOOKUP(Z30,'Puntos XCC Mayor'!$A$1:$B$15,2,FALSE),0) -> 0 | AB30: =IFERROR(VLOOKUP($C30,RESXCO,9,FALSE),0) -> 0 | AC30: =IFERROR(VLOOKUP(AB30,'Puntos XCO'!$A$1:$B$63,2,FALSE),0) -> 0 | AH30: =G30+I30+K30+M30+O30+Q30+S30+U30+W30+Y30+AA30+AC30+AE30+AG30 -> 225
A31: 17 | B31: 16 | C31: 7 | D31: MONTOYA Paolo | E31: COLONO BIKE STATION KOLBI | O31: =IFERROR(VLOOKUP(N31,'Puntos XCC Mayor'!$A$1:$B$15,2,FALSE),0) -> 0 | P31: 7 | Q31: =IFERROR(VLOOKUP(P31,'Puntos XCO'!$A$1:$B$63,2,FALSE),0) -> 90 | R31: 0 | S31: =IFERROR(VLOOKUP(R31,'Puntos XCC Mayor'!$A$1:$B$15,2,FALSE),0) -> 0 | T31: 0 | U31: =IFERROR(VLOOKUP(T31,'Puntos XCO'!$A$1:$B$63,2,FALSE),0) -> 0 | V31: 0 | W31: =IFERROR(VLOOKUP(V31,'Puntos XCC Mayor'!$A$1:$B$15,2,FALSE),0) -> 0 | X31: 3 | Y31: =IFERROR(VLOOKUP(X31,'Puntos XCO'!$A$1:$B$63,2,FALSE),0) -> 120 | Z31: =IFERROR(VLOOKUP($C31,RESXCC_1,9,FALSE),0) -> 0 | AA31: =IFERROR(VLOOKUP(Z31,'Puntos XCC Mayor'!$A$1:$B$15,2,FALSE),0) -> 0 | AB31: =IFERROR(VLOOKUP($C31,RESXCO,9,FALSE),0) -> 0 | AC31: =IFERROR(VLOOKUP(AB31,'Puntos XCO'!$A$1:$B$63,2,FALSE),0) -> 0 | AH31: =G31+I31+K31+M31+O31+Q31+S31+U31+W31+Y31+AA31+AC31+AE31+AG31 -> 210
A32: 18 | B32: 17 | C32: 22 | D32: TAILLEFER Tristan* | E32: PIVOT OTE CONTINENTAL | N32: 8 | O32: =IFERROR(VLOOKUP(N32,'Puntos XCC Mayor'!$A$1:$B$15,2,FALSE),0) -> 8 | P32: 1 | Q32: =IFERROR(VLOOKUP(P32,'Puntos XCO'!$A$1:$B$63,2,FALSE),0) -> 200 | R32: 0 | S32: =IFERROR(VLOOKUP(R32,'Puntos XCC Mayor'!$A$1:$B$15,2,FALSE),0) -> 0 | T32: 0 | U32: =IFERROR(VLOOKUP(T32,'Puntos XCO'!$A$1:$B$63,2,FALSE),0) -> 0 | V32: 0 | W32: =IFERROR(VLOOKUP(V32,'Puntos XCC Mayor'!$A$1:$B$15,2,FALSE),0) -> 0 | X32: 0 | Y32: =IFERROR(VLOOKUP(X32,'Puntos XCO'!$A$1:$B$63,2,FALSE),0) -> 0 | Z32: =IFERROR(VLOOKUP($C32,RESXCC_1,9,FALSE),0) -> 0 | AA32: =IFERROR(VLOOKUP(Z32,'Puntos XCC Mayor'!$A$1:$B$15,2,FALSE),0) -> 0 | AB32: =IFERROR(VLOOKUP($C32,RESXCO,9,FALSE),0) -> 0 | AC32: =IFERROR(VLOOKUP(AB32,'Puntos XCO'!$A$1:$B$63,2,FALSE),0) -> 0 | AH32: =G32+I32+K32+M32+O32+Q32+S32+U32+W32+Y32+AA32+AC32+AE32+AG32 -> 208
A33: 19 | B33: 18 | D33: ASTUA Kyvan | E33: INDEPENDIENTE | F33: 12 | G33: 4 | H33: 7 | I33: 90 | J33: 3 | K33: 16 | L33: 15 | M33: 68 | O33: =IFERROR(VLOOKUP(N33,'Puntos XCC Mayor'!$A$1:$B$15,2,FALSE),0) -> 0 | Q33: =IFERROR(VLOOKUP(P33,'Puntos XCO'!$A$1:$B$63,2,FALSE),0) -> 0 | R33: 0 | S33: =IFERROR(VLOOKUP(R33,'Puntos XCC Mayor'!$A$1:$B$15,2,FALSE),0) -> 0 | T33: 0 | U33: =IFERROR(VLOOKUP(T33,'Puntos XCO'!$A$1:$B$63,2,FALSE),0) -> 0 | V33: 0 | W33: =IFERROR(VLOOKUP(V33,'Puntos XCC Mayor'!$A$1:$B$15,2,FALSE),0) -> 0 | X33: 0 | Y33: =IFERROR(VLOOKUP(X33,'Puntos XCO'!$A$1:$B$63,2,FALSE),0) -> 0 | Z33: =IFERROR(VLOOKUP($C33,RESXCC_1,9,FALSE),0) -> 0 | AA33: =IFERROR(VLOOKUP(Z33,'Puntos XCC Mayor'!$A$1:$B$15,2,FALSE),0) -> 0 | AB33: =IFERROR(VLOOKUP($C33,RESXCO,9,FALSE),0) -> 0 | AC33: =IFERROR(VLOOKUP(AB33,'Puntos XCO'!$A$1:$B$63,2,FALSE),0) -> 0 | AH33: =G33+I33+K33+M33+O33+Q33+S33+U33+W33+Y33+AA33+AC33+AE33+AG33 -> 178
A34: 20 | B34: 39 | C34: 41 | D34: =VLOOKUP(C34,PLANILLA,2,FALSE) -> FERNADEZ Fabricio Alberto* | E34: =VLOOKUP(C34,PLANILLA,4,FALSE) -> Sin equipo | V34: 0 | W34: =IFERROR(VLOOKUP(V34,'Puntos XCC Mayor'!$A$1:$B$15,2,FALSE),0) -> 0 | X34: 15 | Y34: =IFERROR(VLOOKUP(X34,'Puntos XCO'!$A$1:$B$63,2,FALSE),0) -> 68 | Z34: =IFERROR(VLOOKUP($C34,RESXCC_1,9,FALSE),0) -> 8 | AA34: =IFERROR(VLOOKUP(Z34,'Puntos XCC Mayor'!$A$1:$B$15,2,FALSE),0) -> 8 | AB34: =IFERROR(VLOOKUP($C34,RESXCO,9,FALSE),0) -> 6 | AC34: =IFERROR(VLOOKUP(AB34,'Puntos XCO'!$A$1:$B$63,2,FALSE),0) -> 95 | AH34: =G34+I34+K34+M34+O34+Q34+S34+U34+W34+Y34+AA34+AC34+AE34+AG34 -> 171
A35: 21 | B35: 19 | C35: 8 | D35: FONSECA Andrey | E35: TEAM INNOVABIKES SKOLER UH | J35: 0 | K35: 0 | L35: 8 | M35: 85 | N35: 22 | O35: =IFERROR(VLOOKUP(N35,'Puntos XCC Mayor'!$A$1:$B$15,2,FALSE),0) -> 0 | P35: 8 | Q35: =IFERROR(VLOOKUP(P35,'Puntos XCO'!$A$1:$B$63,2,FALSE),0) -> 85 | R35: 0 | S35: =IFERROR(VLOOKUP(R35,'Puntos XCC Mayor'!$A$1:$B$15,2,FALSE),0) -> 0 | T35: 0 | U35: =IFERROR(VLOOKUP(T35,'Puntos XCO'!$A$1:$B$63,2,FALSE),0) -> 0 | V35: 0 | W35: =IFERROR(VLOOKUP(V35,'Puntos XCC Mayor'!$A$1:$B$15,2,FALSE),0) -> 0 | X35: 0 | Y35: =IFERROR(VLOOKUP(X35,'Puntos XCO'!$A$1:$B$63,2,FALSE),0) -> 0 | Z35: =IFERROR(VLOOKUP($C35,RESXCC_1,9,FALSE),0) -> 0 | AA35: =IFERROR(VLOOKUP(Z35,'Puntos XCC Mayor'!$A$1:$B$15,2,FALSE),0) -> 0 | AB35: =IFERROR(VLOOKUP($C35,RESXCO,9,FALSE),0) -> 0 | AC35: =IFERROR(VLOOKUP(AB35,'Puntos XCO'!$A$1:$B$63,2,FALSE),0) -> 0 | AH35: =G35+I35+K35+M35+O35+Q35+S35+U35+W35+Y35+AA35+AC35+AE35+AG35 -> 170
A36: 22 | B36: 20 | C36: 35 | D36: CASTILLO Alejandro* | E36: COLONO BIKE STATION KOLBI | N36: 24 | O36: =IFERROR(VLOOKUP(N36,'Puntos XCC Mayor'!$A$1:$B$15,2,FALSE),0) -> 0 | Q36: =IFERROR(VLOOKUP(P36,'Puntos XCO'!$A$1:$B$63,2,FALSE),0) -> 0 | R36: 0 | S36: =IFERROR(VLOOKUP(R36,'Puntos XCC Mayor'!$A$1:$B$15,2,FALSE),0) -> 0 | T36: 10 | U36: =IFERROR(VLOOKUP(T36,'Puntos XCO'!$A$1:$B$63,2,FALSE),0) -> 78 | V36: 9 | W36: =IFERROR(VLOOKUP(V36,'Puntos XCC Mayor'!$A$1:$B$15,2,FALSE),0) -> 7 | X36: 10 | Y36: =IFERROR(VLOOKUP(X36,'Puntos XCO'!$A$1:$B$63,2,FALSE),0) -> 78 | Z36: =IFERROR(VLOOKUP($C36,RESXCC_1,9,FALSE),0) -> 0 | AA36: =IFERROR(VLOOKUP(Z36,'Puntos XCC Mayor'!$A$1:$B$15,2,FALSE),0) -> 0 | AB36: =IFERROR(VLOOKUP($C36,RESXCO,9,FALSE),0) -> 0 | AC36: =IFERROR(VLOOKUP(AB36,'Puntos XCO'!$A$1:$B$63,2,FALSE),0) -> 0 | AH36: =G36+I36+K36+M36+O36+Q36+S36+U36+W36+Y36+AA36+AC36+AE36+AG36 -> 163
A37: 23 | B37: 21 | C37: 21 | D37: SAN MARTIN Maximiliano* | E37: ER CICLISMO CHILE. | N37: 10 | O37: =IFERROR(VLOOKUP(N37,'Puntos XCC Mayor'!$A$1:$B$15,2,FALSE),0) -> 6 | P37: 2 | Q37: =IFERROR(VLOOKUP(P37,'Puntos XCO'!$A$1:$B$63,2,FALSE),0) -> 150 | R37: 0 | S37: =IFERROR(VLOOKUP(R37,'Puntos XCC Mayor'!$A$1:$B$15,2,FALSE),0) -> 0 | T37: 0 | U37: =IFERROR(VLOOKUP(T37,'Puntos XCO'!$A$1:$B$63,2,FALSE),0) -> 0 | V37: 0 | W37: =IFERROR(VLOOKUP(V37,'Puntos XCC Mayor'!$A$1:$B$15,2,FALSE),0) -> 0 | X37: 0 | Y37: =IFERROR(VLOOKUP(X37,'Puntos XCO'!$A$1:$B$63,2,FALSE),0) -> 0 | Z37: =IFERROR(VLOOKUP($C37,RESXCC_1,9,FALSE),0) -> 0 | AA37: =IFERROR(VLOOKUP(Z37,'Puntos XCC Mayor'!$A$1:$B$15,2,FALSE),0) -> 0 | AB37: =IFERROR(VLOOKUP($C37,RESXCO,9,FALSE),0) -> 0 | AC37: =IFERROR(VLOOKUP(AB37,'Puntos XCO'!$A$1:$B$63,2,FALSE),0) -> 0 | AH37: =G37+I37+K37+M37+O37+Q37+S37+U37+W37+Y37+AA37+AC37+AE37+AG37 -> 156
A38: 24 | B38: 22 | C38: 2 | D38: BOTERO Jhonnatan | E38: GW ERCO SPORTFITNESS | O38: =IFERROR(VLOOKUP(N38,'Puntos XCC Mayor'!$A$1:$B$15,2,FALSE),0) -> 0 | P38: 2 | Q38: =IFERROR(VLOOKUP(P38,'Puntos XCO'!$A$1:$B$63,2,FALSE),0) -> 150 | R38: 0 | S38: =IFERROR(VLOOKUP(R38,'Puntos XCC Mayor'!$A$1:$B$15,2,FALSE),0) -> 0 | T38: 0 | U38: =IFERROR(VLOOKUP(T38,'Puntos XCO'!$A$1:$B$63,2,FALSE),0) -> 0 | V38: 0 | W38: =IFERROR(VLOOKUP(V38,'Puntos XCC Mayor'!$A$1:$B$15,2,FALSE),0) -> 0 | X38: 0 | Y38: =IFERROR(VLOOKUP(X38,'Puntos XCO'!$A$1:$B$63,2,FALSE),0) -> 0 | Z38: =IFERROR(VLOOKUP($C38,RESXCC_1,9,FALSE),0) -> 0 | AA38: =IFERROR(VLOOKUP(Z38,'Puntos XCC Mayor'!$A$1:$B$15,2,FALSE),0) -> 0 | AB38: =IFERROR(VLOOKUP($C38,RESXCO,9,FALSE),0) -> 0 | AC38: =IFERROR(VLOOKUP(AB38,'Puntos XCO'!$A$1:$B$63,2,FALSE),0) -> 0 | AH38: =G38+I38+K38+M38+O38+Q38+S38+U38+W38+Y38+AA38+AC38+AE38+AG38 -> 150
A39: 25 | B39: 23 | C39: 6 | D39: RAMÍREZ Joseph | E39: COLONO BIKE STATION KOLBI | J39: 0 | K39: 0 | L39: 2 | M39: 150 | O39: =IFERROR(VLOOKUP(N39,'Puntos XCC Mayor'!$A$1:$B$15,2,FALSE),0) -> 0 | Q39: =IFERROR(VLOOKUP(P39,'Puntos XCO'!$A$1:$B$63,2,FALSE),0) -> 0 | R39: 0 | S39: =IFERROR(VLOOKUP(R39,'Puntos XCC Mayor'!$A$1:$B$15,2,FALSE),0) -> 0 | T39: 0 | U39: =IFERROR(VLOOKUP(T39,'Puntos XCO'!$A$1:$B$63,2,FALSE),0) -> 0 | V39: 0 | W39: =IFERROR(VLOOKUP(V39,'Puntos XCC Mayor'!$A$1:$B$15,2,FALSE),0) -> 0 | X39: 0 | Y39: =IFERROR(VLOOKUP(X39,'Puntos XCO'!$A$1:$B$63,2,FALSE),0) -> 0 | Z39: =IFERROR(VLOOKUP($C39,RESXCC_1,9,FALSE),0) -> 0 | AA39: =IFERROR(VLOOKUP(Z39,'Puntos XCC Mayor'!$A$1:$B$15,2,FALSE),0) -> 0 | AB39: =IFERROR(VLOOKUP($C39,RESXCO,9,FALSE),0) -> 0 | AC39: =IFERROR(VLOOKUP(AB39,'Puntos XCO'!$A$1:$B$63,2,FALSE),0) -> 0 | AH39: =G39+I39+K39+M39+O39+Q39+S39+U39+W39+Y39+AA39+AC39+AE39+AG39 -> 150
A40: 26 | B40: 40 | C40: 40 | D40: =VLOOKUP(C40,PLANILLA,2,FALSE) -> GUTIERREZ Carlos Daniel | E40: =VLOOKUP(C40,PLANILLA,4,FALSE) -> turrialba | V40: 14 | W40: =IFERROR(VLOOKUP(V40,'Puntos XCC Mayor'!$A$1:$B$15,2,FALSE),0) -> 2 | X40: 16 | Y40: =IFERROR(VLOOKUP(X40,'Puntos XCO'!$A$1:$B$63,2,FALSE),0) -> 66 | Z40: =IFERROR(VLOOKUP($C40,RESXCC_1,9,FALSE),0) -> 11 | AA40: =IFERROR(VLOOKUP(Z40,'Puntos XCC Mayor'!$A$1:$B$15,2,FALSE),0) -> 5 | AB40: =IFERROR(VLOOKUP($C40,RESXCO,9,FALSE),0) -> 11 | AC40: =IFERROR(VLOOKUP(AB40,'Puntos XCO'!$A$1:$B$63,2,FALSE),0) -> 76 | AH40: =G40+I40+K40+M40+O40+Q40+S40+U40+W40+Y40+AA40+AC40+AE40+AG40 -> 149
A41: 27 | B41: 25 | C41: 5 | D41: BEDOYA Jeronimo | E41: GW ERCO SPORTFITNESS | N41: 3 | O41: =IFERROR(VLOOKUP(N41,'Puntos XCC Mayor'!$A$1:$B$15,2,FALSE),0) -> 16 | P41: 3 | Q41: =IFERROR(VLOOKUP(P41,'Puntos XCO'!$A$1:$B$63,2,FALSE),0) -> 120 | R41: 0 | S41: =IFERROR(VLOOKUP(R41,'Puntos XCC Mayor'!$A$1:$B$15,2,FALSE),0) -> 0 | T41: 0 | U41: =IFERROR(VLOOKUP(T41,'Puntos XCO'!$A$1:$B$63,2,FALSE),0) -> 0 | V41: 0 | W41: =IFERROR(VLOOKUP(V41,'Puntos XCC Mayor'!$A$1:$B$15,2,FALSE),0) -> 0 | X41: 0 | Y41: =IFERROR(VLOOKUP(X41,'Puntos XCO'!$A$1:$B$63,2,FALSE),0) -> 0 | Z41: =IFERROR(VLOOKUP($C41,RESXCC_1,9,FALSE),0) -> 0 | AA41: =IFERROR(VLOOKUP(Z41,'Puntos XCC Mayor'!$A$1:$B$15,2,FALSE),0) -> 0 | AB41: =IFERROR(VLOOKUP($C41,RESXCO,9,FALSE),0) -> 0 | AC41: =IFERROR(VLOOKUP(AB41,'Puntos XCO'!$A$1:$B$63,2,FALSE),0) -> 0 | AH41: =G41+I41+K41+M41+O41+Q41+S41+U41+W41+Y41+AA41+AC41+AE41+AG41 -> 136
A42: 28 | B42: 26 | C42: 14 | D42: AGUILAR Ivan | E42: REGULUS 333 | N42: 2 | O42: =IFERROR(VLOOKUP(N42,'Puntos XCC Mayor'!$A$1:$B$15,2,FALSE),0) -> 20 | P42: 4 | Q42: =IFERROR(VLOOKUP(P42,'Puntos XCO'!$A$1:$B$63,2,FALSE),0) -> 110 | R42: 0 | S42: =IFERROR(VLOOKUP(R42,'Puntos XCC Mayor'!$A$1:$B$15,2,FALSE),0) -> 0 | T42: 0 | U42: =IFERROR(VLOOKUP(T42,'Puntos XCO'!$A$1:$B$63,2,FALSE),0) -> 0 | V42: 0 | W42: =IFERROR(VLOOKUP(V42,'Puntos XCC Mayor'!$A$1:$B$15,2,FALSE),0) -> 0 | X42: 0 | Y42: =IFERROR(VLOOKUP(X42,'Puntos XCO'!$A$1:$B$63,2,FALSE),0) -> 0 | Z42: =IFERROR(VLOOKUP($C42,RESXCC_1,9,FALSE),0) -> 0 | AA42: =IFERROR(VLOOKUP(Z42,'Puntos XCC Mayor'!$A$1:$B$15,2,FALSE),0) -> 0 | AB42: =IFERROR(VLOOKUP($C42,RESXCO,9,FALSE),0) -> 0 | AC42: =IFERROR(VLOOKUP(AB42,'Puntos XCO'!$A$1:$B$63,2,FALSE),0) -> 0 | AH42: =G42+I42+K42+M42+O42+Q42+S42+U42+W42+Y42+AA42+AC42+AE42+AG42 -> 130
A43: 29 | B43: 27 | C43: 31 | D43: MORA Kendall* | E43: CODEA ALAJUELA | F43: 17 | G43: 0 | H43: 17 | I43: 64 | J43: 16 | K43: 0 | L43: 19 | M43: 60 | N43: 26 | O43: =IFERROR(VLOOKUP(N43,'Puntos XCC Mayor'!$A$1:$B$15,2,FALSE),0) -> 0 | Q43: =IFERROR(VLOOKUP(P43,'Puntos XCO'!$A$1:$B$63,2,FALSE),0) -> 0 | R43: 0 | S43: =IFERROR(VLOOKUP(R43,'Puntos XCC Mayor'!$A$1:$B$15,2,FALSE),0) -> 0 | T43: 0 | U43: =IFERROR(VLOOKUP(T43,'Puntos XCO'!$A$1:$B$63,2,FALSE),0) -> 0 | V43: 0 | W43: =IFERROR(VLOOKUP(V43,'Puntos XCC Mayor'!$A$1:$B$15,2,FALSE),0) -> 0 | X43: 0 | Y43: =IFERROR(VLOOKUP(X43,'Puntos XCO'!$A$1:$B$63,2,FALSE),0) -> 0 | Z43: =IFERROR(VLOOKUP($C43,RESXCC_1,9,FALSE),0) -> 0 | AA43: =IFERROR(VLOOKUP(Z43,'Puntos XCC Mayor'!$A$1:$B$15,2,FALSE),0) -> 0 | AB43: =IFERROR(VLOOKUP($C43,RESXCO,9,FALSE),0) -> 0 | AC43: =IFERROR(VLOOKUP(AB43,'Puntos XCO'!$A$1:$B$63,2,FALSE),0) -> 0 | AH43: =G43+I43+K43+M43+O43+Q43+S43+U43+W43+Y43+AA43+AC43+AE43+AG43 -> 124
A44: 30 | B44: 28 | C44: 33 | D44: BRUNELLE Alix* | E44: SIBOIRE QUIROULE | O44: =IFERROR(VLOOKUP(N44,'Puntos XCC Mayor'!$A$1:$B$15,2,FALSE),0) -> 0 | P44: 5 | Q44: =IFERROR(VLOOKUP(P44,'Puntos XCO'!$A$1:$B$63,2,FALSE),0) -> 100 | R44: 0 | S44: =IFERROR(VLOOKUP(R44,'Puntos XCC Mayor'!$A$1:$B$15,2,FALSE),0) -> 0 | T44: 0 | U44: =IFERROR(VLOOKUP(T44,'Puntos XCO'!$A$1:$B$63,2,FALSE),0) -> 0 | V44: 0 | W44: =IFERROR(VLOOKUP(V44,'Puntos XCC Mayor'!$A$1:$B$15,2,FALSE),0) -> 0 | X44: 0 | Y44: =IFERROR(VLOOKUP(X44,'Puntos XCO'!$A$1:$B$63,2,FALSE),0) -> 0 | Z44: =IFERROR(VLOOKUP($C44,RESXCC_1,9,FALSE),0) -> 0 | AA44: =IFERROR(VLOOKUP(Z44,'Puntos XCC Mayor'!$A$1:$B$15,2,FALSE),0) -> 0 | AB44: =IFERROR(VLOOKUP($C44,RESXCO,9,FALSE),0) -> 0 | AC44: =IFERROR(VLOOKUP(AB44,'Puntos XCO'!$A$1:$B$63,2,FALSE),0) -> 0 | AH44: =G44+I44+K44+M44+O44+Q44+S44+U44+W44+Y44+AA44+AC44+AE44+AG44 -> 100
A45: 31 | C45: 43 | D45: =VLOOKUP(C45,PLANILLA,2,FALSE) -> SUNSIN Ean* | E45: =VLOOKUP(C45,PLANILLA,4,FALSE) -> ACISA - SARAPIQUÍ | Z45: =IFERROR(VLOOKUP($C45,RESXCC_1,9,FALSE),0) -> 9 | AA45: =IFERROR(VLOOKUP(Z45,'Puntos XCC Mayor'!$A$1:$B$15,2,FALSE),0) -> 7 | AB45: =IFERROR(VLOOKUP($C45,RESXCO,9,FALSE),0) -> 8 | AC45: =IFERROR(VLOOKUP(AB45,'Puntos XCO'!$A$1:$B$63,2,FALSE),0) -> 85 | AH45: =G45+I45+K45+M45+O45+Q45+S45+U45+W45+Y45+AA45+AC45+AE45+AG45 -> 92
A46: 32 | B46: 29 | C46: 34 | D46: RODRIGUEZ Angel* | E46: 7EIGHT7 PROJECT | N46: 20 | O46: =IFERROR(VLOOKUP(N46,'Puntos XCC Mayor'!$A$1:$B$15,2,FALSE),0) -> 0 | P46: 7 | Q46: =IFERROR(VLOOKUP(P46,'Puntos XCO'!$A$1:$B$63,2,FALSE),0) -> 90 | R46: 0 | S46: =IFERROR(VLOOKUP(R46,'Puntos XCC Mayor'!$A$1:$B$15,2,FALSE),0) -> 0 | T46: 0 | U46: =IFERROR(VLOOKUP(T46,'Puntos XCO'!$A$1:$B$63,2,FALSE),0) -> 0 | V46: 0 | W46: =IFERROR(VLOOKUP(V46,'Puntos XCC Mayor'!$A$1:$B$15,2,FALSE),0) -> 0 | X46: 0 | Y46: =IFERROR(VLOOKUP(X46,'Puntos XCO'!$A$1:$B$63,2,FALSE),0) -> 0 | Z46: =IFERROR(VLOOKUP($C46,RESXCC_1,9,FALSE),0) -> 0 | AA46: =IFERROR(VLOOKUP(Z46,'Puntos XCC Mayor'!$A$1:$B$15,2,FALSE),0) -> 0 | AB46: =IFERROR(VLOOKUP($C46,RESXCO,9,FALSE),0) -> 0 | AC46: =IFERROR(VLOOKUP(AB46,'Puntos XCO'!$A$1:$B$63,2,FALSE),0) -> 0 | AH46: =G46+I46+K46+M46+O46+Q46+S46+U46+W46+Y46+AA46+AC46+AE46+AG46 -> 90
A47: 33 | B47: 30 | C47: 24 | D47: DUVAL Mathis* | E47: SIBOIRE QUIROULE | N47: 7 | O47: =IFERROR(VLOOKUP(N47,'Puntos XCC Mayor'!$A$1:$B$15,2,FALSE),0) -> 9 | P47: 9 | Q47: =IFERROR(VLOOKUP(P47,'Puntos XCO'!$A$1:$B$63,2,FALSE),0) -> 80 | R47: 0 | S47: =IFERROR(VLOOKUP(R47,'Puntos XCC Mayor'!$A$1:$B$15,2,FALSE),0) -> 0 | T47: 0 | U47: =IFERROR(VLOOKUP(T47,'Puntos XCO'!$A$1:$B$63,2,FALSE),0) -> 0 | V47: 0 | W47: =IFERROR(VLOOKUP(V47,'Puntos XCC Mayor'!$A$1:$B$15,2,FALSE),0) -> 0 | X47: 0 | Y47: =IFERROR(VLOOKUP(X47,'Puntos XCO'!$A$1:$B$63,2,FALSE),0) -> 0 | Z47: =IFERROR(VLOOKUP($C47,RESXCC_1,9,FALSE),0) -> 0 | AA47: =IFERROR(VLOOKUP(Z47,'Puntos XCC Mayor'!$A$1:$B$15,2,FALSE),0) -> 0 | AB47: =IFERROR(VLOOKUP($C47,RESXCO,9,FALSE),0) -> 0 | AC47: =IFERROR(VLOOKUP(AB47,'Puntos XCO'!$A$1:$B$63,2,FALSE),0) -> 0 | AH47: =G47+I47+K47+M47+O47+Q47+S47+U47+W47+Y47+AA47+AC47+AE47+AG47 -> 89
A48: 34 | B48: 31 | D48: AGUILAR Jonathan* | E48: MANZA TÉ LA SELVA SCOTT | F48: 3 | G48: 16 | H48: 13 | I48: 72 | J48: 0 | K48: 0 | L48: 0 | M48: 0 | O48: =IFERROR(VLOOKUP(N48,'Puntos XCC Mayor'!$A$1:$B$15,2,FALSE),0) -> 0 | Q48: =IFERROR(VLOOKUP(P48,'Puntos XCO'!$A$1:$B$63,2,FALSE),0) -> 0 | R48: 0 | S48: =IFERROR(VLOOKUP(R48,'Puntos XCC Mayor'!$A$1:$B$15,2,FALSE),0) -> 0 | T48: 0 | U48: =IFERROR(VLOOKUP(T48,'Puntos XCO'!$A$1:$B$63,2,FALSE),0) -> 0 | V48: 0 | W48: =IFERROR(VLOOKUP(V48,'Puntos XCC Mayor'!$A$1:$B$15,2,FALSE),0) -> 0 | X48: 0 | Y48: =IFERROR(VLOOKUP(X48,'Puntos XCO'!$A$1:$B$63,2,FALSE),0) -> 0 | Z48: =IFERROR(VLOOKUP($C48,RESXCC_1,9,FALSE),0) -> 0 | AA48: =IFERROR(VLOOKUP(Z48,'Puntos XCC Mayor'!$A$1:$B$15,2,FALSE),0) -> 0 | AB48: =IFERROR(VLOOKUP($C48,RESXCO,9,FALSE),0) -> 0 | AC48: =IFERROR(VLOOKUP(AB48,'Puntos XCO'!$A$1:$B$63,2,FALSE),0) -> 0 | AH48: =G48+I48+K48+M48+O48+Q48+S48+U48+W48+Y48+AA48+AC48+AE48+AG48 -> 88
A49: 35 | B49: 32 | C49: 36 | D49: LUNA José Carlos* | E49: MI BICLA | N49: 17 | O49: =IFERROR(VLOOKUP(N49,'Puntos XCC Mayor'!$A$1:$B$15,2,FALSE),0) -> 0 | P49: 8 | Q49: =IFERROR(VLOOKUP(P49,'Puntos XCO'!$A$1:$B$63,2,FALSE),0) -> 85 | R49: 0 | S49: =IFERROR(VLOOKUP(R49,'Puntos XCC Mayor'!$A$1:$B$15,2,FALSE),0) -> 0 | T49: 0 | U49: =IFERROR(VLOOKUP(T49,'Puntos XCO'!$A$1:$B$63,2,FALSE),0) -> 0 | V49: 0 | W49: =IFERROR(VLOOKUP(V49,'Puntos XCC Mayor'!$A$1:$B$15,2,FALSE),0) -> 0 | X49: 0 | Y49: =IFERROR(VLOOKUP(X49,'Puntos XCO'!$A$1:$B$63,2,FALSE),0) -> 0 | Z49: =IFERROR(VLOOKUP($C49,RESXCC_1,9,FALSE),0) -> 0 | AA49: =IFERROR(VLOOKUP(Z49,'Puntos XCC Mayor'!$A$1:$B$15,2,FALSE),0) -> 0 | AB49: =IFERROR(VLOOKUP($C49,RESXCO,9,FALSE),0) -> 0 | AC49: =IFERROR(VLOOKUP(AB49,'Puntos XCO'!$A$1:$B$63,2,FALSE),0) -> 0 | AH49: =G49+I49+K49+M49+O49+Q49+S49+U49+W49+Y49+AA49+AC49+AE49+AG49 -> 85
...

Sheet Res I Fecha

Sheet Res II Fecha
A1: ELITE
A3: 2
A4: 1
A5: 20
A6: 3
A7: 28
A8: 34
A9: 109 | B9: sub 23
A10: 10
A11: 7
A12: 31
A13: 6
A14: 15
A15: 33
A16: 32
A17: 128 | B17: sub 23
A18: 9
A19: 121 | B19: sub 23
A20: 12
A21: 124 | B21: sub 23
A22: 11
A23: 22
A24: 4
A25: 125 | B25: sub 23
A26: 115 | B26: sub 23
A27: 24
A28: 35
A29: 117 | B29: sub 23
A30: 8
A31: 127 | B31: sub 23
A32: 37
A33: 110 | B33: sub 23
A34: 36
A35: 23
A36: 116 | B36: sub 23
A37: 123 | B37: sub 23
A38: 18
A39: 27
A40: 26
A41: 16
...

Sheet SUB23
A8: SUB23 MASCULINO (19-22)
A10: 1 - Finca Grupo Orosi >21 y 22 febrero 2 - Parque La Libertad Desamparados > 28 y 29 marzo 3 - Adventure Park > 16 y 17 mayo 4 - Finca La Hisopa San Pedro de Turrubares > 13 y 14 junio
A11: 5 - Campamento Oikoumene, Ochomogo > 18 y 19 julio 6 - Finca Grupo Orosi, Paraiso > 12 y 13 setiembre 7 - Parque Recreativo Sarapiqui > 31 Oct y 01 Nov
A13: POSICION | F13: 1 | J13: 2 | N13: 3 | R13: 4 | V13: 5 | Z13: 6 | AD13: 7 | AH13: TOTAL PUNTOS
A14: ACTUAL | B14: ANTERIOR | C14: NO | D14: NOMBRE | E14: EQUIPO | F14: POS XCC | G14: PTOS XCC | H14: POS XCO | I14: PTOS XCO | J14: POS XCC | K14: PTOS XCC | L14: POS XCO | M14: PTOS XCO | N14: POS XCC | O14: PTOS XCC | P14: POS XCO | Q14: PTOS XCO | R14: POS XCC | S14: PTOS XCC | T14: POS XCO | U14: PTOS XCO | V14: POS XCC | W14: PTOS XCC | X14: POS XCO | Y14: PTOS XCO | Z14: POS XCC | AA14: PTOS XCC | AB14: POS XCO | AC14: PTOS XCO | AD14: POS XCC | AE14: PTOS XCC | AF14: POS XCO | AG14: PTOS XCO
A15: 1 | B15: 1 | C15: 25 | D15: GONZÁLEZ Adriano* | E15: COLONO BIKE STATION KOLBI | F15: 3 | G15: =IFERROR(VLOOKUP(F15,'Puntos XCC Mayor'!$A$1:$B$15,2,FALSE),0) -> 16 | H15: 1 | I15: =IFERROR(VLOOKUP(H15,'Puntos XCO'!$A$1:$B$63,2,FALSE),0) -> 200 | J15: 2 | K15: =IFERROR(VLOOKUP(J15,'Puntos XCC Mayor'!$A$1:$B$15,2,FALSE),"0") -> 20 | L15: 1 | M15: =IFERROR(VLOOKUP(L15,'Puntos XCO'!$A$1:$B$63,2,FALSE),0) -> 200 | N15: 5 | O15: =IFERROR(VLOOKUP(N15,'Puntos XCC Mayor'!$A$1:$B$15,2,FALSE),0) -> 12 | P15: 4 | Q15: =IFERROR(VLOOKUP(P15,'Puntos XCO'!$A$1:$B$63,2,FALSE),0) -> 110 | R15: 2 | S15: =IFERROR(VLOOKUP(R15,'Puntos XCC Mayor'!$A$1:$B$15,2,FALSE),0) -> 20 | U15: =IFERROR(VLOOKUP(T15,'Puntos XCO'!$A$1:$B$63,2,FALSE),0) -> 0 | V15: 2 | W15: =IFERROR(VLOOKUP(V15,'Puntos XCC Mayor'!$A$1:$B$15,2,FALSE),0) -> 20 | X15: 2 | Y15: =IFERROR(VLOOKUP(X15,'Puntos XCO'!$A$1:$B$63,2,FALSE),0) -> 150 | Z15: 2 | AA15: =IFERROR(VLOOKUP(Z15,'Puntos XCC Mayor'!$A$1:$B$15,2,FALSE),0) -> 20 | AB15: 2 | AC15: =IFERROR(VLOOKUP(AB15,'Puntos XCO'!$A$1:$B$63,2,FALSE),0) -> 150 | AH15: =G15+I15+K15+M15+O15+Q15+S15+U15+W15+Y15+AA15+AC15+AE15+AG15 -> 918
A16: 2 | B16: 2 | C16: 27 | D16: RAABE Fabricio* | E16: COLONO BIKE STATION KOLBI | F16: 7 | G16: =IFERROR(VLOOKUP(F16,'Puntos XCC Mayor'!$A$1:$B$15,2,FALSE),0) -> 9 | H16: 2 | I16: =IFERROR(VLOOKUP(H16,'Puntos XCO'!$A$1:$B$63,2,FALSE),0) -> 150 | J16: 6 | K16: =IFERROR(VLOOKUP(J16,'Puntos XCC Mayor'!$A$1:$B$15,2,FALSE),"0") -> 10 | L16: 2 | M16: =IFERROR(VLOOKUP(L16,'Puntos XCO'!$A$1:$B$63,2,FALSE),0) -> 150 | N16: 6 | O16: =IFERROR(VLOOKUP(N16,'Puntos XCC Mayor'!$A$1:$B$15,2,FALSE),0) -> 10 | P16: 3 | Q16: =IFERROR(VLOOKUP(P16,'Puntos XCO'!$A$1:$B$63,2,FALSE),0) -> 120 | R16: 3 | S16: =IFERROR(VLOOKUP(R16,'Puntos XCC Mayor'!$A$1:$B$15,2,FALSE),0) -> 16 | T16: 2 | U16: =IFERROR(VLOOKUP(T16,'Puntos XCO'!$A$1:$B$63,2,FALSE),0) -> 150 | V16: 7 | W16: =IFERROR(VLOOKUP(V16,'Puntos XCC Mayor'!$A$1:$B$15,2,FALSE),0) -> 9 | X16: 4 | Y16: =IFERROR(VLOOKUP(X16,'Puntos XCO'!$A$1:$B$63,2,FALSE),0) -> 110 | Z16: 3 | AA16: =IFERROR(VLOOKUP(Z16,'Puntos XCC Mayor'!$A$1:$B$15,2,FALSE),0) -> 16 | AB16: 3 | AC16: =IFERROR(VLOOKUP(AB16,'Puntos XCO'!$A$1:$B$63,2,FALSE),0) -> 120 | AH16: =G16+I16+K16+M16+O16+Q16+S16+U16+W16+Y16+AA16+AC16+AE16+AG16 -> 870
A17: 3 | B17: 4 | C17: 26 | D17: VARGAS José David* | E17: COLONO BIKE STATION KOLBI | J17: 5 | K17: =IFERROR(VLOOKUP(J17,'Puntos XCC Mayor'!$A$1:$B$15,2,FALSE),"0") -> 12 | L17: 3 | M17: =IFERROR(VLOOKUP(L17,'Puntos XCO'!$A$1:$B$63,2,FALSE),0) -> 120 | N17: 11 | O17: =IFERROR(VLOOKUP(N17,'Puntos XCC Mayor'!$A$1:$B$15,2,FALSE),0) -> 5 | P17: 10 | Q17: =IFERROR(VLOOKUP(P17,'Puntos XCO'!$A$1:$B$63,2,FALSE),0) -> 78 | R17: 5 | S17: =IFERROR(VLOOKUP(R17,'Puntos XCC Mayor'!$A$1:$B$15,2,FALSE),0) -> 12 | T17: 3 | U17: =IFERROR(VLOOKUP(T17,'Puntos XCO'!$A$1:$B$63,2,FALSE),0) -> 120 | V17: 9 | W17: =IFERROR(VLOOKUP(V17,'Puntos XCC Mayor'!$A$1:$B$15,2,FALSE),0) -> 7 | X17: 3 | Y17: =IFERROR(VLOOKUP(X17,'Puntos XCO'!$A$1:$B$63,2,FALSE),0) -> 120 | Z17: 1 | AA17: =IFERROR(VLOOKUP(Z17,'Puntos XCC Mayor'!$A$1:$B$15,2,FALSE),0) -> 25 | AB17: 1 | AC17: =IFERROR(VLOOKUP(AB17,'Puntos XCO'!$A$1:$B$63,2,FALSE),0) -> 200 | AH17: =G17+I17+K17+M17+O17+Q17+S17+U17+W17+Y17+AA17+AC17+AE17+AG17 -> 699
A18: 4 | B18: 3 | C18: 28 | D18: AZOFEIFA Daniel* | E18: BOBBYS CYCLING TEAM | F18: 9 | G18: =IFERROR(VLOOKUP(F18,'Puntos XCC Mayor'!$A$1:$B$15,2,FALSE),0) -> 7 | H18: 4 | I18: =IFERROR(VLOOKUP(H18,'Puntos XCO'!$A$1:$B$63,2,FALSE),0) -> 110 | J18: 3 | K18: =IFERROR(VLOOKUP(J18,'Puntos XCC Mayor'!$A$1:$B$15,2,FALSE),"0") -> 16 | L18: 4 | M18: =IFERROR(VLOOKUP(L18,'Puntos XCO'!$A$1:$B$63,2,FALSE),0) -> 110 | N18: 7 | O18: =IFERROR(VLOOKUP(N18,'Puntos XCC Mayor'!$A$1:$B$15,2,FALSE),0) -> 9 | P18: 6 | Q18: =IFERROR(VLOOKUP(P18,'Puntos XCO'!$A$1:$B$63,2,FALSE),0) -> 95 | R18: 1 | S18: =IFERROR(VLOOKUP(R18,'Puntos XCC Mayor'!$A$1:$B$15,2,FALSE),0) -> 25 | T18: 1 | U18: =IFERROR(VLOOKUP(T18,'Puntos XCO'!$A$1:$B$63,2,FALSE),0) -> 200 | V18: 3 | W18: =IFERROR(VLOOKUP(V18,'Puntos XCC Mayor'!$A$1:$B$15,2,FALSE),0) -> 16 | X18: 8 | Y18: =IFERROR(VLOOKUP(X18,'Puntos XCO'!$A$1:$B$63,2,FALSE),0) -> 85 | AA18: =IFERROR(VLOOKUP(Z18,'Puntos XCC Mayor'!$A$1:$B$15,2,FALSE),0) -> 0 | AC18: =IFERROR(VLOOKUP(AB18,'Puntos XCO'!$A$1:$B$63,2,FALSE),0) -> 0 | AH18: =G18+I18+K18+M18+O18+Q18+S18+U18+W18+Y18+AA18+AC18+AE18+AG18 -> 673
A19: 5 | B19: 7 | C19: 37 | D19: ROJAS Alejandro* | E19: TEAM HC | F19: 10 | G19: =IFERROR(VLOOKUP(F19,'Puntos XCC Mayor'!$A$1:$B$15,2,FALSE),0) -> 6 | H19: 9 | I19: =IFERROR(VLOOKUP(H19,'Puntos XCO'!$A$1:$B$63,2,FALSE),0) -> 80 | J19: 7 | K19: =IFERROR(VLOOKUP(J19,'Puntos XCC Mayor'!$A$1:$B$15,2,FALSE),"0") -> 9 | L19: 8 | M19: =IFERROR(VLOOKUP(L19,'Puntos XCO'!$A$1:$B$63,2,FALSE),0) -> 85 | O19: =IFERROR(VLOOKUP(N19,'Puntos XCC Mayor'!$A$1:$B$15,2,FALSE),0) -> 0 | Q19: =IFERROR(VLOOKUP(P19,'Puntos XCO'!$A$1:$B$63,2,FALSE),0) -> 0 | R19: 6 | S19: =IFERROR(VLOOKUP(R19,'Puntos XCC Mayor'!$A$1:$B$15,2,FALSE),0) -> 10 | T19: 4 | U19: =IFERROR(VLOOKUP(T19,'Puntos XCO'!$A$1:$B$63,2,FALSE),0) -> 110 | V19: 5 | W19: =IFERROR(VLOOKUP(V19,'Puntos XCC Mayor'!$A$1:$B$15,2,FALSE),0) -> 12 | X19: 10 | Y19: =IFERROR(VLOOKUP(X19,'Puntos XCO'!$A$1:$B$63,2,FALSE),0) -> 78 | Z19: 5 | AA19: =IFERROR(VLOOKUP(Z19,'Puntos XCC Mayor'!$A$1:$B$15,2,FALSE),0) -> 12 | AB19: 5 | AC19: =IFERROR(VLOOKUP(AB19,'Puntos XCO'!$A$1:$B$63,2,FALSE),0) -> 100 | AH19: =G19+I19+K19+M19+O19+Q19+S19+U19+W19+Y19+AA19+AC19+AE19+AG19 -> 502
A20: 6 | B20: 8 | C20: 30 | D20: ALVARADO Armando* | E20: CCDR DESAMPARADOS | F20: 6 | G20: =IFERROR(VLOOKUP(F20,'Puntos XCC Mayor'!$A$1:$B$15,2,FALSE),0) -> 10 | H20: 6 | I20: =IFERROR(VLOOKUP(H20,'Puntos XCO'!$A$1:$B$63,2,FALSE),0) -> 95 | J20: 12 | K20: =IFERROR(VLOOKUP(J20,'Puntos XCC Mayor'!$A$1:$B$15,2,FALSE),"0") -> 4 | L20: 6 | M20: =IFERROR(VLOOKUP(L20,'Puntos XCO'!$A$1:$B$63,2,FALSE),0) -> 95 | N20: 9 | O20: =IFERROR(VLOOKUP(N20,'Puntos XCC Mayor'!$A$1:$B$15,2,FALSE),0) -> 7 | Q20: =IFERROR(VLOOKUP(P20,'Puntos XCO'!$A$1:$B$63,2,FALSE),0) -> 0 | R20: 7 | S20: =IFERROR(VLOOKUP(R20,'Puntos XCC Mayor'!$A$1:$B$15,2,FALSE),0) -> 9 | U20: =IFERROR(VLOOKUP(T20,'Puntos XCO'!$A$1:$B$63,2,FALSE),0) -> 0 | V20: 10 | W20: =IFERROR(VLOOKUP(V20,'Puntos XCC Mayor'!$A$1:$B$15,2,FALSE),0) -> 6 | X20: 5 | Y20: =IFERROR(VLOOKUP(X20,'Puntos XCO'!$A$1:$B$63,2,FALSE),0) -> 100 | Z20: 4 | AA20: =IFERROR(VLOOKUP(Z20,'Puntos XCC Mayor'!$A$1:$B$15,2,FALSE),0) -> 14 | AB20: 8 | AC20: =IFERROR(VLOOKUP(AB20,'Puntos XCO'!$A$1:$B$63,2,FALSE),0) -> 85 | AH20: =G20+I20+K20+M20+O20+Q20+S20+U20+W20+Y20+AA20+AC20+AE20+AG20 -> 425
A21: 7 | B21: 5 | C21: 23 | D21: MENDEZ Jared* | E21: BOBBYS CYCLING TEAM | F21: 1 | G21: =IFERROR(VLOOKUP(F21,'Puntos XCC Mayor'!$A$1:$B$15,2,FALSE),0) -> 25 | H21: 3 | I21: =IFERROR(VLOOKUP(H21,'Puntos XCO'!$A$1:$B$63,2,FALSE),0) -> 120 | J21: 1 | K21: =IFERROR(VLOOKUP(J21,'Puntos XCC Mayor'!$A$1:$B$15,2,FALSE),"0") -> 25 | L21: 0 | M21: =IFERROR(VLOOKUP(L21,'Puntos XCO'!$A$1:$B$63,2,FALSE),0) -> 0 | N21: 4 | O21: =IFERROR(VLOOKUP(N21,'Puntos XCC Mayor'!$A$1:$B$15,2,FALSE),0) -> 14 | Q21: =IFERROR(VLOOKUP(P21,'Puntos XCO'!$A$1:$B$63,2,FALSE),0) -> 0 | S21: =IFERROR(VLOOKUP(R21,'Puntos XCC Mayor'!$A$1:$B$15,2,FALSE),0) -> 0 | U21: =IFERROR(VLOOKUP(T21,'Puntos XCO'!$A$1:$B$63,2,FALSE),0) -> 0 | V21: 1 | W21: =IFERROR(VLOOKUP(V21,'Puntos XCC Mayor'!$A$1:$B$15,2,FALSE),0) -> 25 | X21: 1 | Y21: =IFERROR(VLOOKUP(X21,'Puntos XCO'!$A$1:$B$63,2,FALSE),0) -> 200 | AA21: =IFERROR(VLOOKUP(Z21,'Puntos XCC Mayor'!$A$1:$B$15,2,FALSE),0) -> 0 | AC21: =IFERROR(VLOOKUP(AB21,'Puntos XCO'!$A$1:$B$63,2,FALSE),0) -> 0 | AH21: =G21+I21+K21+M21+O21+Q21+S21+U21+W21+Y21+AA21+AC21+AE21+AG21 -> 409
A22: 8 | B22: 6 | C22: 29 | D22: HIDALGO Stefano* | E22: BOBBYS CYCLING TEAM | F22: 4 | G22: =IFERROR(VLOOKUP(F22,'Puntos XCC Mayor'!$A$1:$B$15,2,FALSE),0) -> 14 | H22: 7 | I22: =IFERROR(VLOOKUP(H22,'Puntos XCO'!$A$1:$B$63,2,FALSE),0) -> 90 | J22: 4 | K22: =IFERROR(VLOOKUP(J22,'Puntos XCC Mayor'!$A$1:$B$15,2,FALSE),"0") -> 14 | L22: 5 | M22: =IFERROR(VLOOKUP(L22,'Puntos XCO'!$A$1:$B$63,2,FALSE),0) -> 100 | N22: 12 | O22: =IFERROR(VLOOKUP(N22,'Puntos XCC Mayor'!$A$1:$B$15,2,FALSE),0) -> 4 | P22: 11 | Q22: =IFERROR(VLOOKUP(P22,'Puntos XCO'!$A$1:$B$63,2,FALSE),0) -> 76 | R22: 4 | S22: =IFERROR(VLOOKUP(R22,'Puntos XCC Mayor'!$A$1:$B$15,2,FALSE),0) -> 14 | U22: =IFERROR(VLOOKUP(T22,'Puntos XCO'!$A$1:$B$63,2,FALSE),0) -> 0 | V22: 4 | W22: =IFERROR(VLOOKUP(V22,'Puntos XCC Mayor'!$A$1:$B$15,2,FALSE),0) -> 14 | X22: 9 | Y22: =IFERROR(VLOOKUP(X22,'Puntos XCO'!$A$1:$B$63,2,FALSE),0) -> 80 | AA22: =IFERROR(VLOOKUP(Z22,'Puntos XCC Mayor'!$A$1:$B$15,2,FALSE),0) -> 0 | AC22: =IFERROR(VLOOKUP(AB22,'Puntos XCO'!$A$1:$B$63,2,FALSE),0) -> 0 | AH22: =G22+I22+K22+M22+O22+Q22+S22+U22+W22+Y22+AA22+AC22+AE22+AG22 -> 406
A23: 9 | B23: 13 | C23: 32 | D23: TORRES Kevin* | E23: 1000 FPS- ZONA INFINITO SPORT | F23: 11 | G23: =IFERROR(VLOOKUP(F23,'Puntos XCC Mayor'!$A$1:$B$15,2,FALSE),0) -> 5 | H23: 11 | I23: =IFERROR(VLOOKUP(H23,'Puntos XCO'!$A$1:$B$63,2,FALSE),0) -> 76 | J23: 0 | K23: =IFERROR(VLOOKUP(J23,'Puntos XCC Mayor'!$A$1:$B$15,2,FALSE),"0") -> 0 | L23: 0 | M23: =IFERROR(VLOOKUP(L23,'Puntos XCO'!$A$1:$B$63,2,FALSE),0) -> 0 | N23: 14 | O23: =IFERROR(VLOOKUP(N23,'Puntos XCC Mayor'!$A$1:$B$15,2,FALSE),0) -> 2 | P23: 12 | Q23: =IFERROR(VLOOKUP(P23,'Puntos XCO'!$A$1:$B$63,2,FALSE),0) -> 74 | S23: =IFERROR(VLOOKUP(R23,'Puntos XCC Mayor'!$A$1:$B$15,2,FALSE),0) -> 0 | U23: =IFERROR(VLOOKUP(T23,'Puntos XCO'!$A$1:$B$63,2,FALSE),0) -> 0 | W23: =IFERROR(VLOOKUP(V23,'Puntos XCC Mayor'!$A$1:$B$15,2,FALSE),0) -> 0 | Y23: =IFERROR(VLOOKUP(X23,'Puntos XCO'!$A$1:$B$63,2,FALSE),0) -> 0 | Z23: 8 | AA23: =IFERROR(VLOOKUP(Z23,'Puntos XCC Mayor'!$A$1:$B$15,2,FALSE),0) -> 8 | AB23: 7 | AC23: =IFERROR(VLOOKUP(AB23,'Puntos XCO'!$A$1:$B$63,2,FALSE),0) -> 90 | AH23: =G23+I23+K23+M23+O23+Q23+S23+U23+W23+Y23+AA23+AC23+AE23+AG23 -> 255
A24: 10 | B24: 12 | C24: 31 | D24: MORA Kendall* | E24: CODEA ALAJUELA | F24: 12 | G24: =IFERROR(VLOOKUP(F24,'Puntos XCC Mayor'!$A$1:$B$15,2,FALSE),0) -> 4 | H24: 12 | I24: =IFERROR(VLOOKUP(H24,'Puntos XCO'!$A$1:$B$63,2,FALSE),0) -> 74 | J24: 9 | K24: =IFERROR(VLOOKUP(J24,'Puntos XCC Mayor'!$A$1:$B$15,2,FALSE),"0") -> 7 | L24: 10 | M24: =IFERROR(VLOOKUP(L24,'Puntos XCO'!$A$1:$B$63,2,FALSE),0) -> 78 | O24: =IFERROR(VLOOKUP(N24,'Puntos XCC Mayor'!$A$1:$B$15,2,FALSE),0) -> 0 | Q24: =IFERROR(VLOOKUP(P24,'Puntos XCO'!$A$1:$B$63,2,FALSE),0) -> 0 | S24: =IFERROR(VLOOKUP(R24,'Puntos XCC Mayor'!$A$1:$B$15,2,FALSE),0) -> 0 | U24: =IFERROR(VLOOKUP(T24,'Puntos XCO'!$A$1:$B$63,2,FALSE),0) -> 0 | W24: =IFERROR(VLOOKUP(V24,'Puntos XCC Mayor'!$A$1:$B$15,2,FALSE),0) -> 0 | Y24: =IFERROR(VLOOKUP(X24,'Puntos XCO'!$A$1:$B$63,2,FALSE),0) -> 0 | AA24: =IFERROR(VLOOKUP(Z24,'Puntos XCC Mayor'!$A$1:$B$15,2,FALSE),0) -> 0 | AB24: 10 | AC24: =IFERROR(VLOOKUP(AB24,'Puntos XCO'!$A$1:$B$63,2,FALSE),0) -> 78 | AH24: =G24+I24+K24+M24+O24+Q24+S24+U24+W24+Y24+AA24+AC24+AE24+AG24 -> 241
A25: 11 | B25: 9 | C25: 22 | D25: TAILLEFER Tristan* | E25: PIVOT OTE CONTINENTAL | N25: 2 | O25: =IFERROR(VLOOKUP(N25,'Puntos XCC Mayor'!$A$1:$B$15,2,FALSE),0) -> 20 | P25: 1 | Q25: =IFERROR(VLOOKUP(P25,'Puntos XCO'!$A$1:$B$63,2,FALSE),0) -> 200 | S25: =IFERROR(VLOOKUP(R25,'Puntos XCC Mayor'!$A$1:$B$15,2,FALSE),0) -> 0 | U25: =IFERROR(VLOOKUP(T25,'Puntos XCO'!$A$1:$B$63,2,FALSE),0) -> 0 | W25: =IFERROR(VLOOKUP(V25,'Puntos XCC Mayor'!$A$1:$B$15,2,FALSE),0) -> 0 | Y25: =IFERROR(VLOOKUP(X25,'Puntos XCO'!$A$1:$B$63,2,FALSE),0) -> 0 | AA25: =IFERROR(VLOOKUP(Z25,'Puntos XCC Mayor'!$A$1:$B$15,2,FALSE),0) -> 0 | AC25: =IFERROR(VLOOKUP(AB25,'Puntos XCO'!$A$1:$B$63,2,FALSE),0) -> 0 | AH25: =G25+I25+K25+M25+O25+Q25+S25+U25+W25+Y25+AA25+AC25+AE25+AG25 -> 220
A26: 12 | B26: 10 | C26: 35 | D26: CASTILLO Alejandro* | E26: COLONO BIKE STATION KOLBI | N26: 13 | O26: =IFERROR(VLOOKUP(N26,'Puntos XCC Mayor'!$A$1:$B$15,2,FALSE),0) -> 3 | Q26: =IFERROR(VLOOKUP(P26,'Puntos XCO'!$A$1:$B$63,2,FALSE),0) -> 0 | S26: =IFERROR(VLOOKUP(R26,'Puntos XCC Mayor'!$A$1:$B$15,2,FALSE),0) -> 0 | T26: 5 | U26: =IFERROR(VLOOKUP(T26,'Puntos XCO'!$A$1:$B$63,2,FALSE),0) -> 100 | V26: 6 | W26: =IFERROR(VLOOKUP(V26,'Puntos XCC Mayor'!$A$1:$B$15,2,FALSE),0) -> 10 | X26: 6 | Y26: =IFERROR(VLOOKUP(X26,'Puntos XCO'!$A$1:$B$63,2,FALSE),0) -> 95 | AA26: =IFERROR(VLOOKUP(Z26,'Puntos XCC Mayor'!$A$1:$B$15,2,FALSE),0) -> 0 | AC26: =IFERROR(VLOOKUP(AB26,'Puntos XCO'!$A$1:$B$63,2,FALSE),0) -> 0 | AH26: =G26+I26+K26+M26+O26+Q26+S26+U26+W26+Y26+AA26+AC26+AE26+AG26 -> 208
A27: 13 | B27: 27 | C27: 41 | D27: =VLOOKUP(C27,PLANILLA,2,FALSE) -> FERNADEZ Fabricio Alberto* | E27: =VLOOKUP(C27,PLANILLA,4,FALSE) -> Sin equipo | W27: =IFERROR(VLOOKUP(V27,'Puntos XCC Mayor'!$A$1:$B$15,2,FALSE),0) -> 0 | X27: 11 | Y27: =IFERROR(VLOOKUP(X27,'Puntos XCO'!$A$1:$B$63,2,FALSE),0) -> 76 | Z27: 6 | AA27: =IFERROR(VLOOKUP(Z27,'Puntos XCC Mayor'!$A$1:$B$15,2,FALSE),0) -> 10 | AB27: 4 | AC27: =IFERROR(VLOOKUP(AB27,'Puntos XCO'!$A$1:$B$63,2,FALSE),0) -> 110 | AH27: =G27+I27+K27+M27+O27+Q27+S27+U27+W27+Y27+AA27+AC27+AE27+AG27 -> 196
A28: 14 | B28: 11 | C28: 21 | D28: SAN MARTIN Maximiliano* | E28: ER CICLISMO CHILE. | N28: 3 | O28: =IFERROR(VLOOKUP(N28,'Puntos XCC Mayor'!$A$1:$B$15,2,FALSE),0) -> 16 | P28: 2 | Q28: =IFERROR(VLOOKUP(P28,'Puntos XCO'!$A$1:$B$63,2,FALSE),0) -> 150 | S28: =IFERROR(VLOOKUP(R28,'Puntos XCC Mayor'!$A$1:$B$15,2,FALSE),0) -> 0 | U28: =IFERROR(VLOOKUP(T28,'Puntos XCO'!$A$1:$B$63,2,FALSE),0) -> 0 | W28: =IFERROR(VLOOKUP(V28,'Puntos XCC Mayor'!$A$1:$B$15,2,FALSE),0) -> 0 | Y28: =IFERROR(VLOOKUP(X28,'Puntos XCO'!$A$1:$B$63,2,FALSE),0) -> 0 | AA28: =IFERROR(VLOOKUP(Z28,'Puntos XCC Mayor'!$A$1:$B$15,2,FALSE),0) -> 0 | AC28: =IFERROR(VLOOKUP(AB28,'Puntos XCO'!$A$1:$B$63,2,FALSE),0) -> 0 | AH28: =G28+I28+K28+M28+O28+Q28+S28+U28+W28+Y28+AA28+AC28+AE28+AG28 -> 166
A29: 15 | B29: 14 | D29: MADRIGAL Adriano* | E29: CICLISMO BELÉN | F29: 8 | G29: =IFERROR(VLOOKUP(F29,'Puntos XCC Mayor'!$A$1:$B$15,2,FALSE),0) -> 8 | H29: 5 | I29: =IFERROR(VLOOKUP(H29,'Puntos XCO'!$A$1:$B$63,2,FALSE),0) -> 100 | J29: 0 | K29: =IFERROR(VLOOKUP(J29,'Puntos XCC Mayor'!$A$1:$B$15,2,FALSE),"0") -> 0 | L29: 0 | M29: =IFERROR(VLOOKUP(L29,'Puntos XCO'!$A$1:$B$63,2,FALSE),0) -> 0 | O29: =IFERROR(VLOOKUP(N29,'Puntos XCC Mayor'!$A$1:$B$15,2,FALSE),0) -> 0 | Q29: =IFERROR(VLOOKUP(P29,'Puntos XCO'!$A$1:$B$63,2,FALSE),0) -> 0 | S29: =IFERROR(VLOOKUP(R29,'Puntos XCC Mayor'!$A$1:$B$15,2,FALSE),0) -> 0 | U29: =IFERROR(VLOOKUP(T29,'Puntos XCO'!$A$1:$B$63,2,FALSE),0) -> 0 | W29: =IFERROR(VLOOKUP(V29,'Puntos XCC Mayor'!$A$1:$B$15,2,FALSE),0) -> 0 | Y29: =IFERROR(VLOOKUP(X29,'Puntos XCO'!$A$1:$B$63,2,FALSE),0) -> 0 | AA29: =IFERROR(VLOOKUP(Z29,'Puntos XCC Mayor'!$A$1:$B$15,2,FALSE),0) -> 0 | AC29: =IFERROR(VLOOKUP(AB29,'Puntos XCO'!$A$1:$B$63,2,FALSE),0) -> 0 | AH29: =G29+I29+K29+M29+O29+Q29+S29+U29+W29+Y29+AA29+AC29+AE29+AG29 -> 108
A30: 16 | B30: 15 | D30: AGUILAR Jonathan* | E30: MANZA TÉ LA SELVA SCOTT | F30: 2 | G30: =IFERROR(VLOOKUP(F30,'Puntos XCC Mayor'!$A$1:$B$15,2,FALSE),0) -> 20 | H30: 8 | I30: =IFERROR(VLOOKUP(H30,'Puntos XCO'!$A$1:$B$63,2,FALSE),0) -> 85 | J30: 0 | K30: =IFERROR(VLOOKUP(J30,'Puntos XCC Mayor'!$A$1:$B$15,2,FALSE),"0") -> 0 | L30: 0 | M30: =IFERROR(VLOOKUP(L30,'Puntos XCO'!$A$1:$B$63,2,FALSE),0) -> 0 | O30: =IFERROR(VLOOKUP(N30,'Puntos XCC Mayor'!$A$1:$B$15,2,FALSE),0) -> 0 | Q30: =IFERROR(VLOOKUP(P30,'Puntos XCO'!$A$1:$B$63,2,FALSE),0) -> 0 | S30: =IFERROR(VLOOKUP(R30,'Puntos XCC Mayor'!$A$1:$B$15,2,FALSE),0) -> 0 | U30: =IFERROR(VLOOKUP(T30,'Puntos XCO'!$A$1:$B$63,2,FALSE),0) -> 0 | W30: =IFERROR(VLOOKUP(V30,'Puntos XCC Mayor'!$A$1:$B$15,2,FALSE),0) -> 0 | Y30: =IFERROR(VLOOKUP(X30,'Puntos XCO'!$A$1:$B$63,2,FALSE),0) -> 0 | AA30: =IFERROR(VLOOKUP(Z30,'Puntos XCC Mayor'!$A$1:$B$15,2,FALSE),0) -> 0 | AC30: =IFERROR(VLOOKUP(AB30,'Puntos XCO'!$A$1:$B$63,2,FALSE),0) -> 0 | AH30: =G30+I30+K30+M30+O30+Q30+S30+U30+W30+Y30+AA30+AC30+AE30+AG30 -> 105
A31: 17 | B31: 16 | C31: 24 | D31: DUVAL Mathis* | E31: SIBOIRE QUIROULE | N31: 1 | O31: =IFERROR(VLOOKUP(N31,'Puntos XCC Mayor'!$A$1:$B$15,2,FALSE),0) -> 25 | P31: 9 | Q31: =IFERROR(VLOOKUP(P31,'Puntos XCO'!$A$1:$B$63,2,FALSE),0) -> 80 | S31: =IFERROR(VLOOKUP(R31,'Puntos XCC Mayor'!$A$1:$B$15,2,FALSE),0) -> 0 | U31: =IFERROR(VLOOKUP(T31,'Puntos XCO'!$A$1:$B$63,2,FALSE),0) -> 0 | W31: =IFERROR(VLOOKUP(V31,'Puntos XCC Mayor'!$A$1:$B$15,2,FALSE),0) -> 0 | Y31: =IFERROR(VLOOKUP(X31,'Puntos XCO'!$A$1:$B$63,2,FALSE),0) -> 0 | AA31: =IFERROR(VLOOKUP(Z31,'Puntos XCC Mayor'!$A$1:$B$15,2,FALSE),0) -> 0 | AC31: =IFERROR(VLOOKUP(AB31,'Puntos XCO'!$A$1:$B$63,2,FALSE),0) -> 0 | AH31: =G31+I31+K31+M31+O31+Q31+S31+U31+W31+Y31+AA31+AC31+AE31+AG31 -> 105
A32: 18 | C32: 43 | D32: =VLOOKUP(C32,PLANILLA,2,FALSE) -> SUNSIN Ean* | E32: =VLOOKUP(C32,PLANILLA,4,FALSE) -> ACISA - SARAPIQUÍ | Z32: 7 | AA32: =IFERROR(VLOOKUP(Z32,'Puntos XCC Mayor'!$A$1:$B$15,2,FALSE),0) -> 9 | AB32: 6 | AC32: =IFERROR(VLOOKUP(AB32,'Puntos XCO'!$A$1:$B$63,2,FALSE),0) -> 95 | AH32: =G32+I32+K32+M32+O32+Q32+S32+U32+W32+Y32+AA32+AC32+AE32+AG32 -> 104
A33: 19 | B33: 17 | C33: 33 | D33: BRUNELLE Alix* | E33: SIBOIRE QUIROULE | O33: =IFERROR(VLOOKUP(N33,'Puntos XCC Mayor'!$A$1:$B$15,2,FALSE),0) -> 0 | P33: 5 | Q33: =IFERROR(VLOOKUP(P33,'Puntos XCO'!$A$1:$B$63,2,FALSE),0) -> 100 | S33: =IFERROR(VLOOKUP(R33,'Puntos XCC Mayor'!$A$1:$B$15,2,FALSE),0) -> 0 | U33: =IFERROR(VLOOKUP(T33,'Puntos XCO'!$A$1:$B$63,2,FALSE),0) -> 0 | W33: =IFERROR(VLOOKUP(V33,'Puntos XCC Mayor'!$A$1:$B$15,2,FALSE),0) -> 0 | Y33: =IFERROR(VLOOKUP(X33,'Puntos XCO'!$A$1:$B$63,2,FALSE),0) -> 0 | AA33: =IFERROR(VLOOKUP(Z33,'Puntos XCC Mayor'!$A$1:$B$15,2,FALSE),0) -> 0 | AC33: =IFERROR(VLOOKUP(AB33,'Puntos XCO'!$A$1:$B$63,2,FALSE),0) -> 0 | AH33: =G33+I33+K33+M33+O33+Q33+S33+U33+W33+Y33+AA33+AC33+AE33+AG33 -> 100
A34: 20 | B34: 18 | D34: HIDALGO Isaac* | E34: TEAM COSTAFRUT GIANT AC MARRIOT | J34: 8 | K34: =IFERROR(VLOOKUP(J34,'Puntos XCC Mayor'!$A$1:$B$15,2,FALSE),"0") -> 8 | L34: 7 | M34: =IFERROR(VLOOKUP(L34,'Puntos XCO'!$A$1:$B$63,2,FALSE),0) -> 90 | O34: =IFERROR(VLOOKUP(N34,'Puntos XCC Mayor'!$A$1:$B$15,2,FALSE),0) -> 0 | Q34: =IFERROR(VLOOKUP(P34,'Puntos XCO'!$A$1:$B$63,2,FALSE),0) -> 0 | S34: =IFERROR(VLOOKUP(R34,'Puntos XCC Mayor'!$A$1:$B$15,2,FALSE),0) -> 0 | U34: =IFERROR(VLOOKUP(T34,'Puntos XCO'!$A$1:$B$63,2,FALSE),0) -> 0 | W34: =IFERROR(VLOOKUP(V34,'Puntos XCC Mayor'!$A$1:$B$15,2,FALSE),0) -> 0 | Y34: =IFERROR(VLOOKUP(X34,'Puntos XCO'!$A$1:$B$63,2,FALSE),0) -> 0 | AA34: =IFERROR(VLOOKUP(Z34,'Puntos XCC Mayor'!$A$1:$B$15,2,FALSE),0) -> 0 | AC34: =IFERROR(VLOOKUP(AB34,'Puntos XCO'!$A$1:$B$63,2,FALSE),0) -> 0 | AH34: =G34+I34+K34+M34+O34+Q34+S34+U34+W34+Y34+AA34+AC34+AE34+AG34 -> 98
A35: 21 | B35: 19 | C35: 39 | D35: =VLOOKUP(C35,PLANILLA,2,FALSE) -> ROJAS Juan Diego* | E35: =VLOOKUP(C35,PLANILLA,4,FALSE) -> MEGAMO MANZATÉ LA SELVA | V35: 8 | W35: =IFERROR(VLOOKUP(V35,'Puntos XCC Mayor'!$A$1:$B$15,2,FALSE),0) -> 8 | X35: 7 | Y35: =IFERROR(VLOOKUP(X35,'Puntos XCO'!$A$1:$B$63,2,FALSE),0) -> 90 | AA35: =IFERROR(VLOOKUP(Z35,'Puntos XCC Mayor'!$A$1:$B$15,2,FALSE),0) -> 0 | AC35: =IFERROR(VLOOKUP(AB35,'Puntos XCO'!$A$1:$B$63,2,FALSE),0) -> 0 | AH35: =G35+I35+K35+M35+O35+Q35+S35+U35+W35+Y35+AA35+AC35+AE35+AG35 -> 98
A36: 22 | B36: 20 | C36: 34 | D36: RODRIGUEZ Angel* | E36: 7EIGHT7 PROJECT | N36: 10 | O36: =IFERROR(VLOOKUP(N36,'Puntos XCC Mayor'!$A$1:$B$15,2,FALSE),0) -> 6 | P36: 7 | Q36: =IFERROR(VLOOKUP(P36,'Puntos XCO'!$A$1:$B$63,2,FALSE),0) -> 90 | S36: =IFERROR(VLOOKUP(R36,'Puntos XCC Mayor'!$A$1:$B$15,2,FALSE),0) -> 0 | U36: =IFERROR(VLOOKUP(T36,'Puntos XCO'!$A$1:$B$63,2,FALSE),0) -> 0 | W36: =IFERROR(VLOOKUP(V36,'Puntos XCC Mayor'!$A$1:$B$15,2,FALSE),0) -> 0 | Y36: =IFERROR(VLOOKUP(X36,'Puntos XCO'!$A$1:$B$63,2,FALSE),0) -> 0 | AA36: =IFERROR(VLOOKUP(Z36,'Puntos XCC Mayor'!$A$1:$B$15,2,FALSE),0) -> 0 | AC36: =IFERROR(VLOOKUP(AB36,'Puntos XCO'!$A$1:$B$63,2,FALSE),0) -> 0 | AH36: =G36+I36+K36+M36+O36+Q36+S36+U36+W36+Y36+AA36+AC36+AE36+AG36 -> 96
A37: 23 | B37: 21 | C37: 38 | D37: =VLOOKUP(C37,PLANILLA,2,FALSE) -> ARAYA Roberto* | E37: =VLOOKUP(C37,PLANILLA,4,FALSE) -> CCDR PARAÍSO | S37: =IFERROR(VLOOKUP(R37,'Puntos XCC Mayor'!$A$1:$B$15,2,FALSE),0) -> 0 | T37: 6 | U37: =IFERROR(VLOOKUP(T37,'Puntos XCO'!$A$1:$B$63,2,FALSE),0) -> 95 | W37: =IFERROR(VLOOKUP(V37,'Puntos XCC Mayor'!$A$1:$B$15,2,FALSE),0) -> 0 | Y37: =IFERROR(VLOOKUP(X37,'Puntos XCO'!$A$1:$B$63,2,FALSE),0) -> 0 | AA37: =IFERROR(VLOOKUP(Z37,'Puntos XCC Mayor'!$A$1:$B$15,2,FALSE),0) -> 0 | AC37: =IFERROR(VLOOKUP(AB37,'Puntos XCO'!$A$1:$B$63,2,FALSE),0) -> 0 | AH37: =G37+I37+K37+M37+O37+Q37+S37+U37+W37+Y37+AA37+AC37+AE37+AG37 -> 95
A38: 24 | B38: 22 | C38: 36 | D38: LUNA José Carlos* | E38: MI BICLA | N38: 8 | O38: =IFERROR(VLOOKUP(N38,'Puntos XCC Mayor'!$A$1:$B$15,2,FALSE),0) -> 8 | P38: 8 | Q38: =IFERROR(VLOOKUP(P38,'Puntos XCO'!$A$1:$B$63,2,FALSE),0) -> 85 | S38: =IFERROR(VLOOKUP(R38,'Puntos XCC Mayor'!$A$1:$B$15,2,FALSE),0) -> 0 | U38: =IFERROR(VLOOKUP(T38,'Puntos XCO'!$A$1:$B$63,2,FALSE),0) -> 0 | W38: =IFERROR(VLOOKUP(V38,'Puntos XCC Mayor'!$A$1:$B$15,2,FALSE),0) -> 0 | Y38: =IFERROR(VLOOKUP(X38,'Puntos XCO'!$A$1:$B$63,2,FALSE),0) -> 0 | AA38: =IFERROR(VLOOKUP(Z38,'Puntos XCC Mayor'!$A$1:$B$15,2,FALSE),0) -> 0 | AC38: =IFERROR(VLOOKUP(AB38,'Puntos XCO'!$A$1:$B$63,2,FALSE),0) -> 0 | AH38: =G38+I38+K38+M38+O38+Q38+S38+U38+W38+Y38+AA38+AC38+AE38+AG38 -> 93
A39: 25 | C39: 42 | D39: =VLOOKUP(C39,PLANILLA,2,FALSE) -> ORTEGA Kelvin José* | E39: =VLOOKUP(C39,PLANILLA,4,FALSE) -> CCDR Santa Cruz | Z39: 9 | AA39: =IFERROR(VLOOKUP(Z39,'Puntos XCC Mayor'!$A$1:$B$15,2,FALSE),0) -> 7 | AB39: 9 | AC39: =IFERROR(VLOOKUP(AB39,'Puntos XCO'!$A$1:$B$63,2,FALSE),0) -> 80 | AH39: =G39+I39+K39+M39+O39+Q39+S39+U39+W39+Y39+AA39+AC39+AE39+AG39 -> 87
A40: 26 | B40: 23 | D40: CAMACHO Jeancarlo * | E40: INDEPENDIENTE | J40: 10 | K40: =IFERROR(VLOOKUP(J40,'Puntos XCC Mayor'!$A$1:$B$15,2,FALSE),"0") -> 6 | L40: 9 | M40: =IFERROR(VLOOKUP(L40,'Puntos XCO'!$A$1:$B$63,2,FALSE),0) -> 80 | O40: =IFERROR(VLOOKUP(N40,'Puntos XCC Mayor'!$A$1:$B$15,2,FALSE),0) -> 0 | Q40: =IFERROR(VLOOKUP(P40,'Puntos XCO'!$A$1:$B$63,2,FALSE),0) -> 0 | S40: =IFERROR(VLOOKUP(R40,'Puntos XCC Mayor'!$A$1:$B$15,2,FALSE),0) -> 0 | U40: =IFERROR(VLOOKUP(T40,'Puntos XCO'!$A$1:$B$63,2,FALSE),0) -> 0 | W40: =IFERROR(VLOOKUP(V40,'Puntos XCC Mayor'!$A$1:$B$15,2,FALSE),0) -> 0 | Y40: =IFERROR(VLOOKUP(X40,'Puntos XCO'!$A$1:$B$63,2,FALSE),0) -> 0 | AA40: =IFERROR(VLOOKUP(Z40,'Puntos XCC Mayor'!$A$1:$B$15,2,FALSE),0) -> 0 | AC40: =IFERROR(VLOOKUP(AB40,'Puntos XCO'!$A$1:$B$63,2,FALSE),0) -> 0 | AH40: =G40+I40+K40+M40+O40+Q40+S40+U40+W40+Y40+AA40+AC40+AE40+AG40 -> 86
A41: 27 | B41: 24 | D41: ALFARO Jeison* | E41: INDEPENDIENTE | J41: 11 | K41: =IFERROR(VLOOKUP(J41,'Puntos XCC Mayor'!$A$1:$B$15,2,FALSE),"0") -> 5 | L41: 11 | M41: =IFERROR(VLOOKUP(L41,'Puntos XCO'!$A$1:$B$63,2,FALSE),0) -> 76 | O41: =IFERROR(VLOOKUP(N41,'Puntos XCC Mayor'!$A$1:$B$15,2,FALSE),0) -> 0 | Q41: =IFERROR(VLOOKUP(P41,'Puntos XCO'!$A$1:$B$63,2,FALSE),0) -> 0 | S41: =IFERROR(VLOOKUP(R41,'Puntos XCC Mayor'!$A$1:$B$15,2,FALSE),0) -> 0 | U41: =IFERROR(VLOOKUP(T41,'Puntos XCO'!$A$1:$B$63,2,FALSE),0) -> 0 | W41: =IFERROR(VLOOKUP(V41,'Puntos XCC Mayor'!$A$1:$B$15,2,FALSE),0) -> 0 | Y41: =IFERROR(VLOOKUP(X41,'Puntos XCO'!$A$1:$B$63,2,FALSE),0) -> 0 | AA41: =IFERROR(VLOOKUP(Z41,'Puntos XCC Mayor'!$A$1:$B$15,2,FALSE),0) -> 0 | AC41: =IFERROR(VLOOKUP(AB41,'Puntos XCO'!$A$1:$B$63,2,FALSE),0) -> 0 | AH41: =G41+I41+K41+M41+O41+Q41+S41+U41+W41+Y41+AA41+AC41+AE41+AG41 -> 81
A42: 28 | B42: 25 | C42: 40 | D42: =VLOOKUP(C42,PLANILLA,2,FALSE) -> GUTIERREZ Carlos Daniel | E42: =VLOOKUP(C42,PLANILLA,4,FALSE) -> turrialba | V42: 11 | W42: =IFERROR(VLOOKUP(V42,'Puntos XCC Mayor'!$A$1:$B$15,2,FALSE),0) -> 5 | X42: 12 | Y42: =IFERROR(VLOOKUP(X42,'Puntos XCO'!$A$1:$B$63,2,FALSE),0) -> 74 | AA42: =IFERROR(VLOOKUP(Z42,'Puntos XCC Mayor'!$A$1:$B$15,2,FALSE),0) -> 0 | AC42: =IFERROR(VLOOKUP(AB42,'Puntos XCO'!$A$1:$B$63,2,FALSE),0) -> 0 | AH42: =G42+I42+K42+M42+O42+Q42+S42+U42+W42+Y42+AA42+AC42+AE42+AG42 -> 79
A43: 29 | B43: 26 | D43: MENESES Sebastian* | E43: MANZATE LA SELVA SCOTT | F43: 0 | G43: =IFERROR(VLOOKUP(F43,'Puntos XCC Mayor'!$A$1:$B$15,2,FALSE),0) -> 0 | H43: 10 | I43: =IFERROR(VLOOKUP(H43,'Puntos XCO'!$A$1:$B$63,2,FALSE),0) -> 78 | J43: 0 | K43: =IFERROR(VLOOKUP(J43,'Puntos XCC Mayor'!$A$1:$B$15,2,FALSE),"0") -> 0 | L43: 0 | M43: =IFERROR(VLOOKUP(L43,'Puntos XCO'!$A$1:$B$63,2,FALSE),0) -> 0 | O43: =IFERROR(VLOOKUP(N43,'Puntos XCC Mayor'!$A$1:$B$15,2,FALSE),0) -> 0 | Q43: =IFERROR(VLOOKUP(P43,'Puntos XCO'!$A$1:$B$63,2,FALSE),0) -> 0 | S43: =IFERROR(VLOOKUP(R43,'Puntos XCC Mayor'!$A$1:$B$15,2,FALSE),0) -> 0 | U43: =IFERROR(VLOOKUP(T43,'Puntos XCO'!$A$1:$B$63,2,FALSE),0) -> 0 | W43: =IFERROR(VLOOKUP(V43,'Puntos XCC Mayor'!$A$1:$B$15,2,FALSE),0) -> 0 | Y43: =IFERROR(VLOOKUP(X43,'Puntos XCO'!$A$1:$B$63,2,FALSE),0) -> 0 | AA43: =IFERROR(VLOOKUP(Z43,'Puntos XCC Mayor'!$A$1:$B$15,2,FALSE),0) -> 0 | AC43: =IFERROR(VLOOKUP(AB43,'Puntos XCO'!$A$1:$B$63,2,FALSE),0) -> 0 | AH43: =G43+I43+K43+M43+O43+Q43+S43+U43+W43+Y43+AA43+AC43+AE43+AG43 -> 78
