Workbook
Name PLANILLA: Planilla!$B$2:$F$4186
Name RESXCC_1: ResXCC!$B$2:$J$950
Name RESXCO: ResXCO!$B$2:$J$1000
Name RESXCO_SUB23_1: ResXCO!$B$40:$J$60

Sheet EM
A8: ELITE MASCULINO (19+)
A10: 1 - Finca Grupo Orosi >21 y 22 febrero 2 - Parque La Libertad Desamparados > 28 y 29 marzo 3 - Adventure Park > 16 y 17 mayo 4 - Finca La Hisopa San Pedro de Turrubares > 13 y 14 junio
A11: 5 - > 18 y 19 julio 6 - > 12 y 13 setiembre 7 - > 31 Oct y 01 Nov
A13: POSICION | F13: 1 | J13: 2 | N13: 3 | R13: 4 | V13: 5 | Z13: TOTAL PUNTOS
A14: ACTUAL | B14: ANTERIOR | C14: NO | D14: NOMBRE | E14: EQUIPO | F14: POS XCC | G14: PTOS XCC | H14: POS XCO | I14: PTOS XCO | J14: POS XCC | K14: PTOS XCC | L14: POS XCO | M14: PTOS XCO | N14: POS XCC | O14: PTOS XCC | P14: POS XCO | Q14: PTOS XCO | R14: POS XCC | S14: PTOS XCC | T14: POS XCO | U14: PTOS XCO | V14: POS XCC | W14: PTOS XCC | X14: POS XCO | Y14: PTOS XCO
A15: 1 | B15: 1 | C15: 3 | D15: HERRERA Carlos | E15: PEDREGAL 7C | F15: 2 | G15: 20 | H15: 1 | I15: 200 | J15: 2 | K15: 20 | L15: 3 | M15: 120 | N15: 9 | O15: =IFERROR(VLOOKUP(N15,'Puntos XCC Mayor'!$A$1:$B$15,2,FALSE),0) -> 7 | P15: 5 | Q15: =IFERROR(VLOOKUP(P15,'Puntos XCO'!$A$1:$B$63,2,FALSE),0) -> 100 | R15: 2 | S15: =IFERROR(VLOOKUP(R15,'Puntos XCC Mayor'!$A$1:$B$15,2,FALSE),0) -> 20 | T15: 1 | U15: =IFERROR(VLOOKUP(T15,'Puntos XCO'!$A$1:$B$63,2,FALSE),0) -> 200 | V15: =IFERROR(VLOOKUP(C15,RESXCC_1,9,FALSE),0) -> 2 | W15: =IFERROR(VLOOKUP(V15,'Puntos XCC Mayor'!$A$1:$B$15,2,FALSE),0) -> 20 | X15: =IFERROR(VLOOKUP(C15,RESXCO,9,FALSE),0) -> 2 | Y15: =IFERROR(VLOOKUP(X15,'Puntos XCO'!$A$1:$B$63,2,FALSE),0) -> 150 | Z15: =G15+I15+K15+M15+O15+Q15+S15+U15+W15+Y15 -> 857
A16: 2 | B16: 2 | C16: 27 | D16: RAABE Fabricio* | E16: COLONO BIKE STATION KOLBI | F16: 10 | G16: 6 | H16: 4 | I16: 110 | J16: 12 | K16: 4 | L16: 7 | M16: 90 | N16: 15 | O16: =IFERROR(VLOOKUP(N16,'Puntos XCC Mayor'!$A$1:$B$15,2,FALSE),0) -> 1 | P16: 3 | Q16: =IFERROR(VLOOKUP(P16,'Puntos XCO'!$A$1:$B$63,2,FALSE),0) -> 120 | R16: 6 | S16: =IFERROR(VLOOKUP(R16,'Puntos XCC Mayor'!$A$1:$B$15,2,FALSE),0) -> 10 | T16: 5 | U16: =IFERROR(VLOOKUP(T16,'Puntos XCO'!$A$1:$B$63,2,FALSE),0) -> 100 | V16: =IFERROR(VLOOKUP(C16,RESXCC_1,9,FALSE),0) -> 10 | W16: =IFERROR(VLOOKUP(V16,'Puntos XCC Mayor'!$A$1:$B$15,2,FALSE),0) -> 6 | X16: =IFERROR(VLOOKUP(C16,RESXCO,9,FALSE),0) -> 8 | Y16: =IFERROR(VLOOKUP(X16,'Puntos XCO'!$A$1:$B$63,2,FALSE),0) -> 85 | Z16: =G16+I16+K16+M16+O16+Q16+S16+U16+W16+Y16 -> 532
A17: 3 | B17: 4 | C17: 28 | D17: AZOFEIFA Daniel* | E17: BOBBYS CYCLING TEAM | F17: 13 | G17: 3 | H17: 8 | I17: 85 | J17: 2 | K17: 20 | L17: 11 | M17: 76 | N17: 16 | O17: =IFERROR(VLOOKUP(N17,'Puntos XCC Mayor'!$A$1:$B$15,2,FALSE),0) -> 0 | P17: 6 | Q17: =IFERROR(VLOOKUP(P17,'Puntos XCO'!$A$1:$B$63,2,FALSE),0) -> 95 | R17: 4 | S17: =IFERROR(VLOOKUP(R17,'Puntos XCC Mayor'!$A$1:$B$15,2,FALSE),0) -> 14 | T17: 4 | U17: =IFERROR(VLOOKUP(T17,'Puntos XCO'!$A$1:$B$63,2,FALSE),0) -> 110 | V17: =IFERROR(VLOOKUP(C17,RESXCC_1,9,FALSE),0) -> 6 | W17: =IFERROR(VLOOKUP(V17,'Puntos XCC Mayor'!$A$1:$B$15,2,FALSE),0) -> 10 | X17: =IFERROR(VLOOKUP(C17,RESXCO,9,FALSE),0) -> 12 | Y17: =IFERROR(VLOOKUP(X17,'Puntos XCO'!$A$1:$B$63,2,FALSE),0) -> 74 | Z17: =G17+I17+K17+M17+O17+Q17+S17+U17+W17+Y17 -> 487
A18: 4 | B18: 6 | C18: 12 | D18: RAMIREZ Federico | E18: MEGAMO MANZATÉ LA SELVA | F18: 6 | G18: 10 | H18: 10 | I18: 78 | J18: 1 | K18: 25 | L18: 6 | M18: 95 | O18: =IFERROR(VLOOKUP(N18,'Puntos XCC Mayor'!$A$1:$B$15,2,FALSE),0) -> 0 | P18: 11 | Q18: =IFERROR(VLOOKUP(P18,'Puntos XCO'!$A$1:$B$63,2,FALSE),0) -> 76 | R18: 0 | S18: =IFERROR(VLOOKUP(R18,'Puntos XCC Mayor'!$A$1:$B$15,2,FALSE),0) -> 0 | T18: 7 | U18: =IFERROR(VLOOKUP(T18,'Puntos XCO'!$A$1:$B$63,2,FALSE),0) -> 90 | V18: =IFERROR(VLOOKUP(C18,RESXCC_1,9,FALSE),0) -> 4 | W18: =IFERROR(VLOOKUP(V18,'Puntos XCC Mayor'!$A$1:$B$15,2,FALSE),0) -> 14 | X18: =IFERROR(VLOOKUP(C18,RESXCO,9,FALSE),0) -> 6 | Y18: =IFERROR(VLOOKUP(X18,'Puntos XCO'!$A$1:$B$63,2,FALSE),0) -> 95 | Z18: =G18+I18+K18+M18+O18+Q18+S18+U18+W18+Y18 -> 483
A19: 5 | B19: 7 | C19: 25 | D19: GONZÁLEZ Adriano* | E19: COLONO BIKE STATION KOLBI | F19: 4 | G19: 14 | H19: 3 | I19: 120 | J19: 5 | K19: 12 | L19: 5 | M19: 100 | N19: 14 | O19: =IFERROR(VLOOKUP(N19,'Puntos XCC Mayor'!$A$1:$B$15,2,FALSE),0) -> 2 | P19: 4 | Q19: =IFERROR(VLOOKUP(P19,'Puntos XCO'!$A$1:$B$63,2,FALSE),0) -> 110 | R19: 5 | S19: =IFERROR(VLOOKUP(R19,'Puntos XCC Mayor'!$A$1:$B$15,2,FALSE),0) -> 12 | T19: 0 | U19: =IFERROR(VLOOKUP(T19,'Puntos XCO'!$A$1:$B$63,2,FALSE),0) -> 0 | V19: =IFERROR(VLOOKUP(C19,RESXCC_1,9,FALSE),0) -> 5 | W19: =IFERROR(VLOOKUP(V19,'Puntos XCC Mayor'!$A$1:$B$15,2,FALSE),0) -> 12 | X19: =IFERROR(VLOOKUP(C19,RESXCO,9,FALSE),0) -> 5 | Y19: =IFERROR(VLOOKUP(X19,'Puntos XCO'!$A$1:$B$63,2,FALSE),0) -> 100 | Z19: =G19+I19+K19+M19+O19+Q19+S19+U19+W19+Y19 -> 482
A20: 6 | B20: 3 | C20: 4 | D20: LÓPEZ Luis Enrique | E20: MEGAMO MANZATÉ LA SELVA | J20: 1 | K20: 25 | L20: 1 | M20: 200 | N20: 4 | O20: =IFERROR(VLOOKUP(N20,'Puntos XCC Mayor'!$A$1:$B$15,2,FALSE),0) -> 14 | Q20: =IFERROR(VLOOKUP(P20,'Puntos XCO'!$A$1:$B$63,2,FALSE),0) -> 0 | R20: 1 | S20: =IFERROR(VLOOKUP(R20,'Puntos XCC Mayor'!$A$1:$B$15,2,FALSE),0) -> 25 | T20: 2 | U20: =IFERROR(VLOOKUP(T20,'Puntos XCO'!$A$1:$B$63,2,FALSE),0) -> 150 | V20: =IFERROR(VLOOKUP(C20,RESXCC_1,9,FALSE),0) -> 0 | W20: =IFERROR(VLOOKUP(V20,'Puntos XCC Mayor'!$A$1:$B$15,2,FALSE),0) -> 0 | X20: =IFERROR(VLOOKUP(C20,RESXCO,9,FALSE),0) -> 0 | Y20: =IFERROR(VLOOKUP(X20,'Puntos XCO'!$A$1:$B$63,2,FALSE),0) -> 0 | Z20: =G20+I20+K20+M20+O20+Q20+S20+U20+W20+Y20 -> 414
A21: 7 | B21: 5 | C21: 9 | D21: GONZALEZ Raymond | E21: CICLO VÍCTOR VARGAS | F21: 5 | G21: 12 | H21: 2 | I21: 150 | J21: 4 | K21: 14 | L21: 4 | M21: 110 | N21: 6 | O21: =IFERROR(VLOOKUP(N21,'Puntos XCC Mayor'!$A$1:$B$15,2,FALSE),0) -> 10 | P21: 6 | Q21: =IFERROR(VLOOKUP(P21,'Puntos XCO'!$A$1:$B$63,2,FALSE),0) -> 95 | R21: 0 | S21: =IFERROR(VLOOKUP(R21,'Puntos XCC Mayor'!$A$1:$B$15,2,FALSE),0) -> 0 | T21: 0 | U21: =IFERROR(VLOOKUP(T21,'Puntos XCO'!$A$1:$B$63,2,FALSE),0) -> 0 | V21: =IFERROR(VLOOKUP(C21,RESXCC_1,9,FALSE),0) -> 0 | W21: =IFERROR(VLOOKUP(V21,'Puntos XCC Mayor'!$A$1:$B$15,2,FALSE),0) -> 0 | X21: =IFERROR(VLOOKUP(C21,RESXCO,9,FALSE),0) -> 0 | Y21: =IFERROR(VLOOKUP(X21,'Puntos XCO'!$A$1:$B$63,2,FALSE),0) -> 0 | Z21: =G21+I21+K21+M21+O21+Q21+S21+U21+W21+Y21 -> 391
A22: 8 | B22: 20 | C22: 13 | D22: SOLÍS Keiron | E22: PEDREGAL - 7C | N22: 5 | O22: =IFERROR(VLOOKUP(N22,'Puntos XCC Mayor'!$A$1:$B$15,2,FALSE),0) -> 12 | Q22: =IFERROR(VLOOKUP(P22,'Puntos XCO'!$A$1:$B$63,2,FALSE),0) -> 0 | R22: 3 | S22: =IFERROR(VLOOKUP(R22,'Puntos XCC Mayor'!$A$1:$B$15,2,FALSE),0) -> 16 | T22: 3 | U22: =IFERROR(VLOOKUP(T22,'Puntos XCO'!$A$1:$B$63,2,FALSE),0) -> 120 | V22: =IFERROR(VLOOKUP(C22,RESXCC_1,9,FALSE),0) -> 1 | W22: =IFERROR(VLOOKUP(V22,'Puntos XCC Mayor'!$A$1:$B$15,2,FALSE),0) -> 25 | X22: =IFERROR(VLOOKUP(C22,RESXCO,9,FALSE),0) -> 1 | Y22: =IFERROR(VLOOKUP(X22,'Puntos XCO'!$A$1:$B$63,2,FALSE),0) -> 200 | Z22: =G22+I22+K22+M22+O22+Q22+S22+U22+W22+Y22 -> 373
A23: 9 | B23: 8 | C23: 10 | D23: VARGAS Steven Andres | E23: SCOTT SHIMANO CYCLING TEAM | F23: 14 | G23: 2 | H23: 6 | I23: 95 | J23: 0 | K23: 0 | L23: 10 | M23: 78 | N23: 25 | O23: =IFERROR(VLOOKUP(N23,'Puntos XCC Mayor'!$A$1:$B$15,2,FALSE),0) -> 0 | P23: 10 | Q23: =IFERROR(VLOOKUP(P23,'Puntos XCO'!$A$1:$B$63,2,FALSE),0) -> 78 | R23: 7 | S23: =IFERROR(VLOOKUP(R23,'Puntos XCC Mayor'!$A$1:$B$15,2,FALSE),0) -> 9 | T23: 6 | U23: =IFERROR(VLOOKUP(T23,'Puntos XCO'!$A$1:$B$63,2,FALSE),0) -> 95 | V23: =IFERROR(VLOOKUP(C23,RESXCC_1,9,FALSE),0) -> 0 | W23: =IFERROR(VLOOKUP(V23,'Puntos XCC Mayor'!$A$1:$B$15,2,FALSE),0) -> 0 | X23: =IFERROR(VLOOKUP(C23,RESXCO,9,FALSE),0) -> 0 | Y23: =IFERROR(VLOOKUP(X23,'Puntos XCO'!$A$1:$B$63,2,FALSE),0) -> 0 | Z23: =G23+I23+K23+M23+O23+Q23+S23+U23+W23+Y23 -> 357
A24: 10 | B24: 9 | C24: 26 | D24: VARGAS José David* | E24: COLONO BIKE STATION KOLBI | J24: 11 | K24: 5 | L24: 9 | M24: 80 | N24: 21 | O24: =IFERROR(VLOOKUP(N24,'Puntos XCC Mayor'!$A$1:$B$15,2,FALSE),0) -> 0 | P24: 10 | Q24: =IFERROR(VLOOKUP(P24,'Puntos XCO'!$A$1:$B$63,2,FALSE),0) -> 78 | R24: 9 | S24: =IFERROR(VLOOKUP(R24,'Puntos XCC Mayor'!$A$1:$B$15,2,FALSE),0) -> 7 | T24: 8 | U24: =IFERROR(VLOOKUP(T24,'Puntos XCO'!$A$1:$B$63,2,FALSE),0) -> 85 | V24: =IFERROR(VLOOKUP(C24,RESXCC_1,9,FALSE),0) -> 12 | W24: =IFERROR(VLOOKUP(V24,'Puntos XCC Mayor'!$A$1:$B$15,2,FALSE),0) -> 4 | X24: =IFERROR(VLOOKUP(C24,RESXCO,9,FALSE),0) -> 7 | Y24: =IFERROR(VLOOKUP(X24,'Puntos XCO'!$A$1:$B$63,2,FALSE),0) -> 90 | Z24: =G24+I24+K24+M24+O24+Q24+S24+U24+W24+Y24 -> 349
A25: 11 | B25: 10 | C25: 29 | D25: HIDALGO Stefano* | E25: BOBBYS CYCLING TEAM | F25: 7 | G25: 9 | H25: 12 | I25: 74 | J25: 10 | K25: 6 | L25: 12 | M25: 74 | N25: 23 | O25: =IFERROR(VLOOKUP(N25,'Puntos XCC Mayor'!$A$1:$B$15,2,FALSE),0) -> 0 | P25: 11 | Q25: =IFERROR(VLOOKUP(P25,'Puntos XCO'!$A$1:$B$63,2,FALSE),0) -> 76 | R25: 8 | S25: =IFERROR(VLOOKUP(R25,'Puntos XCC Mayor'!$A$1:$B$15,2,FALSE),0) -> 8 | T25: 0 | U25: =IFERROR(VLOOKUP(T25,'Puntos XCO'!$A$1:$B$63,2,FALSE),0) -> 0 | V25: =IFERROR(VLOOKUP(C25,RESXCC_1,9,FALSE),0) -> 7 | W25: =IFERROR(VLOOKUP(V25,'Puntos XCC Mayor'!$A$1:$B$15,2,FALSE),0) -> 9 | X25: =IFERROR(VLOOKUP(C25,RESXCO,9,FALSE),0) -> 13 | Y25: =IFERROR(VLOOKUP(X25,'Puntos XCO'!$A$1:$B$63,2,FALSE),0) -> 72 | Z25: =G25+I25+K25+M25+O25+Q25+S25+U25+W25+Y25 -> 328
A26: 12 | B26: 12 | C26: 37 | D26: ROJAS Alejandro* | E26: TEAM HC | F26: 15 | G26: 1 | H26: 14 | I26: 70 | J26: 13 | K26: 3 | L26: 17 | M26: 64 | O26: =IFERROR(VLOOKUP(N26,'Puntos XCC Mayor'!$A$1:$B$15,2,FALSE),0) -> 0 | Q26: =IFERROR(VLOOKUP(P26,'Puntos XCO'!$A$1:$B$63,2,FALSE),0) -> 0 | R26: 10 | S26: =IFERROR(VLOOKUP(R26,'Puntos XCC Mayor'!$A$1:$B$15,2,FALSE),0) -> 6 | T26: 9 | U26: =IFERROR(VLOOKUP(T26,'Puntos XCO'!$A$1:$B$63,2,FALSE),0) -> 80 | V26: =IFERROR(VLOOKUP(C26,RESXCC_1,9,FALSE),0) -> 8 | W26: =IFERROR(VLOOKUP(V26,'Puntos XCC Mayor'!$A$1:$B$15,2,FALSE),0) -> 8 | X26: =IFERROR(VLOOKUP(C26,RESXCO,9,FALSE),0) -> 14 | Y26: =IFERROR(VLOOKUP(X26,'Puntos XCO'!$A$1:$B$63,2,FALSE),0) -> 70 | Z26: =G26+I26+K26+M26+O26+Q26+S26+U26+W26+Y26 -> 302
A27: 13 | B27: 21 | C27: 23 | D27: MENDEZ Jared* | E27: BOBBYS CYCLING TEAM | F27: 1 | G27: 25 | H27: 5 | I27: 100 | J27: 3 | K27: 16 | L27: 0 | M27: 0 | N27: 11 | O27: =IFERROR(VLOOKUP(N27,'Puntos XCC Mayor'!$A$1:$B$15,2,FALSE),0) -> 5 | Q27: =IFERROR(VLOOKUP(P27,'Puntos XCO'!$A$1:$B$63,2,FALSE),0) -> 0 | R27: 0 | S27: =IFERROR(VLOOKUP(R27,'Puntos XCC Mayor'!$A$1:$B$15,2,FALSE),0) -> 0 | T27: 0 | U27: =IFERROR(VLOOKUP(T27,'Puntos XCO'!$A$1:$B$63,2,FALSE),0) -> 0 | V27: =IFERROR(VLOOKUP(C27,RESXCC_1,9,FALSE),0) -> 3 | W27: =IFERROR(VLOOKUP(V27,'Puntos XCC Mayor'!$A$1:$B$15,2,FALSE),0) -> 16 | X27: =IFERROR(VLOOKUP(C27,RESXCO,9,FALSE),0) -> 4 | Y27: =IFERROR(VLOOKUP(X27,'Puntos XCO'!$A$1:$B$63,2,FALSE),0) -> 110 | Z27: =G27+I27+K27+M27+O27+Q27+S27+U27+W27+Y27 -> 272
A28: 14 | B28: 16 | C28: 30 | D28: ALVARADO Armando* | E28: CCDR DESAMPARADOS | F28: 9 | G28: 7 | H28: 11 | I28: 76 | J28: 0 | K28: 0 | L28: 13 | M28: 72 | N28: 18 | O28: =IFERROR(VLOOKUP(N28,'Puntos XCC Mayor'!$A$1:$B$15,2,FALSE),0) -> 0 | Q28: =IFERROR(VLOOKUP(P28,'Puntos XCO'!$A$1:$B$63,2,FALSE),0) -> 0 | R28: 11 | S28: =IFERROR(VLOOKUP(R28,'Puntos XCC Mayor'!$A$1:$B$15,2,FALSE),0) -> 5 | T28: 0 | U28: =IFERROR(VLOOKUP(T28,'Puntos XCO'!$A$1:$B$63,2,FALSE),0) -> 0 | V28: =IFERROR(VLOOKUP(C28,RESXCC_1,9,FALSE),0) -> 13 | W28: =IFERROR(VLOOKUP(V28,'Puntos XCC Mayor'!$A$1:$B$15,2,FALSE),0) -> 3 | X28: =IFERROR(VLOOKUP(C28,RESXCO,9,FALSE),0) -> 9 | Y28: =IFERROR(VLOOKUP(X28,'Puntos XCO'!$A$1:$B$63,2,FALSE),0) -> 80 | Z28: =G28+I28+K28+M28+O28+Q28+S28+U28+W28+Y28 -> 243
A29: 15 | B29: 11 | C29: 1 | D29: MARQUES José Gabriel | E29: COD RACING | N29: 1 | O29: =IFERROR(VLOOKUP(N29,'Puntos XCC Mayor'!$A$1:$B$15,2,FALSE),0) -> 25 | P29: 1 | Q29: =IFERROR(VLOOKUP(P29,'Puntos XCO'!$A$1:$B$63,2,FALSE),0) -> 200 | R29: 0 | S29: =IFERROR(VLOOKUP(R29,'Puntos XCC Mayor'!$A$1:$B$15,2,FALSE),0) -> 0 | T29: 0 | U29: =IFERROR(VLOOKUP(T29,'Puntos XCO'!$A$1:$B$63,2,FALSE),0) -> 0 | V29: =IFERROR(VLOOKUP(C29,RESXCC_1,9,FALSE),0) -> 0 | W29: =IFERROR(VLOOKUP(V29,'Puntos XCC Mayor'!$A$1:$B$15,2,FALSE),0) -> 0 | X29: =IFERROR(VLOOKUP(C29,RESXCO,9,FALSE),0) -> 0 | Y29: =IFERROR(VLOOKUP(X29,'Puntos XCO'!$A$1:$B$63,2,FALSE),0) -> 0 | Z29: =G29+I29+K29+M29+O29+Q29+S29+U29+W29+Y29 -> 225
A30: 16 | B30: 27 | C30: 7 | D30: MONTOYA Paolo | E30: COLONO BIKE STATION KOLBI | O30: =IFERROR(VLOOKUP(N30,'Puntos XCC Mayor'!$A$1:$B$15,2,FALSE),0) -> 0 | P30: 7 | Q30: =IFERROR(VLOOKUP(P30,'Puntos XCO'!$A$1:$B$63,2,FALSE),0) -> 90 | R30: 0 | S30: =IFERROR(VLOOKUP(R30,'Puntos XCC Mayor'!$A$1:$B$15,2,FALSE),0) -> 0 | T30: 0 | U30: =IFERROR(VLOOKUP(T30,'Puntos XCO'!$A$1:$B$63,2,FALSE),0) -> 0 | V30: =IFERROR(VLOOKUP(C30,RESXCC_1,9,FALSE),0) -> 0 | W30: =IFERROR(VLOOKUP(V30,'Puntos XCC Mayor'!$A$1:$B$15,2,FALSE),0) -> 0 | X30: =IFERROR(VLOOKUP(C30,RESXCO,9,FALSE),0) -> 3 | Y30: =IFERROR(VLOOKUP(X30,'Puntos XCO'!$A$1:$B$63,2,FALSE),0) -> 120 | Z30: =G30+I30+K30+M30+O30+Q30+S30+U30+W30+Y30 -> 210
A31: 17 | B31: 13 | C31: 22 | D31: TAILLEFER Tristan* | E31: PIVOT OTE CONTINENTAL | N31: 8 | O31: =IFERROR(VLOOKUP(N31,'Puntos XCC Mayor'!$A$1:$B$15,2,FALSE),0) -> 8 | P31: 1 | Q31: =IFERROR(VLOOKUP(P31,'Puntos XCO'!$A$1:$B$63,2,FALSE),0) -> 200 | R31: 0 | S31: =IFERROR(VLOOKUP(R31,'Puntos XCC Mayor'!$A$1:$B$15,2,FALSE),0) -> 0 | T31: 0 | U31: =IFERROR(VLOOKUP(T31,'Puntos XCO'!$A$1:$B$63,2,FALSE),0) -> 0 | V31: =IFERROR(VLOOKUP(C31,RESXCC_1,9,FALSE),0) -> 0 | W31: =IFERROR(VLOOKUP(V31,'Puntos XCC Mayor'!$A$1:$B$15,2,FALSE),0) -> 0 | X31: =IFERROR(VLOOKUP(C31,RESXCO,9,FALSE),0) -> 0 | Y31: =IFERROR(VLOOKUP(X31,'Puntos XCO'!$A$1:$B$63,2,FALSE),0) -> 0 | Z31: =G31+I31+K31+M31+O31+Q31+S31+U31+W31+Y31 -> 208
A32: 18 | B32: 14 | D32: ASTUA Kyvan | E32: INDEPENDIENTE | F32: 12 | G32: 4 | H32: 7 | I32: 90 | J32: 3 | K32: 16 | L32: 15 | M32: 68 | O32: =IFERROR(VLOOKUP(N32,'Puntos XCC Mayor'!$A$1:$B$15,2,FALSE),0) -> 0 | Q32: =IFERROR(VLOOKUP(P32,'Puntos XCO'!$A$1:$B$63,2,FALSE),0) -> 0 | R32: 0 | S32: =IFERROR(VLOOKUP(R32,'Puntos XCC Mayor'!$A$1:$B$15,2,FALSE),0) -> 0 | T32: 0 | U32: =IFERROR(VLOOKUP(T32,'Puntos XCO'!$A$1:$B$63,2,FALSE),0) -> 0 | V32: =IFERROR(VLOOKUP(C32,RESXCC_1,9,FALSE),0) -> 0 | W32: =IFERROR(VLOOKUP(V32,'Puntos XCC Mayor'!$A$1:$B$15,2,FALSE),0) -> 0 | X32: =IFERROR(VLOOKUP(C32,RESXCO,9,FALSE),0) -> 0 | Y32: =IFERROR(VLOOKUP(X32,'Puntos XCO'!$A$1:$B$63,2,FALSE),0) -> 0 | Z32: =G32+I32+K32+M32+O32+Q32+S32+U32+W32+Y32 -> 178
A33: 19 | B33: 15 | C33: 8 | D33: FONSECA Andrey | E33: TEAM INNOVABIKES SKOLER UH | J33: 0 | K33: 0 | L33: 8 | M33: 85 | N33: 22 | O33: =IFERROR(VLOOKUP(N33,'Puntos XCC Mayor'!$A$1:$B$15,2,FALSE),0) -> 0 | P33: 8 | Q33: =IFERROR(VLOOKUP(P33,'Puntos XCO'!$A$1:$B$63,2,FALSE),0) -> 85 | R33: 0 | S33: =IFERROR(VLOOKUP(R33,'Puntos XCC Mayor'!$A$1:$B$15,2,FALSE),0) -> 0 | T33: 0 | U33: =IFERROR(VLOOKUP(T33,'Puntos XCO'!$A$1:$B$63,2,FALSE),0) -> 0 | V33: =IFERROR(VLOOKUP(C33,RESXCC_1,9,FALSE),0) -> 0 | W33: =IFERROR(VLOOKUP(V33,'Puntos XCC Mayor'!$A$1:$B$15,2,FALSE),0) -> 0 | X33: =IFERROR(VLOOKUP(C33,RESXCO,9,FALSE),0) -> 0 | Y33: =IFERROR(VLOOKUP(X33,'Puntos XCO'!$A$1:$B$63,2,FALSE),0) -> 0 | Z33: =G33+I33+K33+M33+O33+Q33+S33+U33+W33+Y33 -> 170
A34: 20 | B34: 34 | C34: 35 | D34: CASTILLO Alejandro* | E34: COLONO BIKE STATION KOLBI | N34: 24 | O34: =IFERROR(VLOOKUP(N34,'Puntos XCC Mayor'!$A$1:$B$15,2,FALSE),0) -> 0 | Q34: =IFERROR(VLOOKUP(P34,'Puntos XCO'!$A$1:$B$63,2,FALSE),0) -> 0 | R34: 0 | S34: =IFERROR(VLOOKUP(R34,'Puntos XCC Mayor'!$A$1:$B$15,2,FALSE),0) -> 0 | T34: 10 | U34: =IFERROR(VLOOKUP(T34,'Puntos XCO'!$A$1:$B$63,2,FALSE),0) -> 78 | V34: =IFERROR(VLOOKUP(C34,RESXCC_1,9,FALSE),0) -> 9 | W34: =IFERROR(VLOOKUP(V34,'Puntos XCC Mayor'!$A$1:$B$15,2,FALSE),0) -> 7 | X34: =IFERROR(VLOOKUP(C34,RESXCO,9,FALSE),0) -> 10 | Y34: =IFERROR(VLOOKUP(X34,'Puntos XCO'!$A$1:$B$63,2,FALSE),0) -> 78 | Z34: =G34+I34+K34+M34+O34+Q34+S34+U34+W34+Y34 -> 163
A35: 21 | B35: 17 | C35: 21 | D35: SAN MARTIN Maximiliano* | E35: ER CICLISMO CHILE. | N35: 10 | O35: =IFERROR(VLOOKUP(N35,'Puntos XCC Mayor'!$A$1:$B$15,2,FALSE),0) -> 6 | P35: 2 | Q35: =IFERROR(VLOOKUP(P35,'Puntos XCO'!$A$1:$B$63,2,FALSE),0) -> 150 | R35: 0 | S35: =IFERROR(VLOOKUP(R35,'Puntos XCC Mayor'!$A$1:$B$15,2,FALSE),0) -> 0 | T35: 0 | U35: =IFERROR(VLOOKUP(T35,'Puntos XCO'!$A$1:$B$63,2,FALSE),0) -> 0 | V35: =IFERROR(VLOOKUP(C35,RESXCC_1,9,FALSE),0) -> 0 | W35: =IFERROR(VLOOKUP(V35,'Puntos XCC Mayor'!$A$1:$B$15,2,FALSE),0) -> 0 | X35: =IFERROR(VLOOKUP(C35,RESXCO,9,FALSE),0) -> 0 | Y35: =IFERROR(VLOOKUP(X35,'Puntos XCO'!$A$1:$B$63,2,FALSE),0) -> 0 | Z35: =G35+I35+K35+M35+O35+Q35+S35+U35+W35+Y35 -> 156
A36: 22 | B36: 18 | C36: 2 | D36: BOTERO Jhonnatan | E36: GW ERCO SPORTFITNESS | O36: =IFERROR(VLOOKUP(N36,'Puntos XCC Mayor'!$A$1:$B$15,2,FALSE),0) -> 0 | P36: 2 | Q36: =IFERROR(VLOOKUP(P36,'Puntos XCO'!$A$1:$B$63,2,FALSE),0) -> 150 | R36: 0 | S36: =IFERROR(VLOOKUP(R36,'Puntos XCC Mayor'!$A$1:$B$15,2,FALSE),0) -> 0 | T36: 0 | U36: =IFERROR(VLOOKUP(T36,'Puntos XCO'!$A$1:$B$63,2,FALSE),0) -> 0 | V36: =IFERROR(VLOOKUP(C36,RESXCC_1,9,FALSE),0) -> 0 | W36: =IFERROR(VLOOKUP(V36,'Puntos XCC Mayor'!$A$1:$B$15,2,FALSE),0) -> 0 | X36: =IFERROR(VLOOKUP(C36,RESXCO,9,FALSE),0) -> 0 | Y36: =IFERROR(VLOOKUP(X36,'Puntos XCO'!$A$1:$B$63,2,FALSE),0) -> 0 | Z36: =G36+I36+K36+M36+O36+Q36+S36+U36+W36+Y36 -> 150
A37: 23 | B37: 19 | C37: 6 | D37: RAMÍREZ Joseph | E37: COLONO BIKE STATION KOLBI | J37: 0 | K37: 0 | L37: 2 | M37: 150 | O37: =IFERROR(VLOOKUP(N37,'Puntos XCC Mayor'!$A$1:$B$15,2,FALSE),0) -> 0 | Q37: =IFERROR(VLOOKUP(P37,'Puntos XCO'!$A$1:$B$63,2,FALSE),0) -> 0 | R37: 0 | S37: =IFERROR(VLOOKUP(R37,'Puntos XCC Mayor'!$A$1:$B$15,2,FALSE),0) -> 0 | T37: 0 | U37: =IFERROR(VLOOKUP(T37,'Puntos XCO'!$A$1:$B$63,2,FALSE),0) -> 0 | V37: =IFERROR(VLOOKUP(C37,RESXCC_1,9,FALSE),0) -> 0 | W37: =IFERROR(VLOOKUP(V37,'Puntos XCC Mayor'!$A$1:$B$15,2,FALSE),0) -> 0 | X37: =IFERROR(VLOOKUP(C37,RESXCO,9,FALSE),0) -> 0 | Y37: =IFERROR(VLOOKUP(X37,'Puntos XCO'!$A$1:$B$63,2,FALSE),0) -> 0 | Z37: =G37+I37+K37+M37+O37+Q37+S37+U37+W37+Y37 -> 150
A38: 24 | B38: 22 | C38: 32 | D38: TORRES Kevin* | E38: 1000 FPS- ZONA INFINITO SPORT | F38: 16 | G38: 0 | H38: 16 | I38: 66 | J38: 0 | K38: 0 | L38: 0 | M38: 0 | N38: 27 | O38: =IFERROR(VLOOKUP(N38,'Puntos XCC Mayor'!$A$1:$B$15,2,FALSE),0) -> 0 | P38: 12 | Q38: =IFERROR(VLOOKUP(P38,'Puntos XCO'!$A$1:$B$63,2,FALSE),0) -> 74 | R38: 0 | S38: =IFERROR(VLOOKUP(R38,'Puntos XCC Mayor'!$A$1:$B$15,2,FALSE),0) -> 0 | T38: 0 | U38: =IFERROR(VLOOKUP(T38,'Puntos XCO'!$A$1:$B$63,2,FALSE),0) -> 0 | V38: =IFERROR(VLOOKUP(C38,RESXCC_1,9,FALSE),0) -> 0 | W38: =IFERROR(VLOOKUP(V38,'Puntos XCC Mayor'!$A$1:$B$15,2,FALSE),0) -> 0 | X38: =IFERROR(VLOOKUP(C38,RESXCO,9,FALSE),0) -> 0 | Y38: =IFERROR(VLOOKUP(X38,'Puntos XCO'!$A$1:$B$63,2,FALSE),0) -> 0 | Z38: =G38+I38+K38+M38+O38+Q38+S38+U38+W38+Y38 -> 140
A39: 25 | B39: 23 | C39: 5 | D39: BEDOYA Jeronimo | E39: GW ERCO SPORTFITNESS | N39: 3 | O39: =IFERROR(VLOOKUP(N39,'Puntos XCC Mayor'!$A$1:$B$15,2,FALSE),0) -> 16 | P39: 3 | Q39: =IFERROR(VLOOKUP(P39,'Puntos XCO'!$A$1:$B$63,2,FALSE),0) -> 120 | R39: 0 | S39: =IFERROR(VLOOKUP(R39,'Puntos XCC Mayor'!$A$1:$B$15,2,FALSE),0) -> 0 | T39: 0 | U39: =IFERROR(VLOOKUP(T39,'Puntos XCO'!$A$1:$B$63,2,FALSE),0) -> 0 | V39: =IFERROR(VLOOKUP(C39,RESXCC_1,9,FALSE),0) -> 0 | W39: =IFERROR(VLOOKUP(V39,'Puntos XCC Mayor'!$A$1:$B$15,2,FALSE),0) -> 0 | X39: =IFERROR(VLOOKUP(C39,RESXCO,9,FALSE),0) -> 0 | Y39: =IFERROR(VLOOKUP(X39,'Puntos XCO'!$A$1:$B$63,2,FALSE),0) -> 0 | Z39: =G39+I39+K39+M39+O39+Q39+S39+U39+W39+Y39 -> 136
A40: 26 | B40: 24 | C40: 14 | D40: AGUILAR Ivan | E40: REGULUS 333 | N40: 2 | O40: =IFERROR(VLOOKUP(N40,'Puntos XCC Mayor'!$A$1:$B$15,2,FALSE),0) -> 20 | P40: 4 | Q40: =IFERROR(VLOOKUP(P40,'Puntos XCO'!$A$1:$B$63,2,FALSE),0) -> 110 | R40: 0 | S40: =IFERROR(VLOOKUP(R40,'Puntos XCC Mayor'!$A$1:$B$15,2,FALSE),0) -> 0 | T40: 0 | U40: =IFERROR(VLOOKUP(T40,'Puntos XCO'!$A$1:$B$63,2,FALSE),0) -> 0 | V40: =IFERROR(VLOOKUP(C40,RESXCC_1,9,FALSE),0) -> 0 | W40: =IFERROR(VLOOKUP(V40,'Puntos XCC Mayor'!$A$1:$B$15,2,FALSE),0) -> 0 | X40: =IFERROR(VLOOKUP(C40,RESXCO,9,FALSE),0) -> 0 | Y40: =IFERROR(VLOOKUP(X40,'Puntos XCO'!$A$1:$B$63,2,FALSE),0) -> 0 | Z40: =G40+I40+K40+M40+O40+Q40+S40+U40+W40+Y40 -> 130
A41: 27 | B41: 25 | C41: 31 | D41: MORA Kendall* | E41: CODEA ALAJUELA | F41: 17 | G41: 0 | H41: 17 | I41: 64 | J41: 16 | K41: 0 | L41: 19 | M41: 60 | N41: 26 | O41: =IFERROR(VLOOKUP(N41,'Puntos XCC Mayor'!$A$1:$B$15,2,FALSE),0) -> 0 | Q41: =IFERROR(VLOOKUP(P41,'Puntos XCO'!$A$1:$B$63,2,FALSE),0) -> 0 | R41: 0 | S41: =IFERROR(VLOOKUP(R41,'Puntos XCC Mayor'!$A$1:$B$15,2,FALSE),0) -> 0 | T41: 0 | U41: =IFERROR(VLOOKUP(T41,'Puntos XCO'!$A$1:$B$63,2,FALSE),0) -> 0 | V41: =IFERROR(VLOOKUP(C41,RESXCC_1,9,FALSE),0) -> 0 | W41: =IFERROR(VLOOKUP(V41,'Puntos XCC Mayor'!$A$1:$B$15,2,FALSE),0) -> 0 | X41: =IFERROR(VLOOKUP(C41,RESXCO,9,FALSE),0) -> 0 | Y41: =IFERROR(VLOOKUP(X41,'Puntos XCO'!$A$1:$B$63,2,FALSE),0) -> 0 | Z41: =G41+I41+K41+M41+O41+Q41+S41+U41+W41+Y41 -> 124
A42: 28 | B42: 26 | C42: 33 | D42: BRUNELLE Alix* | E42: SIBOIRE QUIROULE | O42: =IFERROR(VLOOKUP(N42,'Puntos XCC Mayor'!$A$1:$B$15,2,FALSE),0) -> 0 | P42: 5 | Q42: =IFERROR(VLOOKUP(P42,'Puntos XCO'!$A$1:$B$63,2,FALSE),0) -> 100 | R42: 0 | S42: =IFERROR(VLOOKUP(R42,'Puntos XCC Mayor'!$A$1:$B$15,2,FALSE),0) -> 0 | T42: 0 | U42: =IFERROR(VLOOKUP(T42,'Puntos XCO'!$A$1:$B$63,2,FALSE),0) -> 0 | V42: =IFERROR(VLOOKUP(C42,RESXCC_1,9,FALSE),0) -> 0 | W42: =IFERROR(VLOOKUP(V42,'Puntos XCC Mayor'!$A$1:$B$15,2,FALSE),0) -> 0 | X42: =IFERROR(VLOOKUP(C42,RESXCO,9,FALSE),0) -> 0 | Y42: =IFERROR(VLOOKUP(X42,'Puntos XCO'!$A$1:$B$63,2,FALSE),0) -> 0 | Z42: =G42+I42+K42+M42+O42+Q42+S42+U42+W42+Y42 -> 100
A43: 29 | B43: 28 | C43: 34 | D43: RODRIGUEZ Angel* | E43: 7EIGHT7 PROJECT | N43: 20 | O43: =IFERROR(VLOOKUP(N43,'Puntos XCC Mayor'!$A$1:$B$15,2,FALSE),0) -> 0 | P43: 7 | Q43: =IFERROR(VLOOKUP(P43,'Puntos XCO'!$A$1:$B$63,2,FALSE),0) -> 90 | R43: 0 | S43: =IFERROR(VLOOKUP(R43,'Puntos XCC Mayor'!$A$1:$B$15,2,FALSE),0) -> 0 | T43: 0 | U43: =IFERROR(VLOOKUP(T43,'Puntos XCO'!$A$1:$B$63,2,FALSE),0) -> 0 | V43: =IFERROR(VLOOKUP(C43,RESXCC_1,9,FALSE),0) -> 0 | W43: =IFERROR(VLOOKUP(V43,'Puntos XCC Mayor'!$A$1:$B$15,2,FALSE),0) -> 0 | X43: =IFERROR(VLOOKUP(C43,RESXCO,9,FALSE),0) -> 0 | Y43: =IFERROR(VLOOKUP(X43,'Puntos XCO'!$A$1:$B$63,2,FALSE),0) -> 0 | Z43: =G43+I43+K43+M43+O43+Q43+S43+U43+W43+Y43 -> 90
A44: 30 | B44: 29 | C44: 24 | D44: DUVAL Mathis* | E44: SIBOIRE QUIROULE | N44: 7 | O44: =IFERROR(VLOOKUP(N44,'Puntos XCC Mayor'!$A$1:$B$15,2,FALSE),0) -> 9 | P44: 9 | Q44: =IFERROR(VLOOKUP(P44,'Puntos XCO'!$A$1:$B$63,2,FALSE),0) -> 80 | R44: 0 | S44: =IFERROR(VLOOKUP(R44,'Puntos XCC Mayor'!$A$1:$B$15,2,FALSE),0) -> 0 | T44: 0 | U44: =IFERROR(VLOOKUP(T44,'Puntos XCO'!$A$1:$B$63,2,FALSE),0) -> 0 | V44: =IFERROR(VLOOKUP(C44,RESXCC_1,9,FALSE),0) -> 0 | W44: =IFERROR(VLOOKUP(V44,'Puntos XCC Mayor'!$A$1:$B$15,2,FALSE),0) -> 0 | X44: =IFERROR(VLOOKUP(C44,RESXCO,9,FALSE),0) -> 0 | Y44: =IFERROR(VLOOKUP(X44,'Puntos XCO'!$A$1:$B$63,2,FALSE),0) -> 0 | Z44: =G44+I44+K44+M44+O44+Q44+S44+U44+W44+Y44 -> 89
A45: 31 | B45: 30 | D45: AGUILAR Jonathan* | E45: MANZA TÉ LA SELVA SCOTT | F45: 3 | G45: 16 | H45: 13 | I45: 72 | J45: 0 | K45: 0 | L45: 0 | M45: 0 | O45: =IFERROR(VLOOKUP(N45,'Puntos XCC Mayor'!$A$1:$B$15,2,FALSE),0) -> 0 | Q45: =IFERROR(VLOOKUP(P45,'Puntos XCO'!$A$1:$B$63,2,FALSE),0) -> 0 | R45: 0 | S45: =IFERROR(VLOOKUP(R45,'Puntos XCC Mayor'!$A$1:$B$15,2,FALSE),0) -> 0 | T45: 0 | U45: =IFERROR(VLOOKUP(T45,'Puntos XCO'!$A$1:$B$63,2,FALSE),0) -> 0 | V45: =IFERROR(VLOOKUP(C45,RESXCC_1,9,FALSE),0) -> 0 | W45: =IFERROR(VLOOKUP(V45,'Puntos XCC Mayor'!$A$1:$B$15,2,FALSE),0) -> 0 | X45: =IFERROR(VLOOKUP(C45,RESXCO,9,FALSE),0) -> 0 | Y45: =IFERROR(VLOOKUP(X45,'Puntos XCO'!$A$1:$B$63,2,FALSE),0) -> 0 | Z45: =G45+I45+K45+M45+O45+Q45+S45+U45+W45+Y45 -> 88
A46: 32 | B46: 31 | C46: 36 | D46: LUNA José Carlos* | E46: MI BICLA | N46: 17 | O46: =IFERROR(VLOOKUP(N46,'Puntos XCC Mayor'!$A$1:$B$15,2,FALSE),0) -> 0 | P46: 8 | Q46: =IFERROR(VLOOKUP(P46,'Puntos XCO'!$A$1:$B$63,2,FALSE),0) -> 85 | R46: 0 | S46: =IFERROR(VLOOKUP(R46,'Puntos XCC Mayor'!$A$1:$B$15,2,FALSE),0) -> 0 | T46: 0 | U46: =IFERROR(VLOOKUP(T46,'Puntos XCO'!$A$1:$B$63,2,FALSE),0) -> 0 | V46: =IFERROR(VLOOKUP(C46,RESXCC_1,9,FALSE),0) -> 0 | W46: =IFERROR(VLOOKUP(V46,'Puntos XCC Mayor'!$A$1:$B$15,2,FALSE),0) -> 0 | X46: =IFERROR(VLOOKUP(C46,RESXCO,9,FALSE),0) -> 0 | Y46: =IFERROR(VLOOKUP(X46,'Puntos XCO'!$A$1:$B$63,2,FALSE),0) -> 0 | Z46: =G46+I46+K46+M46+O46+Q46+S46+U46+W46+Y46 -> 85
A47: 33 | B47: 32 | D47: MADRIGAL Adriano* | E47: CICLISMO BELÉN | F47: 11 | G47: 5 | H47: 9 | I47: 80 | J47: 0 | K47: 0 | L47: 0 | M47: 0 | O47: =IFERROR(VLOOKUP(N47,'Puntos XCC Mayor'!$A$1:$B$15,2,FALSE),0) -> 0 | Q47: =IFERROR(VLOOKUP(P47,'Puntos XCO'!$A$1:$B$63,2,FALSE),0) -> 0 | R47: 0 | S47: =IFERROR(VLOOKUP(R47,'Puntos XCC Mayor'!$A$1:$B$15,2,FALSE),0) -> 0 | T47: 0 | U47: =IFERROR(VLOOKUP(T47,'Puntos XCO'!$A$1:$B$63,2,FALSE),0) -> 0 | V47: =IFERROR(VLOOKUP(C47,RESXCC_1,9,FALSE),0) -> 0 | W47: =IFERROR(VLOOKUP(V47,'Puntos XCC Mayor'!$A$1:$B$15,2,FALSE),0) -> 0 | X47: =IFERROR(VLOOKUP(C47,RESXCO,9,FALSE),0) -> 0 | Y47: =IFERROR(VLOOKUP(X47,'Puntos XCO'!$A$1:$B$63,2,FALSE),0) -> 0 | Z47: =G47+I47+K47+M47+O47+Q47+S47+U47+W47+Y47 -> 85
A48: 34 | C48: 39 | D48: =VLOOKUP(C48,PLANILLA,2,FALSE) -> ROJAS Juan Diego* | E48: =VLOOKUP(C48,PLANILLA,4,FALSE) -> MEGAMO MANZATÉ LA SELVA | V48: =IFERROR(VLOOKUP(C48,RESXCC_1,9,FALSE),0) -> 11 | W48: =IFERROR(VLOOKUP(V48,'Puntos XCC Mayor'!$A$1:$B$15,2,FALSE),0) -> 5 | X48: =IFERROR(VLOOKUP(C48,RESXCO,9,FALSE),0) -> 11 | Y48: =IFERROR(VLOOKUP(X48,'Puntos XCO'!$A$1:$B$63,2,FALSE),0) -> 76 | Z48: =G48+I48+K48+M48+O48+Q48+S48+U48+W48+Y48 -> 81
A49: 35 | B49: 33 | C49: 11 | D49: FARNWORTH Landon | E49: UNATTACHED | N49: 19 | O49: =IFERROR(VLOOKUP(N49,'Puntos XCC Mayor'!$A$1:$B$15,2,FALSE),0) -> 0 | P49: 9 | Q49: =IFERROR(VLOOKUP(P49,'Puntos XCO'!$A$1:$B$63,2,FALSE),0) -> 80 | R49: 0 | S49: =IFERROR(VLOOKUP(R49,'Puntos XCC Mayor'!$A$1:$B$15,2,FALSE),0) -> 0 | T49: 0 | U49: =IFERROR(VLOOKUP(T49,'Puntos XCO'!$A$1:$B$63,2,FALSE),0) -> 0 | V49: =IFERROR(VLOOKUP(C49,RESXCC_1,9,FALSE),0) -> 0 | W49: =IFERROR(VLOOKUP(V49,'Puntos XCC Mayor'!$A$1:$B$15,2,FALSE),0) -> 0 | X49: =IFERROR(VLOOKUP(C49,RESXCO,9,FALSE),0) -> 0 | Y49: =IFERROR(VLOOKUP(X49,'Puntos XCO'!$A$1:$B$63,2,FALSE),0) -> 0 | Z49: =G49+I49+K49+M49+O49+Q49+S49+U49+W49+Y49 -> 80
...

Sheet Res I Fecha

Sheet Res II Fecha
A1: ELITE
A3: 2
A4: 1
A5: 20
A6: 3
A7: 28
A8: 34
A9: 109 | B9: sub 23
A10: 10
A11: 7
A12: 31
A13: 6
A14: 15
A15: 33
A16: 32
A17: 128 | B17: sub 23
A18: 9
A19: 121 | B19: sub 23
A20: 12
A21: 124 | B21: sub 23
A22: 11
A23: 22
A24: 4
A25: 125 | B25: sub 23
A26: 115 | B26: sub 23
A27: 24
A28: 35
A29: 117 | B29: sub 23
A30: 8
A31: 127 | B31: sub 23
A32: 37
A33: 110 | B33: sub 23
A34: 36
A35: 23
A36: 116 | B36: sub 23
A37: 123 | B37: sub 23
A38: 18
A39: 27
A40: 26
A41: 16
...

Sheet SUB23
A8: SUB23 MASCULINO (19-22)
A10: 1 - Finca Grupo Orosi >21 y 22 febrero 2 - Parque La Libertad Desamparados > 28 y 29 marzo 3 - Adventure Park > 16 y 17 mayo 4 - Finca La Hisopa San Pedro de Turrubares > 13 y 14 junio
A11: 5 - > 18 y 19 julio 6 - > 12 y 13 setiembre 7 - > 31 Oct y 01 Nov
A13: POSICION | F13: 1 | J13: 2 | N13: 3 | R13: 4 | V13: 5 | Z13: TOTAL PUNTOS
A14: ACTUAL | B14: ANTERIOR | C14: NO | D14: NOMBRE | E14: EQUIPO | F14: POS XCC | G14: PTOS XCC | H14: POS XCO | I14: PTOS XCO | J14: POS XCC | K14: PTOS XCC | L14: POS XCO | M14: PTOS XCO | N14: POS XCC | O14: PTOS XCC | P14: POS XCO | Q14: PTOS XCO | R14: POS XCC | S14: PTOS XCC | T14: POS XCO | U14: PTOS XCO | V14: POS XCC | W14: PTOS XCC | X14: POS XCO | Y14: PTOS XCO
A15: 1 | B15: 2 | C15: 25 | D15: GONZÁLEZ Adriano* | E15: COLONO BIKE STATION KOLBI | F15: 3 | G15: =IFERROR(VLOOKUP(F15,'Puntos XCC Mayor'!$A$1:$B$15,2,FALSE),0) -> 16 | H15: 1 | I15: =IFERROR(VLOOKUP(H15,'Puntos XCO'!$A$1:$B$63,2,FALSE),0) -> 200 | J15: 2 | K15: =IFERROR(VLOOKUP(J15,'Puntos XCC Mayor'!$A$1:$B$15,2,FALSE),"0") -> 20 | L15: 1 | M15: =IFERROR(VLOOKUP(L15,'Puntos XCO'!$A$1:$B$63,2,FALSE),0) -> 200 | N15: 5 | O15: =IFERROR(VLOOKUP(N15,'Puntos XCC Mayor'!$A$1:$B$15,2,FALSE),0) -> 12 | P15: 4 | Q15: =IFERROR(VLOOKUP(P15,'Puntos XCO'!$A$1:$B$63,2,FALSE),0) -> 110 | R15: 2 | S15: =IFERROR(VLOOKUP(R15,'Puntos XCC Mayor'!$A$1:$B$15,2,FALSE),0) -> 20 | U15: =IFERROR(VLOOKUP(T15,'Puntos XCO'!$A$1:$B$63,2,FALSE),0) -> 0 | V15: 2 | W15: =IFERROR(VLOOKUP(V15,'Puntos XCC Mayor'!$A$1:$B$15,2,FALSE),0) -> 20 | X15: 2 | Y15: =IFERROR(VLOOKUP(X15,'Puntos XCO'!$A$1:$B$63,2,FALSE),0) -> 150 | Z15: =G15+I15+K15+M15+O15+Q15+S15+U15+W15+Y15 -> 748
A16: 2 | B16: 1 | C16: 27 | D16: RAABE Fabricio* | E16: COLONO BIKE STATION KOLBI | F16: 7 | G16: =IFERROR(VLOOKUP(F16,'Puntos XCC Mayor'!$A$1:$B$15,2,FALSE),0) -> 9 | H16: 2 | I16: =IFERROR(VLOOKUP(H16,'Puntos XCO'!$A$1:$B$63,2,FALSE),0) -> 150 | J16: 6 | K16: =IFERROR(VLOOKUP(J16,'Puntos XCC Mayor'!$A$1:$B$15,2,FALSE),"0") -> 10 | L16: 2 | M16: =IFERROR(VLOOKUP(L16,'Puntos XCO'!$A$1:$B$63,2,FALSE),0) -> 150 | N16: 6 | O16: =IFERROR(VLOOKUP(N16,'Puntos XCC Mayor'!$A$1:$B$15,2,FALSE),0) -> 10 | P16: 3 | Q16: =IFERROR(VLOOKUP(P16,'Puntos XCO'!$A$1:$B$63,2,FALSE),0) -> 120 | R16: 3 | S16: =IFERROR(VLOOKUP(R16,'Puntos XCC Mayor'!$A$1:$B$15,2,FALSE),0) -> 16 | T16: 2 | U16: =IFERROR(VLOOKUP(T16,'Puntos XCO'!$A$1:$B$63,2,FALSE),0) -> 150 | V16: 7 | W16: =IFERROR(VLOOKUP(V16,'Puntos XCC Mayor'!$A$1:$B$15,2,FALSE),0) -> 9 | X16: 4 | Y16: =IFERROR(VLOOKUP(X16,'Puntos XCO'!$A$1:$B$63,2,FALSE),0) -> 110 | Z16: =G16+I16+K16+M16+O16+Q16+S16+U16+W16+Y16 -> 734
A17: 3 | B17: 3 | C17: 28 | D17: AZOFEIFA Daniel* | E17: BOBBYS CYCLING TEAM | F17: 9 | G17: =IFERROR(VLOOKUP(F17,'Puntos XCC Mayor'!$A$1:$B$15,2,FALSE),0) -> 7 | H17: 4 | I17: =IFERROR(VLOOKUP(H17,'Puntos XCO'!$A$1:$B$63,2,FALSE),0) -> 110 | J17: 3 | K17: =IFERROR(VLOOKUP(J17,'Puntos XCC Mayor'!$A$1:$B$15,2,FALSE),"0") -> 16 | L17: 4 | M17: =IFERROR(VLOOKUP(L17,'Puntos XCO'!$A$1:$B$63,2,FALSE),0) -> 110 | N17: 7 | O17: =IFERROR(VLOOKUP(N17,'Puntos XCC Mayor'!$A$1:$B$15,2,FALSE),0) -> 9 | P17: 6 | Q17: =IFERROR(VLOOKUP(P17,'Puntos XCO'!$A$1:$B$63,2,FALSE),0) -> 95 | R17: 1 | S17: =IFERROR(VLOOKUP(R17,'Puntos XCC Mayor'!$A$1:$B$15,2,FALSE),0) -> 25 | T17: 1 | U17: =IFERROR(VLOOKUP(T17,'Puntos XCO'!$A$1:$B$63,2,FALSE),0) -> 200 | V17: 3 | W17: =IFERROR(VLOOKUP(V17,'Puntos XCC Mayor'!$A$1:$B$15,2,FALSE),0) -> 16 | X17: 8 | Y17: =IFERROR(VLOOKUP(X17,'Puntos XCO'!$A$1:$B$63,2,FALSE),0) -> 85 | Z17: =G17+I17+K17+M17+O17+Q17+S17+U17+W17+Y17 -> 673
A18: 4 | B18: 4 | C18: 26 | D18: VARGAS José David* | E18: COLONO BIKE STATION KOLBI | J18: 5 | K18: =IFERROR(VLOOKUP(J18,'Puntos XCC Mayor'!$A$1:$B$15,2,FALSE),"0") -> 12 | L18: 3 | M18: =IFERROR(VLOOKUP(L18,'Puntos XCO'!$A$1:$B$63,2,FALSE),0) -> 120 | N18: 11 | O18: =IFERROR(VLOOKUP(N18,'Puntos XCC Mayor'!$A$1:$B$15,2,FALSE),0) -> 5 | P18: 10 | Q18: =IFERROR(VLOOKUP(P18,'Puntos XCO'!$A$1:$B$63,2,FALSE),0) -> 78 | R18: 5 | S18: =IFERROR(VLOOKUP(R18,'Puntos XCC Mayor'!$A$1:$B$15,2,FALSE),0) -> 12 | T18: 3 | U18: =IFERROR(VLOOKUP(T18,'Puntos XCO'!$A$1:$B$63,2,FALSE),0) -> 120 | V18: 9 | W18: =IFERROR(VLOOKUP(V18,'Puntos XCC Mayor'!$A$1:$B$15,2,FALSE),0) -> 7 | X18: 3 | Y18: =IFERROR(VLOOKUP(X18,'Puntos XCO'!$A$1:$B$63,2,FALSE),0) -> 120 | Z18: =G18+I18+K18+M18+O18+Q18+S18+U18+W18+Y18 -> 474
A19: 5 | B19: 9 | C19: 23 | D19: MENDEZ Jared* | E19: BOBBYS CYCLING TEAM | F19: 1 | G19: =IFERROR(VLOOKUP(F19,'Puntos XCC Mayor'!$A$1:$B$15,2,FALSE),0) -> 25 | H19: 3 | I19: =IFERROR(VLOOKUP(H19,'Puntos XCO'!$A$1:$B$63,2,FALSE),0) -> 120 | J19: 1 | K19: =IFERROR(VLOOKUP(J19,'Puntos XCC Mayor'!$A$1:$B$15,2,FALSE),"0") -> 25 | L19: 0 | M19: =IFERROR(VLOOKUP(L19,'Puntos XCO'!$A$1:$B$63,2,FALSE),0) -> 0 | N19: 4 | O19: =IFERROR(VLOOKUP(N19,'Puntos XCC Mayor'!$A$1:$B$15,2,FALSE),0) -> 14 | Q19: =IFERROR(VLOOKUP(P19,'Puntos XCO'!$A$1:$B$63,2,FALSE),0) -> 0 | S19: =IFERROR(VLOOKUP(R19,'Puntos XCC Mayor'!$A$1:$B$15,2,FALSE),0) -> 0 | U19: =IFERROR(VLOOKUP(T19,'Puntos XCO'!$A$1:$B$63,2,FALSE),0) -> 0 | V19: 1 | W19: =IFERROR(VLOOKUP(V19,'Puntos XCC Mayor'!$A$1:$B$15,2,FALSE),0) -> 25 | X19: 1 | Y19: =IFERROR(VLOOKUP(X19,'Puntos XCO'!$A$1:$B$63,2,FALSE),0) -> 200 | Z19: =G19+I19+K19+M19+O19+Q19+S19+U19+W19+Y19 -> 409
A20: 6 | B20: 5 | C20: 29 | D20: HIDALGO Stefano* | E20: BOBBYS CYCLING TEAM | F20: 4 | G20: =IFERROR(VLOOKUP(F20,'Puntos XCC Mayor'!$A$1:$B$15,2,FALSE),0) -> 14 | H20: 7 | I20: =IFERROR(VLOOKUP(H20,'Puntos XCO'!$A$1:$B$63,2,FALSE),0) -> 90 | J20: 4 | K20: =IFERROR(VLOOKUP(J20,'Puntos XCC Mayor'!$A$1:$B$15,2,FALSE),"0") -> 14 | L20: 5 | M20: =IFERROR(VLOOKUP(L20,'Puntos XCO'!$A$1:$B$63,2,FALSE),0) -> 100 | N20: 12 | O20: =IFERROR(VLOOKUP(N20,'Puntos XCC Mayor'!$A$1:$B$15,2,FALSE),0) -> 4 | P20: 11 | Q20: =IFERROR(VLOOKUP(P20,'Puntos XCO'!$A$1:$B$63,2,FALSE),0) -> 76 | R20: 4 | S20: =IFERROR(VLOOKUP(R20,'Puntos XCC Mayor'!$A$1:$B$15,2,FALSE),0) -> 14 | U20: =IFERROR(VLOOKUP(T20,'Puntos XCO'!$A$1:$B$63,2,FALSE),0) -> 0 | V20: 4 | W20: =IFERROR(VLOOKUP(V20,'Puntos XCC Mayor'!$A$1:$B$15,2,FALSE),0) -> 14 | X20: 9 | Y20: =IFERROR(VLOOKUP(X20,'Puntos XCO'!$A$1:$B$63,2,FALSE),0) -> 80 | Z20: =G20+I20+K20+M20+O20+Q20+S20+U20+W20+Y20 -> 406
A21: 7 | B21: 6 | C21: 37 | D21: ROJAS Alejandro* | E21: TEAM HC | F21: 10 | G21: =IFERROR(VLOOKUP(F21,'Puntos XCC Mayor'!$A$1:$B$15,2,FALSE),0) -> 6 | H21: 9 | I21: =IFERROR(VLOOKUP(H21,'Puntos XCO'!$A$1:$B$63,2,FALSE),0) -> 80 | J21: 7 | K21: =IFERROR(VLOOKUP(J21,'Puntos XCC Mayor'!$A$1:$B$15,2,FALSE),"0") -> 9 | L21: 8 | M21: =IFERROR(VLOOKUP(L21,'Puntos XCO'!$A$1:$B$63,2,FALSE),0) -> 85 | O21: =IFERROR(VLOOKUP(N21,'Puntos XCC Mayor'!$A$1:$B$15,2,FALSE),0) -> 0 | Q21: =IFERROR(VLOOKUP(P21,'Puntos XCO'!$A$1:$B$63,2,FALSE),0) -> 0 | R21: 6 | S21: =IFERROR(VLOOKUP(R21,'Puntos XCC Mayor'!$A$1:$B$15,2,FALSE),0) -> 10 | T21: 4 | U21: =IFERROR(VLOOKUP(T21,'Puntos XCO'!$A$1:$B$63,2,FALSE),0) -> 110 | V21: 5 | W21: =IFERROR(VLOOKUP(V21,'Puntos XCC Mayor'!$A$1:$B$15,2,FALSE),0) -> 12 | X21: 10 | Y21: =IFERROR(VLOOKUP(X21,'Puntos XCO'!$A$1:$B$63,2,FALSE),0) -> 78 | Z21: =G21+I21+K21+M21+O21+Q21+S21+U21+W21+Y21 -> 390
A22: 8 | B22: 8 | C22: 30 | D22: ALVARADO Armando* | E22: CCDR DESAMPARADOS | F22: 6 | G22: =IFERROR(VLOOKUP(F22,'Puntos XCC Mayor'!$A$1:$B$15,2,FALSE),0) -> 10 | H22: 6 | I22: =IFERROR(VLOOKUP(H22,'Puntos XCO'!$A$1:$B$63,2,FALSE),0) -> 95 | J22: 12 | K22: =IFERROR(VLOOKUP(J22,'Puntos XCC Mayor'!$A$1:$B$15,2,FALSE),"0") -> 4 | L22: 6 | M22: =IFERROR(VLOOKUP(L22,'Puntos XCO'!$A$1:$B$63,2,FALSE),0) -> 95 | N22: 9 | O22: =IFERROR(VLOOKUP(N22,'Puntos XCC Mayor'!$A$1:$B$15,2,FALSE),0) -> 7 | Q22: =IFERROR(VLOOKUP(P22,'Puntos XCO'!$A$1:$B$63,2,FALSE),0) -> 0 | R22: 7 | S22: =IFERROR(VLOOKUP(R22,'Puntos XCC Mayor'!$A$1:$B$15,2,FALSE),0) -> 9 | U22: =IFERROR(VLOOKUP(T22,'Puntos XCO'!$A$1:$B$63,2,FALSE),0) -> 0 | V22: 10 | W22: =IFERROR(VLOOKUP(V22,'Puntos XCC Mayor'!$A$1:$B$15,2,FALSE),0) -> 6 | X22: 5 | Y22: =IFERROR(VLOOKUP(X22,'Puntos XCO'!$A$1:$B$63,2,FALSE),0) -> 100 | Z22: =G22+I22+K22+M22+O22+Q22+S22+U22+W22+Y22 -> 326
A23: 9 | B23: 7 | C23: 22 | D23: TAILLEFER Tristan* | E23: PIVOT OTE CONTINENTAL | N23: 2 | O23: =IFERROR(VLOOKUP(N23,'Puntos XCC Mayor'!$A$1:$B$15,2,FALSE),0) -> 20 | P23: 1 | Q23: =IFERROR(VLOOKUP(P23,'Puntos XCO'!$A$1:$B$63,2,FALSE),0) -> 200 | S23: =IFERROR(VLOOKUP(R23,'Puntos XCC Mayor'!$A$1:$B$15,2,FALSE),0) -> 0 | U23: =IFERROR(VLOOKUP(T23,'Puntos XCO'!$A$1:$B$63,2,FALSE),0) -> 0 | W23: =IFERROR(VLOOKUP(V23,'Puntos XCC Mayor'!$A$1:$B$15,2,FALSE),0) -> 0 | Y23: =IFERROR(VLOOKUP(X23,'Puntos XCO'!$A$1:$B$63,2,FALSE),0) -> 0 | Z23: =G23+I23+K23+M23+O23+Q23+S23+U23+W23+Y23 -> 220
A24: 10 | B24: 16 | C24: 35 | D24: CASTILLO Alejandro* | E24: COLONO BIKE STATION KOLBI | N24: 13 | O24: =IFERROR(VLOOKUP(N24,'Puntos XCC Mayor'!$A$1:$B$15,2,FALSE),0) -> 3 | Q24: =IFERROR(VLOOKUP(P24,'Puntos XCO'!$A$1:$B$63,2,FALSE),0) -> 0 | S24: =IFERROR(VLOOKUP(R24,'Puntos XCC Mayor'!$A$1:$B$15,2,FALSE),0) -> 0 | T24: 5 | U24: =IFERROR(VLOOKUP(T24,'Puntos XCO'!$A$1:$B$63,2,FALSE),0) -> 100 | V24: 6 | W24: =IFERROR(VLOOKUP(V24,'Puntos XCC Mayor'!$A$1:$B$15,2,FALSE),0) -> 10 | X24: 6 | Y24: =IFERROR(VLOOKUP(X24,'Puntos XCO'!$A$1:$B$63,2,FALSE),0) -> 95 | Z24: =G24+I24+K24+M24+O24+Q24+S24+U24+W24+Y24 -> 208
A25: 11 | B25: 10 | C25: 21 | D25: SAN MARTIN Maximiliano* | E25: ER CICLISMO CHILE. | N25: 3 | O25: =IFERROR(VLOOKUP(N25,'Puntos XCC Mayor'!$A$1:$B$15,2,FALSE),0) -> 16 | P25: 2 | Q25: =IFERROR(VLOOKUP(P25,'Puntos XCO'!$A$1:$B$63,2,FALSE),0) -> 150 | S25: =IFERROR(VLOOKUP(R25,'Puntos XCC Mayor'!$A$1:$B$15,2,FALSE),0) -> 0 | U25: =IFERROR(VLOOKUP(T25,'Puntos XCO'!$A$1:$B$63,2,FALSE),0) -> 0 | W25: =IFERROR(VLOOKUP(V25,'Puntos XCC Mayor'!$A$1:$B$15,2,FALSE),0) -> 0 | Y25: =IFERROR(VLOOKUP(X25,'Puntos XCO'!$A$1:$B$63,2,FALSE),0) -> 0 | Z25: =G25+I25+K25+M25+O25+Q25+S25+U25+W25+Y25 -> 166
A26: 12 | B26: 11 | C26: 31 | D26: MORA Kendall* | E26: CODEA ALAJUELA | F26: 12 | G26: =IFERROR(VLOOKUP(F26,'Puntos XCC Mayor'!$A$1:$B$15,2,FALSE),0) -> 4 | H26: 12 | I26: =IFERROR(VLOOKUP(H26,'Puntos XCO'!$A$1:$B$63,2,FALSE),0) -> 74 | J26: 9 | K26: =IFERROR(VLOOKUP(J26,'Puntos XCC Mayor'!$A$1:$B$15,2,FALSE),"0") -> 7 | L26: 10 | M26: =IFERROR(VLOOKUP(L26,'Puntos XCO'!$A$1:$B$63,2,FALSE),0) -> 78 | O26: =IFERROR(VLOOKUP(N26,'Puntos XCC Mayor'!$A$1:$B$15,2,FALSE),0) -> 0 | Q26: =IFERROR(VLOOKUP(P26,'Puntos XCO'!$A$1:$B$63,2,FALSE),0) -> 0 | S26: =IFERROR(VLOOKUP(R26,'Puntos XCC Mayor'!$A$1:$B$15,2,FALSE),0) -> 0 | U26: =IFERROR(VLOOKUP(T26,'Puntos XCO'!$A$1:$B$63,2,FALSE),0) -> 0 | W26: =IFERROR(VLOOKUP(V26,'Puntos XCC Mayor'!$A$1:$B$15,2,FALSE),0) -> 0 | Y26: =IFERROR(VLOOKUP(X26,'Puntos XCO'!$A$1:$B$63,2,FALSE),0) -> 0 | Z26: =G26+I26+K26+M26+O26+Q26+S26+U26+W26+Y26 -> 163
A27: 13 | B27: 12 | C27: 32 | D27: TORRES Kevin* | E27: 1000 FPS- ZONA INFINITO SPORT | F27: 11 | G27: =IFERROR(VLOOKUP(F27,'Puntos XCC Mayor'!$A$1:$B$15,2,FALSE),0) -> 5 | H27: 11 | I27: =IFERROR(VLOOKUP(H27,'Puntos XCO'!$A$1:$B$63,2,FALSE),0) -> 76 | J27: 0 | K27: =IFERROR(VLOOKUP(J27,'Puntos XCC Mayor'!$A$1:$B$15,2,FALSE),"0") -> 0 | L27: 0 | M27: =IFERROR(VLOOKUP(L27,'Puntos XCO'!$A$1:$B$63,2,FALSE),0) -> 0 | N27: 14 | O27: =IFERROR(VLOOKUP(N27,'Puntos XCC Mayor'!$A$1:$B$15,2,FALSE),0) -> 2 | P27: 12 | Q27: =IFERROR(VLOOKUP(P27,'Puntos XCO'!$A$1:$B$63,2,FALSE),0) -> 74 | S27: =IFERROR(VLOOKUP(R27,'Puntos XCC Mayor'!$A$1:$B$15,2,FALSE),0) -> 0 | U27: =IFERROR(VLOOKUP(T27,'Puntos XCO'!$A$1:$B$63,2,FALSE),0) -> 0 | W27: =IFERROR(VLOOKUP(V27,'Puntos XCC Mayor'!$A$1:$B$15,2,FALSE),0) -> 0 | Y27: =IFERROR(VLOOKUP(X27,'Puntos XCO'!$A$1:$B$63,2,FALSE),0) -> 0 | Z27: =G27+I27+K27+M27+O27+Q27+S27+U27+W27+Y27 -> 157
A28: 14 | B28: 13 | D28: MADRIGAL Adriano* | E28: CICLISMO BELÉN | F28: 8 | G28: =IFERROR(VLOOKUP(F28,'Puntos XCC Mayor'!$A$1:$B$15,2,FALSE),0) -> 8 | H28: 5 | I28: =IFERROR(VLOOKUP(H28,'Puntos XCO'!$A$1:$B$63,2,FALSE),0) -> 100 | J28: 0 | K28: =IFERROR(VLOOKUP(J28,'Puntos XCC Mayor'!$A$1:$B$15,2,FALSE),"0") -> 0 | L28: 0 | M28: =IFERROR(VLOOKUP(L28,'Puntos XCO'!$A$1:$B$63,2,FALSE),0) -> 0 | O28: =IFERROR(VLOOKUP(N28,'Puntos XCC Mayor'!$A$1:$B$15,2,FALSE),0) -> 0 | Q28: =IFERROR(VLOOKUP(P28,'Puntos XCO'!$A$1:$B$63,2,FALSE),0) -> 0 | S28: =IFERROR(VLOOKUP(R28,'Puntos XCC Mayor'!$A$1:$B$15,2,FALSE),0) -> 0 | U28: =IFERROR(VLOOKUP(T28,'Puntos XCO'!$A$1:$B$63,2,FALSE),0) -> 0 | W28: =IFERROR(VLOOKUP(V28,'Puntos XCC Mayor'!$A$1:$B$15,2,FALSE),0) -> 0 | Y28: =IFERROR(VLOOKUP(X28,'Puntos XCO'!$A$1:$B$63,2,FALSE),0) -> 0 | Z28: =G28+I28+K28+M28+O28+Q28+S28+U28+W28+Y28 -> 108
A29: 15 | B29: 14 | D29: AGUILAR Jonathan* | E29: MANZA TÉ LA SELVA SCOTT | F29: 2 | G29: =IFERROR(VLOOKUP(F29,'Puntos XCC Mayor'!$A$1:$B$15,2,FALSE),0) -> 20 | H29: 8 | I29: =IFERROR(VLOOKUP(H29,'Puntos XCO'!$A$1:$B$63,2,FALSE),0) -> 85 | J29: 0 | K29: =IFERROR(VLOOKUP(J29,'Puntos XCC Mayor'!$A$1:$B$15,2,FALSE),"0") -> 0 | L29: 0 | M29: =IFERROR(VLOOKUP(L29,'Puntos XCO'!$A$1:$B$63,2,FALSE),0) -> 0 | O29: =IFERROR(VLOOKUP(N29,'Puntos XCC Mayor'!$A$1:$B$15,2,FALSE),0) -> 0 | Q29: =IFERROR(VLOOKUP(P29,'Puntos XCO'!$A$1:$B$63,2,FALSE),0) -> 0 | S29: =IFERROR(VLOOKUP(R29,'Puntos XCC Mayor'!$A$1:$B$15,2,FALSE),0) -> 0 | U29: =IFERROR(VLOOKUP(T29,'Puntos XCO'!$A$1:$B$63,2,FALSE),0) -> 0 | W29: =IFERROR(VLOOKUP(V29,'Puntos XCC Mayor'!$A$1:$B$15,2,FALSE),0) -> 0 | Y29: =IFERROR(VLOOKUP(X29,'Puntos XCO'!$A$1:$B$63,2,FALSE),0) -> 0 | Z29: =G29+I29+K29+M29+O29+Q29+S29+U29+W29+Y29 -> 105
A30: 16 | B30: 15 | C30: 24 | D30: DUVAL Mathis* | E30: SIBOIRE QUIROULE | N30: 1 | O30: =IFERROR(VLOOKUP(N30,'Puntos XCC Mayor'!$A$1:$B$15,2,FALSE),0) -> 25 | P30: 9 | Q30: =IFERROR(VLOOKUP(P30,'Puntos XCO'!$A$1:$B$63,2,FALSE),0) -> 80 | S30: =IFERROR(VLOOKUP(R30,'Puntos XCC Mayor'!$A$1:$B$15,2,FALSE),0) -> 0 | U30: =IFERROR(VLOOKUP(T30,'Puntos XCO'!$A$1:$B$63,2,FALSE),0) -> 0 | W30: =IFERROR(VLOOKUP(V30,'Puntos XCC Mayor'!$A$1:$B$15,2,FALSE),0) -> 0 | Y30: =IFERROR(VLOOKUP(X30,'Puntos XCO'!$A$1:$B$63,2,FALSE),0) -> 0 | Z30: =G30+I30+K30+M30+O30+Q30+S30+U30+W30+Y30 -> 105
A31: 17 | B31: 17 | C31: 33 | D31: BRUNELLE Alix* | E31: SIBOIRE QUIROULE | O31: =IFERROR(VLOOKUP(N31,'Puntos XCC Mayor'!$A$1:$B$15,2,FALSE),0) -> 0 | P31: 5 | Q31: =IFERROR(VLOOKUP(P31,'Puntos XCO'!$A$1:$B$63,2,FALSE),0) -> 100 | S31: =IFERROR(VLOOKUP(R31,'Puntos XCC Mayor'!$A$1:$B$15,2,FALSE),0) -> 0 | U31: =IFERROR(VLOOKUP(T31,'Puntos XCO'!$A$1:$B$63,2,FALSE),0) -> 0 | W31: =IFERROR(VLOOKUP(V31,'Puntos XCC Mayor'!$A$1:$B$15,2,FALSE),0) -> 0 | Y31: =IFERROR(VLOOKUP(X31,'Puntos XCO'!$A$1:$B$63,2,FALSE),0) -> 0 | Z31: =G31+I31+K31+M31+O31+Q31+S31+U31+W31+Y31 -> 100
A32: 18 | B32: 18 | D32: HIDALGO Isaac* | E32: TEAM COSTAFRUT GIANT AC MARRIOT | J32: 8 | K32: =IFERROR(VLOOKUP(J32,'Puntos XCC Mayor'!$A$1:$B$15,2,FALSE),"0") -> 8 | L32: 7 | M32: =IFERROR(VLOOKUP(L32,'Puntos XCO'!$A$1:$B$63,2,FALSE),0) -> 90 | O32: =IFERROR(VLOOKUP(N32,'Puntos XCC Mayor'!$A$1:$B$15,2,FALSE),0) -> 0 | Q32: =IFERROR(VLOOKUP(P32,'Puntos XCO'!$A$1:$B$63,2,FALSE),0) -> 0 | S32: =IFERROR(VLOOKUP(R32,'Puntos XCC Mayor'!$A$1:$B$15,2,FALSE),0) -> 0 | U32: =IFERROR(VLOOKUP(T32,'Puntos XCO'!$A$1:$B$63,2,FALSE),0) -> 0 | W32: =IFERROR(VLOOKUP(V32,'Puntos XCC Mayor'!$A$1:$B$15,2,FALSE),0) -> 0 | Y32: =IFERROR(VLOOKUP(X32,'Puntos XCO'!$A$1:$B$63,2,FALSE),0) -> 0 | Z32: =G32+I32+K32+M32+O32+Q32+S32+U32+W32+Y32 -> 98
A33: 19 | C33: 39 | D33: =VLOOKUP(C33,PLANILLA,2,FALSE) -> ROJAS Juan Diego* | E33: =VLOOKUP(C33,PLANILLA,4,FALSE) -> MEGAMO MANZATÉ LA SELVA | V33: 8 | W33: =IFERROR(VLOOKUP(V33,'Puntos XCC Mayor'!$A$1:$B$15,2,FALSE),0) -> 8 | X33: 7 | Y33: =IFERROR(VLOOKUP(X33,'Puntos XCO'!$A$1:$B$63,2,FALSE),0) -> 90 | Z33: =G33+I33+K33+M33+O33+Q33+S33+U33+W33+Y33 -> 98
A34: 20 | B34: 19 | C34: 34 | D34: RODRIGUEZ Angel* | E34: 7EIGHT7 PROJECT | N34: 10 | O34: =IFERROR(VLOOKUP(N34,'Puntos XCC Mayor'!$A$1:$B$15,2,FALSE),0) -> 6 | P34: 7 | Q34: =IFERROR(VLOOKUP(P34,'Puntos XCO'!$A$1:$B$63,2,FALSE),0) -> 90 | S34: =IFERROR(VLOOKUP(R34,'Puntos XCC Mayor'!$A$1:$B$15,2,FALSE),0) -> 0 | U34: =IFERROR(VLOOKUP(T34,'Puntos XCO'!$A$1:$B$63,2,FALSE),0) -> 0 | W34: =IFERROR(VLOOKUP(V34,'Puntos XCC Mayor'!$A$1:$B$15,2,FALSE),0) -> 0 | Y34: =IFERROR(VLOOKUP(X34,'Puntos XCO'!$A$1:$B$63,2,FALSE),0) -> 0 | Z34: =G34+I34+K34+M34+O34+Q34+S34+U34+W34+Y34 -> 96
A35: 21 | C35: 38 | D35: =VLOOKUP(C35,PLANILLA,2,FALSE) -> ARAYA Roberto* | E35: =VLOOKUP(C35,PLANILLA,4,FALSE) -> CCDR PARAÍSO | S35: =IFERROR(VLOOKUP(R35,'Puntos XCC Mayor'!$A$1:$B$15,2,FALSE),0) -> 0 | T35: 6 | U35: =IFERROR(VLOOKUP(T35,'Puntos XCO'!$A$1:$B$63,2,FALSE),0) -> 95 | W35: =IFERROR(VLOOKUP(V35,'Puntos XCC Mayor'!$A$1:$B$15,2,FALSE),0) -> 0 | Y35: =IFERROR(VLOOKUP(X35,'Puntos XCO'!$A$1:$B$63,2,FALSE),0) -> 0 | Z35: =G35+I35+K35+M35+O35+Q35+S35+U35+W35+Y35 -> 95
A36: 22 | B36: 20 | C36: 36 | D36: LUNA José Carlos* | E36: MI BICLA | N36: 8 | O36: =IFERROR(VLOOKUP(N36,'Puntos XCC Mayor'!$A$1:$B$15,2,FALSE),0) -> 8 | P36: 8 | Q36: =IFERROR(VLOOKUP(P36,'Puntos XCO'!$A$1:$B$63,2,FALSE),0) -> 85 | S36: =IFERROR(VLOOKUP(R36,'Puntos XCC Mayor'!$A$1:$B$15,2,FALSE),0) -> 0 | U36: =IFERROR(VLOOKUP(T36,'Puntos XCO'!$A$1:$B$63,2,FALSE),0) -> 0 | W36: =IFERROR(VLOOKUP(V36,'Puntos XCC Mayor'!$A$1:$B$15,2,FALSE),0) -> 0 | Y36: =IFERROR(VLOOKUP(X36,'Puntos XCO'!$A$1:$B$63,2,FALSE),0) -> 0 | Z36: =G36+I36+K36+M36+O36+Q36+S36+U36+W36+Y36 -> 93
A37: 23 | B37: 21 | D37: CAMACHO Jeancarlo * | E37: INDEPENDIENTE | J37: 10 | K37: =IFERROR(VLOOKUP(J37,'Puntos XCC Mayor'!$A$1:$B$15,2,FALSE),"0") -> 6 | L37: 9 | M37: =IFERROR(VLOOKUP(L37,'Puntos XCO'!$A$1:$B$63,2,FALSE),0) -> 80 | O37: =IFERROR(VLOOKUP(N37,'Puntos XCC Mayor'!$A$1:$B$15,2,FALSE),0) -> 0 | Q37: =IFERROR(VLOOKUP(P37,'Puntos XCO'!$A$1:$B$63,2,FALSE),0) -> 0 | S37: =IFERROR(VLOOKUP(R37,'Puntos XCC Mayor'!$A$1:$B$15,2,FALSE),0) -> 0 | U37: =IFERROR(VLOOKUP(T37,'Puntos XCO'!$A$1:$B$63,2,FALSE),0) -> 0 | W37: =IFERROR(VLOOKUP(V37,'Puntos XCC Mayor'!$A$1:$B$15,2,FALSE),0) -> 0 | Y37: =IFERROR(VLOOKUP(X37,'Puntos XCO'!$A$1:$B$63,2,FALSE),0) -> 0 | Z37: =G37+I37+K37+M37+O37+Q37+S37+U37+W37+Y37 -> 86
A38: 24 | B38: 22 | D38: ALFARO Jeison* | E38: INDEPENDIENTE | J38: 11 | K38: =IFERROR(VLOOKUP(J38,'Puntos XCC Mayor'!$A$1:$B$15,2,FALSE),"0") -> 5 | L38: 11 | M38: =IFERROR(VLOOKUP(L38,'Puntos XCO'!$A$1:$B$63,2,FALSE),0) -> 76 | O38: =IFERROR(VLOOKUP(N38,'Puntos XCC Mayor'!$A$1:$B$15,2,FALSE),0) -> 0 | Q38: =IFERROR(VLOOKUP(P38,'Puntos XCO'!$A$1:$B$63,2,FALSE),0) -> 0 | S38: =IFERROR(VLOOKUP(R38,'Puntos XCC Mayor'!$A$1:$B$15,2,FALSE),0) -> 0 | U38: =IFERROR(VLOOKUP(T38,'Puntos XCO'!$A$1:$B$63,2,FALSE),0) -> 0 | W38: =IFERROR(VLOOKUP(V38,'Puntos XCC Mayor'!$A$1:$B$15,2,FALSE),0) -> 0 | Y38: =IFERROR(VLOOKUP(X38,'Puntos XCO'!$A$1:$B$63,2,FALSE),0) -> 0 | Z38: =G38+I38+K38+M38+O38+Q38+S38+U38+W38+Y38 -> 81
A39: 25 | C39: 40 | D39: =VLOOKUP(C39,PLANILLA,2,FALSE) -> GUTIÉRREZ Carlos Daniel* | E39: =VLOOKUP(C39,PLANILLA,4,FALSE) -> TURRIALBA | V39: 11 | W39: =IFERROR(VLOOKUP(V39,'Puntos XCC Mayor'!$A$1:$B$15,2,FALSE),0) -> 5 | X39: 12 | Y39: =IFERROR(VLOOKUP(X39,'Puntos XCO'!$A$1:$B$63,2,FALSE),0) -> 74 | Z39: =G39+I39+K39+M39+O39+Q39+S39+U39+W39+Y39 -> 79
A40: 26 | B40: 23 | D40: MENESES Sebastian* | E40: MANZATE LA SELVA SCOTT | F40: 0 | G40: =IFERROR(VLOOKUP(F40,'Puntos XCC Mayor'!$A$1:$B$15,2,FALSE),0) -> 0 | H40: 10 | I40: =IFERROR(VLOOKUP(H40,'Puntos XCO'!$A$1:$B$63,2,FALSE),0) -> 78 | J40: 0 | K40: =IFERROR(VLOOKUP(J40,'Puntos XCC Mayor'!$A$1:$B$15,2,FALSE),"0") -> 0 | L40: 0 | M40: =IFERROR(VLOOKUP(L40,'Puntos XCO'!$A$1:$B$63,2,FALSE),0) -> 0 | O40: =IFERROR(VLOOKUP(N40,'Puntos XCC Mayor'!$A$1:$B$15,2,FALSE),0) -> 0 | Q40: =IFERROR(VLOOKUP(P40,'Puntos XCO'!$A$1:$B$63,2,FALSE),0) -> 0 | S40: =IFERROR(VLOOKUP(R40,'Puntos XCC Mayor'!$A$1:$B$15,2,FALSE),0) -> 0 | U40: =IFERROR(VLOOKUP(T40,'Puntos XCO'!$A$1:$B$63,2,FALSE),0) -> 0 | W40: =IFERROR(VLOOKUP(V40,'Puntos XCC Mayor'!$A$1:$B$15,2,FALSE),0) -> 0 | Y40: =IFERROR(VLOOKUP(X40,'Puntos XCO'!$A$1:$B$63,2,FALSE),0) -> 0 | Z40: =G40+I40+K40+M40+O40+Q40+S40+U40+W40+Y40 -> 78
A41: 27 | C41: 41 | D41: =VLOOKUP(C41,PLANILLA,2,FALSE) -> FERNÁNDEZ Fabricio Alberto* | E41: =VLOOKUP(C41,PLANILLA,4,FALSE) | W41: =IFERROR(VLOOKUP(V41,'Puntos XCC Mayor'!$A$1:$B$15,2,FALSE),0) -> 0 | X41: 11 | Y41: =IFERROR(VLOOKUP(X41,'Puntos XCO'!$A$1:$B$63,2,FALSE),0) -> 76 | Z41: =G41+I41+K41+M41+O41+Q41+S41+U41+W41+Y41 -> 76
A42: 28 | B42: 24 | D42: VARGAS Ismael Felipe* | E42: 7C ECONOMIC HYUNDAI | F42: 5 | G42: =IFERROR(VLOOKUP(F42,'Puntos XCC Mayor'!$A$1:$B$15,2,FALSE),0) -> 12 | H42: 0 | I42: =IFERROR(VLOOKUP(H42,'Puntos XCO'!$A$1:$B$63,2,FALSE),0) -> 0 | J42: 0 | K42: =IFERROR(VLOOKUP(J42,'Puntos XCC Mayor'!$A$1:$B$15,2,FALSE),"0") -> 0 | L42: 0 | M42: =IFERROR(VLOOKUP(L42,'Puntos XCO'!$A$1:$B$63,2,FALSE),0) -> 0 | O42: =IFERROR(VLOOKUP(N42,'Puntos XCC Mayor'!$A$1:$B$15,2,FALSE),0) -> 0 | Q42: =IFERROR(VLOOKUP(P42,'Puntos XCO'!$A$1:$B$63,2,FALSE),0) -> 0 | S42: =IFERROR(VLOOKUP(R42,'Puntos XCC Mayor'!$A$1:$B$15,2,FALSE),0) -> 0 | U42: =IFERROR(VLOOKUP(T42,'Puntos XCO'!$A$1:$B$63,2,FALSE),0) -> 0 | W42: =IFERROR(VLOOKUP(V42,'Puntos XCC Mayor'!$A$1:$B$15,2,FALSE),0) -> 0 | Y42: =IFERROR(VLOOKUP(X42,'Puntos XCO'!$A$1:$B$63,2,FALSE),0) -> 0 | Z42: =G42+I42+K42+M42+O42+Q42+S42+U42+W42+Y42 -> 12
B43: 25 | D43: CAMPOS Haswel* | E43: DESAMPARADOS | F43: 0 | G43: =IFERROR(VLOOKUP(F43,'Puntos XCC Mayor'!$A$1:$B$15,2,FALSE),0) -> 0 | H43: 0 | I43: =IFERROR(VLOOKUP(H43,'Puntos XCO'!$A$1:$B$63,2,FALSE),0) -> 0 | J43: 0 | K43: =IFERROR(VLOOKUP(J43,'Puntos XCC Mayor'!$A$1:$B$15,2,FALSE),"0") -> 0 | L43: 0 | M43: =IFERROR(VLOOKUP(L43,'Puntos XCO'!$A$1:$B$63,2,FALSE),0) -> 0 | O43: =IFERROR(VLOOKUP(N43,'Puntos XCC Mayor'!$A$1:$B$15,2,FALSE),0) -> 0 | Q43: =IFERROR(VLOOKUP(P43,'Puntos XCO'!$A$1:$B$63,2,FALSE),0) -> 0 | S43: =IFERROR(VLOOKUP(R43,'Puntos XCC Mayor'!$A$1:$B$15,2,FALSE),0) -> 0 | U43: =IFERROR(VLOOKUP(T43,'Puntos XCO'!$A$1:$B$63,2,FALSE),0) -> 0 | W43: =IFERROR(VLOOKUP(V43,'Puntos XCC Mayor'!$A$1:$B$15,2,FALSE),0) -> 0 | Y43: =IFERROR(VLOOKUP(X43,'Puntos XCO'!$A$1:$B$63,2,FALSE),0) -> 0 | Z43: =G43+I43+K43+M43+O43+Q43+S43+U43+W43+Y43 -> 0

Sheet EF
A8: ELITE FEMENINO
A10: 1 - Finca Grupo Orosi >21 y 22 febrero 2 - Parque La Libertad Desamparados > 28 y 29 marzo 3 - Adventure Park > 16 y 17 mayo 4 - Finca La Hisopa San Pedro de Turrubares > 13 y 14 junio
A11: 5 - > 18 y 19 julio 6 - > 12 y 13 setiembre 7 - > 31 Oct y 01 Nov
A13: POSICION | F13: 1 | J13: 2 | N13: 3 | R13: 4 | V13: 5 | Z13: TOTAL PUNTOS
A14: ACTUAL | B14: ANTERIOR | C14: NO | D14: NOMBRE | E14: EQUIPO | F14: POS XCC | G14: PTOS XCC | H14: POS XCO | I14: PTOS XCO | J14: POS XCC | K14: PTOS XCC | L14: POS XCO | M14: PTOS XCO | N14: POS XCC | O14: PTOS XCC | P14: POS XCO | Q14: PTOS XCO | R14: POS XCC | S14: PTOS XCC | T14: POS XCO | U14: PTOS XCO | V14: POS XCC | W14: PTOS XCC | X14: POS XCO | Y14: PTOS XCO
A15: 1 | B15: 1 | C15: 84 | D15: ROJAS Adriana | E15: CBZ ASFALTOS- DEKRA- MAXXIS | F15: 1 | G15: 25 | H15: 1 | I15: 200 | J15: 0 | K15: 0 | L15: 0 | M15: 0 | N15: 2 | O15: =IFERROR(VLOOKUP(N15,'Puntos XCC Mayor'!$A$1:$B$15,2,FALSE),0) -> 20 | P15: 3 | Q15: =IFERROR(VLOOKUP(P15,'Puntos XCO'!$A$1:$B$63,2,FALSE),0) -> 120 | R15: 1 | S15: =IFERROR(VLOOKUP(R15,'Puntos XCC Mayor'!$A$1:$B$15,2,FALSE),0) -> 25 | T15: 1 | U15: =IFERROR(VLOOKUP(T15,'Puntos XCO'!$A$1:$B$63,2,FALSE),0) -> 200 | V15: =IFERROR(VLOOKUP(C15,RESXCC_1,9,FALSE),0) -> 2 | W15: =IFERROR(VLOOKUP(V15,'Puntos XCC Mayor'!$A$1:$B$15,2,FALSE),0) -> 20 | X15: =IFERROR(VLOOKUP(C15,RESXCO,9,FALSE),0) -> 2 | Y15: =IFERROR(VLOOKUP(X15,'Puntos XCO'!$A$1:$B$63,2,FALSE),0) -> 150 | Z15: =G15+I15+K15+M15+O15+Q15+S15+U15+W15+Y15 -> 760
A16: 2 | B16: 3 | C16: 85 | D16: ESPINOZA Cristel | E16: ASFALTOS CBZ/ DEKRA/ SECNET | F16: 3 | G16: 16 | H16: 2 | I16: 150 | J16: 0 | K16: 0 | L16: 1 | M16: 200 | O16: =IFERROR(VLOOKUP(N16,'Puntos XCC Mayor'!$A$1:$B$15,2,FALSE),0) -> 0 | P16: 5 | Q16: =IFERROR(VLOOKUP(P16,'Puntos XCO'!$A$1:$B$63,2,FALSE),0) -> 100 | R16: 0 | S16: =IFERROR(VLOOKUP(R16,'Puntos XCC Mayor'!$A$1:$B$15,2,FALSE),0) -> 0 | T16: 0 | U16: =IFERROR(VLOOKUP(T16,'Puntos XCO'!$A$1:$B$63,2,FALSE),0) -> 0 | V16: =IFERROR(VLOOKUP(C16,RESXCC_1,9,FALSE),0) -> 1 | W16: =IFERROR(VLOOKUP(V16,'Puntos XCC Mayor'!$A$1:$B$15,2,FALSE),0) -> 25 | X16: =IFERROR(VLOOKUP(C16,RESXCO,9,FALSE),0) -> 1 | Y16: =IFERROR(VLOOKUP(X16,'Puntos XCO'!$A$1:$B$63,2,FALSE),0) -> 200 | Z16: =G16+I16+K16+M16+O16+Q16+S16+U16+W16+Y16 -> 691
A17: 3 | B17: 2 | C17: 91 | D17: GARCÍA Isabel* | E17: COLONO BIKE STATION KOLBI | J17: 1 | K17: 25 | L17: 2 | M17: 150 | N17: 5 | O17: =IFERROR(VLOOKUP(N17,'Puntos XCC Mayor'!$A$1:$B$15,2,FALSE),0) -> 12 | P17: 1 | Q17: =IFERROR(VLOOKUP(P17,'Puntos XCO'!$A$1:$B$63,2,FALSE),0) -> 200 | R17: 3 | S17: =IFERROR(VLOOKUP(R17,'Puntos XCC Mayor'!$A$1:$B$15,2,FALSE),0) -> 16 | T17: 3 | U17: =IFERROR(VLOOKUP(T17,'Puntos XCO'!$A$1:$B$63,2,FALSE),0) -> 120 | V17: =IFERROR(VLOOKUP(C17,RESXCC_1,9,FALSE),0) -> 3 | W17: =IFERROR(VLOOKUP(V17,'Puntos XCC Mayor'!$A$1:$B$15,2,FALSE),0) -> 16 | X17: =IFERROR(VLOOKUP(C17,RESXCO,9,FALSE),0) -> 3 | Y17: =IFERROR(VLOOKUP(X17,'Puntos XCO'!$A$1:$B$63,2,FALSE),0) -> 120 | Z17: =G17+I17+K17+M17+O17+Q17+S17+U17+W17+Y17 -> 659
A18: 4 | B18: 4 | C18: 94 | D18: NUÑEZ Alison* | E18: DESAMPARADOS BIKE CAFÉ FAST&UP | F18: 0 | G18: 0 | H18: 6 | I18: 95 | J18: 5 | K18: 12 | L18: 8 | M18: 85 | N18: 7 | O18: =IFERROR(VLOOKUP(N18,'Puntos XCC Mayor'!$A$1:$B$15,2,FALSE),0) -> 9 | P18: 3 | Q18: =IFERROR(VLOOKUP(P18,'Puntos XCO'!$A$1:$B$63,2,FALSE),0) -> 120 | R18: 6 | S18: =IFERROR(VLOOKUP(R18,'Puntos XCC Mayor'!$A$1:$B$15,2,FALSE),0) -> 10 | T18: 5 | U18: =IFERROR(VLOOKUP(T18,'Puntos XCO'!$A$1:$B$63,2,FALSE),0) -> 100 | V18: =IFERROR(VLOOKUP(C18,RESXCC_1,9,FALSE),0) -> 7 | W18: =IFERROR(VLOOKUP(V18,'Puntos XCC Mayor'!$A$1:$B$15,2,FALSE),0) -> 9 | X18: =IFERROR(VLOOKUP(C18,RESXCO,9,FALSE),0) -> 6 | Y18: =IFERROR(VLOOKUP(X18,'Puntos XCO'!$A$1:$B$63,2,FALSE),0) -> 95 | Z18: =G18+I18+K18+M18+O18+Q18+S18+U18+W18+Y18 -> 535
A19: 5 | B19: 5 | C19: 87 | D19: ZELEDÓN Gabriela | E19: NUMU COACHING | J19: 4 | K19: 14 | L19: 5 | M19: 100 | N19: 6 | O19: =IFERROR(VLOOKUP(N19,'Puntos XCC Mayor'!$A$1:$B$15,2,FALSE),0) -> 10 | P19: 7 | Q19: =IFERROR(VLOOKUP(P19,'Puntos XCO'!$A$1:$B$63,2,FALSE),0) -> 90 | R19: 4 | S19: =IFERROR(VLOOKUP(R19,'Puntos XCC Mayor'!$A$1:$B$15,2,FALSE),0) -> 14 | T19: 4 | U19: =IFERROR(VLOOKUP(T19,'Puntos XCO'!$A$1:$B$63,2,FALSE),0) -> 110 | V19: =IFERROR(VLOOKUP(C19,RESXCC_1,9,FALSE),0) -> 5 | W19: =IFERROR(VLOOKUP(V19,'Puntos XCC Mayor'!$A$1:$B$15,2,FALSE),0) -> 12 | X19: =IFERROR(VLOOKUP(C19,RESXCO,9,FALSE),0) -> 5 | Y19: =IFERROR(VLOOKUP(X19,'Puntos XCO'!$A$1:$B$63,2,FALSE),0) -> 100 | Z19: =G19+I19+K19+M19+O19+Q19+S19+U19+W19+Y19 -> 450
A20: 6 | B20: 6 | C20: 92 | D20: GARCÍA Marisol* | E20: COLONO BIKE STATION KOLBI | J20: 2 | K20: 20 | L20: 3 | M20: 120 | O20: =IFERROR(VLOOKUP(N20,'Puntos XCC Mayor'!$A$1:$B$15,2,FALSE),0) -> 0 | Q20: =IFERROR(VLOOKUP(P20,'Puntos XCO'!$A$1:$B$63,2,FALSE),0) -> 0 | R20: 2 | S20: =IFERROR(VLOOKUP(R20,'Puntos XCC Mayor'!$A$1:$B$15,2,FALSE),0) -> 20 | T20: 2 | U20: =IFERROR(VLOOKUP(T20,'Puntos XCO'!$A$1:$B$63,2,FALSE),0) -> 150 | V20: =IFERROR(VLOOKUP(C20,RESXCC_1,9,FALSE),0) -> 4 | W20: =IFERROR(VLOOKUP(V20,'Puntos XCC Mayor'!$A$1:$B$15,2,FALSE),0) -> 14 | X20: =IFERROR(VLOOKUP(C20,RESXCO,9,FALSE),0) -> 4 | Y20: =IFERROR(VLOOKUP(X20,'Puntos XCO'!$A$1:$B$63,2,FALSE),0) -> 110 | Z20: =G20+I20+K20+M20+O20+Q20+S20+U20+W20+Y20 -> 434
A21: 7 | B21: 7 | C21: 95 | D21: ALVARADO Elizabeth * | E21: SANTA ANA | F21: 8 | G21: 8 | H21: 9 | I21: 80 | J21: 6 | K21: 10 | L21: 7 | M21: 90 | O21: =IFERROR(VLOOKUP(N21,'Puntos XCC Mayor'!$A$1:$B$15,2,FALSE),0) -> 0 | Q21: =IFERROR(VLOOKUP(P21,'Puntos XCO'!$A$1:$B$63,2,FALSE),0) -> 0 | R21: 7 | S21: =IFERROR(VLOOKUP(R21,'Puntos XCC Mayor'!$A$1:$B$15,2,FALSE),0) -> 9 | T21: 7 | U21: =IFERROR(VLOOKUP(T21,'Puntos XCO'!$A$1:$B$63,2,FALSE),0) -> 90 | V21: =IFERROR(VLOOKUP(C21,RESXCC_1,9,FALSE),0) -> 6 | W21: =IFERROR(VLOOKUP(V21,'Puntos XCC Mayor'!$A$1:$B$15,2,FALSE),0) -> 10 | X21: =IFERROR(VLOOKUP(C21,RESXCO,9,FALSE),0) -> 7 | Y21: =IFERROR(VLOOKUP(X21,'Puntos XCO'!$A$1:$B$63,2,FALSE),0) -> 90 | Z21: =G21+I21+K21+M21+O21+Q21+S21+U21+W21+Y21 -> 387
A22: 8 | B22: 8 | C22: 90 | D22: RAHILLY Denise* | E22: BOBBYS CYCLING TEAM | F22: 0 | G22: 0 | H22: 8 | I22: 85 | J22: 0 | K22: 0 | L22: 6 | M22: 95 | O22: =IFERROR(VLOOKUP(N22,'Puntos XCC Mayor'!$A$1:$B$15,2,FALSE),0) -> 0 | Q22: =IFERROR(VLOOKUP(P22,'Puntos XCO'!$A$1:$B$63,2,FALSE),0) -> 0 | R22: 5 | S22: =IFERROR(VLOOKUP(R22,'Puntos XCC Mayor'!$A$1:$B$15,2,FALSE),0) -> 12 | T22: 6 | U22: =IFERROR(VLOOKUP(T22,'Puntos XCO'!$A$1:$B$63,2,FALSE),0) -> 95 | V22: =IFERROR(VLOOKUP(C22,RESXCC_1,9,FALSE),0) -> 0 | W22: =IFERROR(VLOOKUP(V22,'Puntos XCC Mayor'!$A$1:$B$15,2,FALSE),0) -> 0 | X22: =IFERROR(VLOOKUP(C22,RESXCO,9,FALSE),0) -> 0 | Y22: =IFERROR(VLOOKUP(X22,'Puntos XCO'!$A$1:$B$63,2,FALSE),0) -> 0 | Z22: =G22+I22+K22+M22+O22+Q22+S22+U22+W22+Y22 -> 287
A23: 9 | B23: 9 | C23: 88 | D23: MARTINEZ Daniela | E23: BOBBYS CYCLING TEAM | F23: 7 | G23: 9 | H23: 5 | I23: 100 | J23: 3 | K23: 16 | L23: 4 | M23: 110 | O23: =IFERROR(VLOOKUP(N23,'Puntos XCC Mayor'!$A$1:$B$15,2,FALSE),0) -> 0 | Q23: =IFERROR(VLOOKUP(P23,'Puntos XCO'!$A$1:$B$63,2,FALSE),0) -> 0 | R23: 0 | S23: =IFERROR(VLOOKUP(R23,'Puntos XCC Mayor'!$A$1:$B$15,2,FALSE),0) -> 0 | T23: 0 | U23: =IFERROR(VLOOKUP(T23,'Puntos XCO'!$A$1:$B$63,2,FALSE),0) -> 0 | V23: =IFERROR(VLOOKUP(C23,RESXCC_1,9,FALSE),0) -> 0 | W23: =IFERROR(VLOOKUP(V23,'Puntos XCC Mayor'!$A$1:$B$15,2,FALSE),0) -> 0 | X23: =IFERROR(VLOOKUP(C23,RESXCO,9,FALSE),0) -> 0 | Y23: =IFERROR(VLOOKUP(X23,'Puntos XCO'!$A$1:$B$63,2,FALSE),0) -> 0 | Z23: =G23+I23+K23+M23+O23+Q23+S23+U23+W23+Y23 -> 235
A24: 10 | B24: 10 | C24: 89 | D24: SALVINI Giuliana | E24: GEN2RISE | O24: =IFERROR(VLOOKUP(N24,'Puntos XCC Mayor'!$A$1:$B$15,2,FALSE),0) -> 0 | P24: 1 | Q24: =IFERROR(VLOOKUP(P24,'Puntos XCO'!$A$1:$B$63,2,FALSE),0) -> 200 | R24: 0 | S24: =IFERROR(VLOOKUP(R24,'Puntos XCC Mayor'!$A$1:$B$15,2,FALSE),0) -> 0 | T24: 0 | U24: =IFERROR(VLOOKUP(T24,'Puntos XCO'!$A$1:$B$63,2,FALSE),0) -> 0 | V24: =IFERROR(VLOOKUP(C24,RESXCC_1,9,FALSE),0) -> 0 | W24: =IFERROR(VLOOKUP(V24,'Puntos XCC Mayor'!$A$1:$B$15,2,FALSE),0) -> 0 | X24: =IFERROR(VLOOKUP(C24,RESXCO,9,FALSE),0) -> 0 | Y24: =IFERROR(VLOOKUP(X24,'Puntos XCO'!$A$1:$B$63,2,FALSE),0) -> 0 | Z24: =G24+I24+K24+M24+O24+Q24+S24+U24+W24+Y24 -> 200
A25: 11 | B25: 11 | C25: 82 | D25: RODRÍGUEZ Suheily | E25: SINTESIS DEVELOPMENT TEAM | N25: 1 | O25: =IFERROR(VLOOKUP(N25,'Puntos XCC Mayor'!$A$1:$B$15,2,FALSE),0) -> 25 | P25: 2 | Q25: =IFERROR(VLOOKUP(P25,'Puntos XCO'!$A$1:$B$63,2,FALSE),0) -> 150 | R25: 0 | S25: =IFERROR(VLOOKUP(R25,'Puntos XCC Mayor'!$A$1:$B$15,2,FALSE),0) -> 0 | T25: 0 | U25: =IFERROR(VLOOKUP(T25,'Puntos XCO'!$A$1:$B$63,2,FALSE),0) -> 0 | V25: =IFERROR(VLOOKUP(C25,RESXCC_1,9,FALSE),0) -> 0 | W25: =IFERROR(VLOOKUP(V25,'Puntos XCC Mayor'!$A$1:$B$15,2,FALSE),0) -> 0 | X25: =IFERROR(VLOOKUP(C25,RESXCO,9,FALSE),0) -> 0 | Y25: =IFERROR(VLOOKUP(X25,'Puntos XCO'!$A$1:$B$63,2,FALSE),0) -> 0 | Z25: =G25+I25+K25+M25+O25+Q25+S25+U25+W25+Y25 -> 175
A26: 12 | B26: 12 | C26: 93 | D26: WESTER Isabela Katerina* | E26: DONOVAN RACING | N26: 4 | O26: =IFERROR(VLOOKUP(N26,'Puntos XCC Mayor'!$A$1:$B$15,2,FALSE),0) -> 14 | P26: 2 | Q26: =IFERROR(VLOOKUP(P26,'Puntos XCO'!$A$1:$B$63,2,FALSE),0) -> 150 | R26: 0 | S26: =IFERROR(VLOOKUP(R26,'Puntos XCC Mayor'!$A$1:$B$15,2,FALSE),0) -> 0 | T26: 0 | U26: =IFERROR(VLOOKUP(T26,'Puntos XCO'!$A$1:$B$63,2,FALSE),0) -> 0 | V26: =IFERROR(VLOOKUP(C26,RESXCC_1,9,FALSE),0) -> 0 | W26: =IFERROR(VLOOKUP(V26,'Puntos XCC Mayor'!$A$1:$B$15,2,FALSE),0) -> 0 | X26: =IFERROR(VLOOKUP(C26,RESXCO,9,FALSE),0) -> 0 | Y26: =IFERROR(VLOOKUP(X26,'Puntos XCO'!$A$1:$B$63,2,FALSE),0) -> 0 | Z26: =G26+I26+K26+M26+O26+Q26+S26+U26+W26+Y26 -> 164
A27: 13 | B27: 13 | D27: AVILA Melisa* | E27: MANZATÉ LA SELVA NOVARIX | F27: 6 | G27: 10 | H27: 3 | I27: 120 | J27: 0 | K27: 0 | L27: 0 | M27: 0 | O27: =IFERROR(VLOOKUP(N27,'Puntos XCC Mayor'!$A$1:$B$15,2,FALSE),0) -> 0 | Q27: =IFERROR(VLOOKUP(P27,'Puntos XCO'!$A$1:$B$63,2,FALSE),0) -> 0 | R27: 0 | S27: =IFERROR(VLOOKUP(R27,'Puntos XCC Mayor'!$A$1:$B$15,2,FALSE),0) -> 0 | T27: 0 | U27: =IFERROR(VLOOKUP(T27,'Puntos XCO'!$A$1:$B$63,2,FALSE),0) -> 0 | V27: =IFERROR(VLOOKUP(C27,RESXCC_1,9,FALSE),0) -> 0 | W27: =IFERROR(VLOOKUP(V27,'Puntos XCC Mayor'!$A$1:$B$15,2,FALSE),0) -> 0 | X27: =IFERROR(VLOOKUP(C27,RESXCO,9,FALSE),0) -> 0 | Y27: =IFERROR(VLOOKUP(X27,'Puntos XCO'!$A$1:$B$63,2,FALSE),0) -> 0 | Z27: =G27+I27+K27+M27+O27+Q27+S27+U27+W27+Y27 -> 130
